INFO 2019-09-30 14:06:11,554 basehttp 124 "GET / HTTP/1.1" 200 16286
INFO 2019-09-30 14:06:11,729 basehttp 124 "GET /static/admin/fonts/Roboto-Bold-webfont.woff HTTP/1.1" 304 0
INFO 2019-09-30 14:13:33,328 basehttp 124 "GET / HTTP/1.1" 200 16286
INFO 2019-09-30 16:05:08,053 basehttp 124 "GET /image_codes/4800e137-f4e0-44b9-8bf3-6485f810db2a/ HTTP/1.1" 200 3415
INFO 2019-09-30 16:05:09,423 basehttp 124 "GET /image_codes/37f060dd-4a1b-40f6-8802-30b6ea206d2a/ HTTP/1.1" 200 3006
INFO 2019-09-30 16:05:09,913 basehttp 124 "GET /image_codes/6ca888aa-93ea-4024-abe2-afc16cd4f801/ HTTP/1.1" 200 3510
INFO 2019-09-30 16:06:03,732 basehttp 124 "GET /image_codes/c43b6f63-3c2d-4fbf-aa81-e26d65a92f6e/ HTTP/1.1" 200 2739
INFO 2019-09-30 16:06:04,161 basehttp 124 "GET /image_codes/965077e7-5675-4654-b8e4-84b49d338174/ HTTP/1.1" 200 2921
INFO 2019-09-30 16:06:04,608 basehttp 124 "GET /image_codes/aef77785-6ed2-4551-a84d-f32b62dac530/ HTTP/1.1" 200 3215
WARNING 2019-09-30 16:44:44,290 log 228 Not Found: /
WARNING 2019-09-30 16:44:44,290 basehttp 124 "GET / HTTP/1.1" 404 2114
INFO 2019-09-30 16:44:52,391 basehttp 124 "OPTIONS /cart/ HTTP/1.1" 200 0
WARNING 2019-09-30 16:44:52,444 log 228 Not Found: /cart/
WARNING 2019-09-30 16:44:52,444 basehttp 124 "GET /cart/ HTTP/1.1" 404 2152
INFO 2019-09-30 16:48:59,766 basehttp 124 "OPTIONS /cart/ HTTP/1.1" 200 0
WARNING 2019-09-30 16:48:59,815 log 228 Not Found: /cart/
WARNING 2019-09-30 16:48:59,816 basehttp 124 "GET /cart/ HTTP/1.1" 404 2152
WARNING 2019-09-30 16:49:01,308 log 228 Not Found: /cart/
WARNING 2019-09-30 16:49:01,308 basehttp 124 "GET /cart/ HTTP/1.1" 404 2152
INFO 2019-09-30 16:49:03,674 basehttp 124 "GET /image_codes/da063630-91a7-4b17-8c00-8dbad87d2a07/ HTTP/1.1" 200 3030
INFO 2019-09-30 16:49:05,483 basehttp 124 "GET /image_codes/8d1b3cf6-956a-4d87-a82b-a9e89fc62a58/ HTTP/1.1" 200 3199
INFO 2019-09-30 16:49:05,962 basehttp 124 "GET /image_codes/985b60a1-0074-4484-b252-07906aef2d5b/ HTTP/1.1" 200 3308
INFO 2019-09-30 16:49:06,252 basehttp 124 "GET /image_codes/2dc7df10-a5ba-4fb6-bd26-f9175c1a4dce/ HTTP/1.1" 200 3804
INFO 2019-09-30 16:49:06,393 basehttp 124 "GET /image_codes/d8b758f5-3407-47a4-80c1-a17d99d6b0ec/ HTTP/1.1" 200 3271
INFO 2019-09-30 16:49:06,713 basehttp 124 "GET /image_codes/53398625-c27a-4665-9bd9-3e074fe47fbc/ HTTP/1.1" 200 3194
INFO 2019-09-30 16:49:06,900 basehttp 124 "GET /image_codes/19bdc0d6-c3c1-493a-b8c1-f0d30d969868/ HTTP/1.1" 200 3094
INFO 2019-09-30 16:49:07,067 basehttp 124 "GET /image_codes/1ef0210f-d410-4a6b-8f1e-21c184bb21b0/ HTTP/1.1" 200 3647
INFO 2019-09-30 16:49:07,231 basehttp 124 "GET /image_codes/e3cbf6a1-2587-488c-b1af-de4db8ca1eed/ HTTP/1.1" 200 3152
INFO 2019-09-30 16:49:07,379 basehttp 124 "GET /image_codes/67927284-3abc-4781-b994-c67040daab5e/ HTTP/1.1" 200 3131
INFO 2019-09-30 16:49:07,548 basehttp 124 "GET /image_codes/c15201e2-2b46-457a-8be9-b549284afe32/ HTTP/1.1" 200 3208
INFO 2019-09-30 16:49:07,708 basehttp 124 "GET /image_codes/0e6adf65-398b-4fd9-bdbf-980d4452f11e/ HTTP/1.1" 200 3132
INFO 2019-09-30 16:49:08,056 basehttp 124 "GET /image_codes/5cadef3b-dc55-4601-b434-182711a8b2d4/ HTTP/1.1" 200 3542
INFO 2019-09-30 16:49:08,938 basehttp 124 "GET /image_codes/41e7ac4c-f282-4859-a542-83971f7374cd/ HTTP/1.1" 200 3114
INFO 2019-09-30 16:49:09,084 basehttp 124 "GET /image_codes/737e3700-3a95-4635-9fc4-6ded8d14d873/ HTTP/1.1" 200 3335
INFO 2019-09-30 16:49:10,938 basehttp 124 "GET /image_codes/aee2aacd-b706-41d0-a0f0-62c4a401b668/ HTTP/1.1" 200 3633
INFO 2019-09-30 16:49:11,097 basehttp 124 "GET /image_codes/5c125222-68ad-489b-a262-0ee6b933e075/ HTTP/1.1" 200 3124
INFO 2019-09-30 16:49:11,275 basehttp 124 "GET /image_codes/9111864b-dfe6-4563-8862-f1b7f69dde59/ HTTP/1.1" 200 2921
INFO 2019-09-30 16:49:11,419 basehttp 124 "GET /image_codes/b4e89a6c-9b10-430e-bb82-2d3fe0567d36/ HTTP/1.1" 200 3093
INFO 2019-09-30 16:49:11,992 basehttp 124 "GET /image_codes/6a0bee05-a10e-420a-b68f-8df28469ce3b/ HTTP/1.1" 200 3119
INFO 2019-09-30 16:49:12,146 basehttp 124 "GET /image_codes/7256d944-2271-4bd3-9286-9ab5eb009494/ HTTP/1.1" 200 2730
INFO 2019-09-30 16:49:12,302 basehttp 124 "GET /image_codes/1959324d-508f-410c-89d2-6a5a5efece42/ HTTP/1.1" 200 2990
INFO 2019-09-30 16:49:12,461 basehttp 124 "GET /image_codes/9f8eb8c3-291c-4af0-8a4f-e2593eab75ca/ HTTP/1.1" 200 3198
INFO 2019-09-30 16:49:12,609 basehttp 124 "GET /image_codes/8ca5c5c1-4897-49bb-98f8-060f4a2643c6/ HTTP/1.1" 200 3547
INFO 2019-09-30 16:49:12,966 basehttp 124 "GET /image_codes/f60690fb-907a-4d9d-9c34-e871b6cd3e9e/ HTTP/1.1" 200 3316
INFO 2019-10-08 09:13:13,839 basehttp 124 "OPTIONS /cart/ HTTP/1.1" 200 0
WARNING 2019-10-08 09:13:14,058 log 228 Not Found: /cart/
WARNING 2019-10-08 09:13:14,059 basehttp 124 "GET /cart/ HTTP/1.1" 404 2152
INFO 2019-10-08 09:13:31,241 basehttp 124 "OPTIONS /cart/ HTTP/1.1" 200 0
WARNING 2019-10-08 09:13:31,261 log 228 Not Found: /cart/
WARNING 2019-10-08 09:13:31,262 basehttp 124 "GET /cart/ HTTP/1.1" 404 2152
WARNING 2019-10-08 09:13:37,674 log 228 Not Found: /cart/
WARNING 2019-10-08 09:13:37,674 basehttp 124 "GET /cart/ HTTP/1.1" 404 2152
INFO 2019-10-08 09:13:39,009 basehttp 124 "GET /image_codes/1c2404c9-f0eb-440e-98e5-ffa5552519ce/ HTTP/1.1" 200 3590
INFO 2019-10-08 09:13:40,261 basehttp 124 "GET /image_codes/f120dd9d-0b4f-43c4-8bf6-7902a08db3cd/ HTTP/1.1" 200 2800
INFO 2019-10-08 09:14:03,867 basehttp 124 "GET /image_codes/35dc5dc4-208a-4264-8ac7-4c90bc3eb058/ HTTP/1.1" 200 3013
INFO 2019-10-08 09:15:56,914 basehttp 124 "GET /image_codes/99eac4f8-c014-4ed8-870c-41bff4a07802/ HTTP/1.1" 200 3220
ERROR 2019-10-08 09:16:32,692 log 228 Internal Server Error: /image_codes/5b2d9231-0b2f-4dae-ae0e-9aff7b443c23/
Traceback (most recent call last):
  File "/home/lgl/virtualenvs/py3_django/lib/python3.6/site-packages/django/core/handlers/exception.py", line 34, in inner
    response = get_response(request)
  File "/home/lgl/virtualenvs/py3_django/lib/python3.6/site-packages/django/core/handlers/base.py", line 126, in _get_response
    response = self.process_exception_by_middleware(e, request)
  File "/home/lgl/virtualenvs/py3_django/lib/python3.6/site-packages/django/core/handlers/base.py", line 124, in _get_response
    response = wrapped_callback(request, *callback_args, **callback_kwargs)
  File "/home/lgl/virtualenvs/py3_django/lib/python3.6/site-packages/django/views/decorators/csrf.py", line 54, in wrapped_view
    return view_func(*args, **kwargs)
  File "/home/lgl/virtualenvs/py3_django/lib/python3.6/site-packages/django/views/generic/base.py", line 68, in view
    return self.dispatch(request, *args, **kwargs)
  File "/home/lgl/virtualenvs/py3_django/lib/python3.6/site-packages/rest_framework/views.py", line 483, in dispatch
    response = self.handle_exception(exc)
  File "/home/lgl/virtualenvs/py3_django/lib/python3.6/site-packages/rest_framework/views.py", line 443, in handle_exception
    self.raise_uncaught_exception(exc)
  File "/home/lgl/virtualenvs/py3_django/lib/python3.6/site-packages/rest_framework/views.py", line 480, in dispatch
    response = handler(request, *args, **kwargs)
  File "/home/lgl/workplace/django_project/meiduo_mall/meiduo_mall/apps/verifications/views.py", line 20, in get
    text, image = captcha.generate_captcha()
ValueError: too many values to unpack (expected 2)
ERROR 2019-10-08 09:16:32,694 basehttp 124 "GET /image_codes/5b2d9231-0b2f-4dae-ae0e-9aff7b443c23/ HTTP/1.1" 500 18961
ERROR 2019-10-08 09:16:33,761 log 228 Internal Server Error: /image_codes/d250493d-1ccb-460b-93c3-b489ae6440b0/
Traceback (most recent call last):
  File "/home/lgl/virtualenvs/py3_django/lib/python3.6/site-packages/django/core/handlers/exception.py", line 34, in inner
    response = get_response(request)
  File "/home/lgl/virtualenvs/py3_django/lib/python3.6/site-packages/django/core/handlers/base.py", line 126, in _get_response
    response = self.process_exception_by_middleware(e, request)
  File "/home/lgl/virtualenvs/py3_django/lib/python3.6/site-packages/django/core/handlers/base.py", line 124, in _get_response
    response = wrapped_callback(request, *callback_args, **callback_kwargs)
  File "/home/lgl/virtualenvs/py3_django/lib/python3.6/site-packages/django/views/decorators/csrf.py", line 54, in wrapped_view
    return view_func(*args, **kwargs)
  File "/home/lgl/virtualenvs/py3_django/lib/python3.6/site-packages/django/views/generic/base.py", line 68, in view
    return self.dispatch(request, *args, **kwargs)
  File "/home/lgl/virtualenvs/py3_django/lib/python3.6/site-packages/rest_framework/views.py", line 483, in dispatch
    response = self.handle_exception(exc)
  File "/home/lgl/virtualenvs/py3_django/lib/python3.6/site-packages/rest_framework/views.py", line 443, in handle_exception
    self.raise_uncaught_exception(exc)
  File "/home/lgl/virtualenvs/py3_django/lib/python3.6/site-packages/rest_framework/views.py", line 480, in dispatch
    response = handler(request, *args, **kwargs)
  File "/home/lgl/workplace/django_project/meiduo_mall/meiduo_mall/apps/verifications/views.py", line 20, in get
    text, image = captcha.generate_captcha()
ValueError: too many values to unpack (expected 2)
ERROR 2019-10-08 09:16:33,762 basehttp 124 "GET /image_codes/d250493d-1ccb-460b-93c3-b489ae6440b0/ HTTP/1.1" 500 18961
INFO 2019-10-08 09:16:47,357 basehttp 124 "GET /image_codes/580d0cb3-9614-43a8-8786-ad4b37e5a63f/ HTTP/1.1" 200 3413
INFO 2019-10-08 09:16:48,491 basehttp 124 "GET /image_codes/0e593af8-1e4a-46e4-92ff-8297ba1ac181/ HTTP/1.1" 200 2965
WARNING 2019-10-08 11:51:57,308 log 228 Not Found: /
WARNING 2019-10-08 11:51:57,309 basehttp 124 "GET / HTTP/1.1" 404 2114
WARNING 2019-10-08 11:51:57,405 log 228 Not Found: /favicon.ico
WARNING 2019-10-08 11:51:57,406 basehttp 124 "GET /favicon.ico HTTP/1.1" 404 2165
WARNING 2019-10-08 14:22:26,891 log 228 Not Found: /
WARNING 2019-10-08 14:22:26,891 basehttp 124 "GET / HTTP/1.1" 404 2114
WARNING 2019-10-08 14:22:26,937 log 228 Not Found: /favicon.ico
WARNING 2019-10-08 14:22:26,937 basehttp 124 "GET /favicon.ico HTTP/1.1" 404 2165
INFO 2019-10-08 14:22:39,366 basehttp 124 "OPTIONS /cart/ HTTP/1.1" 200 0
WARNING 2019-10-08 14:22:39,424 log 228 Not Found: /cart/
WARNING 2019-10-08 14:22:39,425 basehttp 124 "GET /cart/ HTTP/1.1" 404 2152
WARNING 2019-10-08 14:22:40,191 log 228 Not Found: /cart/
WARNING 2019-10-08 14:22:40,192 basehttp 124 "GET /cart/ HTTP/1.1" 404 2152
ERROR 2019-10-08 14:22:48,669 log 228 Internal Server Error: /image_codes/24f7cf94-90ed-4eda-a28b-45ff3d4efbd1/
Traceback (most recent call last):
  File "/home/lgl/virtualenvs/py3_django/lib/python3.6/site-packages/django/core/handlers/exception.py", line 34, in inner
    response = get_response(request)
  File "/home/lgl/virtualenvs/py3_django/lib/python3.6/site-packages/django/core/handlers/base.py", line 126, in _get_response
    response = self.process_exception_by_middleware(e, request)
  File "/home/lgl/virtualenvs/py3_django/lib/python3.6/site-packages/django/core/handlers/base.py", line 124, in _get_response
    response = wrapped_callback(request, *callback_args, **callback_kwargs)
  File "/home/lgl/virtualenvs/py3_django/lib/python3.6/site-packages/django/views/decorators/csrf.py", line 54, in wrapped_view
    return view_func(*args, **kwargs)
  File "/home/lgl/virtualenvs/py3_django/lib/python3.6/site-packages/django/views/generic/base.py", line 68, in view
    return self.dispatch(request, *args, **kwargs)
  File "/home/lgl/virtualenvs/py3_django/lib/python3.6/site-packages/rest_framework/views.py", line 483, in dispatch
    response = self.handle_exception(exc)
  File "/home/lgl/virtualenvs/py3_django/lib/python3.6/site-packages/rest_framework/views.py", line 443, in handle_exception
    self.raise_uncaught_exception(exc)
  File "/home/lgl/virtualenvs/py3_django/lib/python3.6/site-packages/rest_framework/views.py", line 480, in dispatch
    response = handler(request, *args, **kwargs)
  File "/home/lgl/workplace/django_project/meiduo_mall/meiduo_mall/apps/verifications/views.py", line 30, in get
    redis_conn.setex("img_%s" % image_code_id, constants.IMAGE_CODE_REDIS_EXPIRES, text)
AttributeError: module 'celery_tasks.sms.constants' has no attribute 'IMAGE_CODE_REDIS_EXPIRES'
ERROR 2019-10-08 14:22:48,670 basehttp 124 "GET /image_codes/24f7cf94-90ed-4eda-a28b-45ff3d4efbd1/ HTTP/1.1" 500 19145
ERROR 2019-10-08 14:22:50,339 log 228 Internal Server Error: /image_codes/a90bee68-1f38-4288-b3ed-0360ad22feb7/
Traceback (most recent call last):
  File "/home/lgl/virtualenvs/py3_django/lib/python3.6/site-packages/django/core/handlers/exception.py", line 34, in inner
    response = get_response(request)
  File "/home/lgl/virtualenvs/py3_django/lib/python3.6/site-packages/django/core/handlers/base.py", line 126, in _get_response
    response = self.process_exception_by_middleware(e, request)
  File "/home/lgl/virtualenvs/py3_django/lib/python3.6/site-packages/django/core/handlers/base.py", line 124, in _get_response
    response = wrapped_callback(request, *callback_args, **callback_kwargs)
  File "/home/lgl/virtualenvs/py3_django/lib/python3.6/site-packages/django/views/decorators/csrf.py", line 54, in wrapped_view
    return view_func(*args, **kwargs)
  File "/home/lgl/virtualenvs/py3_django/lib/python3.6/site-packages/django/views/generic/base.py", line 68, in view
    return self.dispatch(request, *args, **kwargs)
  File "/home/lgl/virtualenvs/py3_django/lib/python3.6/site-packages/rest_framework/views.py", line 483, in dispatch
    response = self.handle_exception(exc)
  File "/home/lgl/virtualenvs/py3_django/lib/python3.6/site-packages/rest_framework/views.py", line 443, in handle_exception
    self.raise_uncaught_exception(exc)
  File "/home/lgl/virtualenvs/py3_django/lib/python3.6/site-packages/rest_framework/views.py", line 480, in dispatch
    response = handler(request, *args, **kwargs)
  File "/home/lgl/workplace/django_project/meiduo_mall/meiduo_mall/apps/verifications/views.py", line 30, in get
    redis_conn.setex("img_%s" % image_code_id, constants.IMAGE_CODE_REDIS_EXPIRES, text)
AttributeError: module 'celery_tasks.sms.constants' has no attribute 'IMAGE_CODE_REDIS_EXPIRES'
ERROR 2019-10-08 14:22:50,340 basehttp 124 "GET /image_codes/a90bee68-1f38-4288-b3ed-0360ad22feb7/ HTTP/1.1" 500 19145
ERROR 2019-10-08 14:22:50,977 log 228 Internal Server Error: /image_codes/bf463722-6e24-4adb-8e71-246fcfa8a884/
Traceback (most recent call last):
  File "/home/lgl/virtualenvs/py3_django/lib/python3.6/site-packages/django/core/handlers/exception.py", line 34, in inner
    response = get_response(request)
  File "/home/lgl/virtualenvs/py3_django/lib/python3.6/site-packages/django/core/handlers/base.py", line 126, in _get_response
    response = self.process_exception_by_middleware(e, request)
  File "/home/lgl/virtualenvs/py3_django/lib/python3.6/site-packages/django/core/handlers/base.py", line 124, in _get_response
    response = wrapped_callback(request, *callback_args, **callback_kwargs)
  File "/home/lgl/virtualenvs/py3_django/lib/python3.6/site-packages/django/views/decorators/csrf.py", line 54, in wrapped_view
    return view_func(*args, **kwargs)
  File "/home/lgl/virtualenvs/py3_django/lib/python3.6/site-packages/django/views/generic/base.py", line 68, in view
    return self.dispatch(request, *args, **kwargs)
  File "/home/lgl/virtualenvs/py3_django/lib/python3.6/site-packages/rest_framework/views.py", line 483, in dispatch
    response = self.handle_exception(exc)
  File "/home/lgl/virtualenvs/py3_django/lib/python3.6/site-packages/rest_framework/views.py", line 443, in handle_exception
    self.raise_uncaught_exception(exc)
  File "/home/lgl/virtualenvs/py3_django/lib/python3.6/site-packages/rest_framework/views.py", line 480, in dispatch
    response = handler(request, *args, **kwargs)
  File "/home/lgl/workplace/django_project/meiduo_mall/meiduo_mall/apps/verifications/views.py", line 30, in get
    redis_conn.setex("img_%s" % image_code_id, constants.IMAGE_CODE_REDIS_EXPIRES, text)
AttributeError: module 'celery_tasks.sms.constants' has no attribute 'IMAGE_CODE_REDIS_EXPIRES'
ERROR 2019-10-08 14:22:50,978 basehttp 124 "GET /image_codes/bf463722-6e24-4adb-8e71-246fcfa8a884/ HTTP/1.1" 500 19145
ERROR 2019-10-08 14:23:06,581 log 228 Internal Server Error: /image_codes/0faa1644-dde3-474e-a13d-7a110f79e162/
Traceback (most recent call last):
  File "/home/lgl/virtualenvs/py3_django/lib/python3.6/site-packages/django/core/handlers/exception.py", line 34, in inner
    response = get_response(request)
  File "/home/lgl/virtualenvs/py3_django/lib/python3.6/site-packages/django/core/handlers/base.py", line 126, in _get_response
    response = self.process_exception_by_middleware(e, request)
  File "/home/lgl/virtualenvs/py3_django/lib/python3.6/site-packages/django/core/handlers/base.py", line 124, in _get_response
    response = wrapped_callback(request, *callback_args, **callback_kwargs)
  File "/home/lgl/virtualenvs/py3_django/lib/python3.6/site-packages/django/views/decorators/csrf.py", line 54, in wrapped_view
    return view_func(*args, **kwargs)
  File "/home/lgl/virtualenvs/py3_django/lib/python3.6/site-packages/django/views/generic/base.py", line 68, in view
    return self.dispatch(request, *args, **kwargs)
  File "/home/lgl/virtualenvs/py3_django/lib/python3.6/site-packages/rest_framework/views.py", line 483, in dispatch
    response = self.handle_exception(exc)
  File "/home/lgl/virtualenvs/py3_django/lib/python3.6/site-packages/rest_framework/views.py", line 443, in handle_exception
    self.raise_uncaught_exception(exc)
  File "/home/lgl/virtualenvs/py3_django/lib/python3.6/site-packages/rest_framework/views.py", line 480, in dispatch
    response = handler(request, *args, **kwargs)
  File "/home/lgl/workplace/django_project/meiduo_mall/meiduo_mall/apps/verifications/views.py", line 30, in get
    redis_conn.setex("img_%s" % image_code_id, constants.IMAGE_CODE_REDIS_EXPIRES, text)
AttributeError: module 'celery_tasks.sms.constants' has no attribute 'IMAGE_CODE_REDIS_EXPIRES'
ERROR 2019-10-08 14:23:06,582 basehttp 124 "GET /image_codes/0faa1644-dde3-474e-a13d-7a110f79e162/ HTTP/1.1" 500 19145
ERROR 2019-10-08 14:23:44,217 log 228 Internal Server Error: /image_codes/c9d533be-1111-48dc-9d8d-0a80fad970b5/
Traceback (most recent call last):
  File "/home/lgl/virtualenvs/py3_django/lib/python3.6/site-packages/django/core/handlers/exception.py", line 34, in inner
    response = get_response(request)
  File "/home/lgl/virtualenvs/py3_django/lib/python3.6/site-packages/django/core/handlers/base.py", line 126, in _get_response
    response = self.process_exception_by_middleware(e, request)
  File "/home/lgl/virtualenvs/py3_django/lib/python3.6/site-packages/django/core/handlers/base.py", line 124, in _get_response
    response = wrapped_callback(request, *callback_args, **callback_kwargs)
  File "/home/lgl/virtualenvs/py3_django/lib/python3.6/site-packages/django/views/decorators/csrf.py", line 54, in wrapped_view
    return view_func(*args, **kwargs)
  File "/home/lgl/virtualenvs/py3_django/lib/python3.6/site-packages/django/views/generic/base.py", line 68, in view
    return self.dispatch(request, *args, **kwargs)
  File "/home/lgl/virtualenvs/py3_django/lib/python3.6/site-packages/rest_framework/views.py", line 483, in dispatch
    response = self.handle_exception(exc)
  File "/home/lgl/virtualenvs/py3_django/lib/python3.6/site-packages/rest_framework/views.py", line 443, in handle_exception
    self.raise_uncaught_exception(exc)
  File "/home/lgl/virtualenvs/py3_django/lib/python3.6/site-packages/rest_framework/views.py", line 480, in dispatch
    response = handler(request, *args, **kwargs)
  File "/home/lgl/workplace/django_project/meiduo_mall/meiduo_mall/apps/verifications/views.py", line 30, in get
    redis_conn.setex("img_%s" % image_code_id, constants.IMAGE_CODE_REDIS_EXPIRES, text)
AttributeError: module 'celery_tasks.sms.constants' has no attribute 'IMAGE_CODE_REDIS_EXPIRES'
ERROR 2019-10-08 14:23:44,218 basehttp 124 "GET /image_codes/c9d533be-1111-48dc-9d8d-0a80fad970b5/ HTTP/1.1" 500 19145
ERROR 2019-10-08 14:23:46,848 log 228 Internal Server Error: /image_codes/7c87a011-5bb3-4da1-bbdc-1b9676783963/
Traceback (most recent call last):
  File "/home/lgl/virtualenvs/py3_django/lib/python3.6/site-packages/django/core/handlers/exception.py", line 34, in inner
    response = get_response(request)
  File "/home/lgl/virtualenvs/py3_django/lib/python3.6/site-packages/django/core/handlers/base.py", line 126, in _get_response
    response = self.process_exception_by_middleware(e, request)
  File "/home/lgl/virtualenvs/py3_django/lib/python3.6/site-packages/django/core/handlers/base.py", line 124, in _get_response
    response = wrapped_callback(request, *callback_args, **callback_kwargs)
  File "/home/lgl/virtualenvs/py3_django/lib/python3.6/site-packages/django/views/decorators/csrf.py", line 54, in wrapped_view
    return view_func(*args, **kwargs)
  File "/home/lgl/virtualenvs/py3_django/lib/python3.6/site-packages/django/views/generic/base.py", line 68, in view
    return self.dispatch(request, *args, **kwargs)
  File "/home/lgl/virtualenvs/py3_django/lib/python3.6/site-packages/rest_framework/views.py", line 483, in dispatch
    response = self.handle_exception(exc)
  File "/home/lgl/virtualenvs/py3_django/lib/python3.6/site-packages/rest_framework/views.py", line 443, in handle_exception
    self.raise_uncaught_exception(exc)
  File "/home/lgl/virtualenvs/py3_django/lib/python3.6/site-packages/rest_framework/views.py", line 480, in dispatch
    response = handler(request, *args, **kwargs)
  File "/home/lgl/workplace/django_project/meiduo_mall/meiduo_mall/apps/verifications/views.py", line 30, in get
    redis_conn.setex("img_%s" % image_code_id, constants.IMAGE_CODE_REDIS_EXPIRES, text)
AttributeError: module 'celery_tasks.sms.constants' has no attribute 'IMAGE_CODE_REDIS_EXPIRES'
ERROR 2019-10-08 14:23:46,849 basehttp 124 "GET /image_codes/7c87a011-5bb3-4da1-bbdc-1b9676783963/ HTTP/1.1" 500 19145
ERROR 2019-10-08 14:23:48,838 log 228 Internal Server Error: /image_codes/7801a0a1-f2c2-4844-aba2-fd48c2e25490/
Traceback (most recent call last):
  File "/home/lgl/virtualenvs/py3_django/lib/python3.6/site-packages/django/core/handlers/exception.py", line 34, in inner
    response = get_response(request)
  File "/home/lgl/virtualenvs/py3_django/lib/python3.6/site-packages/django/core/handlers/base.py", line 126, in _get_response
    response = self.process_exception_by_middleware(e, request)
  File "/home/lgl/virtualenvs/py3_django/lib/python3.6/site-packages/django/core/handlers/base.py", line 124, in _get_response
    response = wrapped_callback(request, *callback_args, **callback_kwargs)
  File "/home/lgl/virtualenvs/py3_django/lib/python3.6/site-packages/django/views/decorators/csrf.py", line 54, in wrapped_view
    return view_func(*args, **kwargs)
  File "/home/lgl/virtualenvs/py3_django/lib/python3.6/site-packages/django/views/generic/base.py", line 68, in view
    return self.dispatch(request, *args, **kwargs)
  File "/home/lgl/virtualenvs/py3_django/lib/python3.6/site-packages/rest_framework/views.py", line 483, in dispatch
    response = self.handle_exception(exc)
  File "/home/lgl/virtualenvs/py3_django/lib/python3.6/site-packages/rest_framework/views.py", line 443, in handle_exception
    self.raise_uncaught_exception(exc)
  File "/home/lgl/virtualenvs/py3_django/lib/python3.6/site-packages/rest_framework/views.py", line 480, in dispatch
    response = handler(request, *args, **kwargs)
  File "/home/lgl/workplace/django_project/meiduo_mall/meiduo_mall/apps/verifications/views.py", line 30, in get
    redis_conn.setex("img_%s" % image_code_id, constants.IMAGE_CODE_REDIS_EXPIRES, text)
AttributeError: module 'celery_tasks.sms.constants' has no attribute 'IMAGE_CODE_REDIS_EXPIRES'
ERROR 2019-10-08 14:23:48,838 basehttp 124 "GET /image_codes/7801a0a1-f2c2-4844-aba2-fd48c2e25490/ HTTP/1.1" 500 19145
ERROR 2019-10-08 14:26:46,002 log 228 Internal Server Error: /image_codes/a864f7c9-e376-4c95-ba04-f539c9e89e10/
Traceback (most recent call last):
  File "/home/lgl/virtualenvs/py3_django/lib/python3.6/site-packages/django/core/handlers/exception.py", line 34, in inner
    response = get_response(request)
  File "/home/lgl/virtualenvs/py3_django/lib/python3.6/site-packages/django/core/handlers/base.py", line 126, in _get_response
    response = self.process_exception_by_middleware(e, request)
  File "/home/lgl/virtualenvs/py3_django/lib/python3.6/site-packages/django/core/handlers/base.py", line 124, in _get_response
    response = wrapped_callback(request, *callback_args, **callback_kwargs)
  File "/home/lgl/virtualenvs/py3_django/lib/python3.6/site-packages/django/views/decorators/csrf.py", line 54, in wrapped_view
    return view_func(*args, **kwargs)
  File "/home/lgl/virtualenvs/py3_django/lib/python3.6/site-packages/django/views/generic/base.py", line 68, in view
    return self.dispatch(request, *args, **kwargs)
  File "/home/lgl/virtualenvs/py3_django/lib/python3.6/site-packages/rest_framework/views.py", line 483, in dispatch
    response = self.handle_exception(exc)
  File "/home/lgl/virtualenvs/py3_django/lib/python3.6/site-packages/rest_framework/views.py", line 443, in handle_exception
    self.raise_uncaught_exception(exc)
  File "/home/lgl/virtualenvs/py3_django/lib/python3.6/site-packages/rest_framework/views.py", line 480, in dispatch
    response = handler(request, *args, **kwargs)
  File "/home/lgl/workplace/django_project/meiduo_mall/meiduo_mall/apps/verifications/views.py", line 32, in get
    redis_conn.setex("img_%s" % image_code_id, constants.IMAGE_CODE_REDIS_EXPIRES, text)
AttributeError: module 'celery_tasks.sms.constants' has no attribute 'IMAGE_CODE_REDIS_EXPIRES'
ERROR 2019-10-08 14:26:46,003 basehttp 124 "GET /image_codes/a864f7c9-e376-4c95-ba04-f539c9e89e10/ HTTP/1.1" 500 19145
ERROR 2019-10-08 14:26:46,935 log 228 Internal Server Error: /image_codes/3924b5d1-72db-434c-ac73-815c0a864090/
Traceback (most recent call last):
  File "/home/lgl/virtualenvs/py3_django/lib/python3.6/site-packages/django/core/handlers/exception.py", line 34, in inner
    response = get_response(request)
  File "/home/lgl/virtualenvs/py3_django/lib/python3.6/site-packages/django/core/handlers/base.py", line 126, in _get_response
    response = self.process_exception_by_middleware(e, request)
  File "/home/lgl/virtualenvs/py3_django/lib/python3.6/site-packages/django/core/handlers/base.py", line 124, in _get_response
    response = wrapped_callback(request, *callback_args, **callback_kwargs)
  File "/home/lgl/virtualenvs/py3_django/lib/python3.6/site-packages/django/views/decorators/csrf.py", line 54, in wrapped_view
    return view_func(*args, **kwargs)
  File "/home/lgl/virtualenvs/py3_django/lib/python3.6/site-packages/django/views/generic/base.py", line 68, in view
    return self.dispatch(request, *args, **kwargs)
  File "/home/lgl/virtualenvs/py3_django/lib/python3.6/site-packages/rest_framework/views.py", line 483, in dispatch
    response = self.handle_exception(exc)
  File "/home/lgl/virtualenvs/py3_django/lib/python3.6/site-packages/rest_framework/views.py", line 443, in handle_exception
    self.raise_uncaught_exception(exc)
  File "/home/lgl/virtualenvs/py3_django/lib/python3.6/site-packages/rest_framework/views.py", line 480, in dispatch
    response = handler(request, *args, **kwargs)
  File "/home/lgl/workplace/django_project/meiduo_mall/meiduo_mall/apps/verifications/views.py", line 32, in get
    redis_conn.setex("img_%s" % image_code_id, constants.IMAGE_CODE_REDIS_EXPIRES, text)
AttributeError: module 'celery_tasks.sms.constants' has no attribute 'IMAGE_CODE_REDIS_EXPIRES'
ERROR 2019-10-08 14:26:46,936 basehttp 124 "GET /image_codes/3924b5d1-72db-434c-ac73-815c0a864090/ HTTP/1.1" 500 19145
ERROR 2019-10-08 14:26:47,370 log 228 Internal Server Error: /image_codes/ccdc8ad9-5ba6-4fac-87bc-f9a66951b2a1/
Traceback (most recent call last):
  File "/home/lgl/virtualenvs/py3_django/lib/python3.6/site-packages/django/core/handlers/exception.py", line 34, in inner
    response = get_response(request)
  File "/home/lgl/virtualenvs/py3_django/lib/python3.6/site-packages/django/core/handlers/base.py", line 126, in _get_response
    response = self.process_exception_by_middleware(e, request)
  File "/home/lgl/virtualenvs/py3_django/lib/python3.6/site-packages/django/core/handlers/base.py", line 124, in _get_response
    response = wrapped_callback(request, *callback_args, **callback_kwargs)
  File "/home/lgl/virtualenvs/py3_django/lib/python3.6/site-packages/django/views/decorators/csrf.py", line 54, in wrapped_view
    return view_func(*args, **kwargs)
  File "/home/lgl/virtualenvs/py3_django/lib/python3.6/site-packages/django/views/generic/base.py", line 68, in view
    return self.dispatch(request, *args, **kwargs)
  File "/home/lgl/virtualenvs/py3_django/lib/python3.6/site-packages/rest_framework/views.py", line 483, in dispatch
    response = self.handle_exception(exc)
  File "/home/lgl/virtualenvs/py3_django/lib/python3.6/site-packages/rest_framework/views.py", line 443, in handle_exception
    self.raise_uncaught_exception(exc)
  File "/home/lgl/virtualenvs/py3_django/lib/python3.6/site-packages/rest_framework/views.py", line 480, in dispatch
    response = handler(request, *args, **kwargs)
  File "/home/lgl/workplace/django_project/meiduo_mall/meiduo_mall/apps/verifications/views.py", line 32, in get
    redis_conn.setex("img_%s" % image_code_id, constants.IMAGE_CODE_REDIS_EXPIRES, text)
AttributeError: module 'celery_tasks.sms.constants' has no attribute 'IMAGE_CODE_REDIS_EXPIRES'
ERROR 2019-10-08 14:26:47,371 basehttp 124 "GET /image_codes/ccdc8ad9-5ba6-4fac-87bc-f9a66951b2a1/ HTTP/1.1" 500 19145
ERROR 2019-10-08 14:26:47,596 log 228 Internal Server Error: /image_codes/a5b63b95-8bea-42ff-be33-18ab18e8de7d/
Traceback (most recent call last):
  File "/home/lgl/virtualenvs/py3_django/lib/python3.6/site-packages/django/core/handlers/exception.py", line 34, in inner
    response = get_response(request)
  File "/home/lgl/virtualenvs/py3_django/lib/python3.6/site-packages/django/core/handlers/base.py", line 126, in _get_response
    response = self.process_exception_by_middleware(e, request)
  File "/home/lgl/virtualenvs/py3_django/lib/python3.6/site-packages/django/core/handlers/base.py", line 124, in _get_response
    response = wrapped_callback(request, *callback_args, **callback_kwargs)
  File "/home/lgl/virtualenvs/py3_django/lib/python3.6/site-packages/django/views/decorators/csrf.py", line 54, in wrapped_view
    return view_func(*args, **kwargs)
  File "/home/lgl/virtualenvs/py3_django/lib/python3.6/site-packages/django/views/generic/base.py", line 68, in view
    return self.dispatch(request, *args, **kwargs)
  File "/home/lgl/virtualenvs/py3_django/lib/python3.6/site-packages/rest_framework/views.py", line 483, in dispatch
    response = self.handle_exception(exc)
  File "/home/lgl/virtualenvs/py3_django/lib/python3.6/site-packages/rest_framework/views.py", line 443, in handle_exception
    self.raise_uncaught_exception(exc)
  File "/home/lgl/virtualenvs/py3_django/lib/python3.6/site-packages/rest_framework/views.py", line 480, in dispatch
    response = handler(request, *args, **kwargs)
  File "/home/lgl/workplace/django_project/meiduo_mall/meiduo_mall/apps/verifications/views.py", line 32, in get
    redis_conn.setex("img_%s" % image_code_id, constants.IMAGE_CODE_REDIS_EXPIRES, text)
AttributeError: module 'celery_tasks.sms.constants' has no attribute 'IMAGE_CODE_REDIS_EXPIRES'
ERROR 2019-10-08 14:26:47,597 basehttp 124 "GET /image_codes/a5b63b95-8bea-42ff-be33-18ab18e8de7d/ HTTP/1.1" 500 19145
ERROR 2019-10-08 14:26:47,781 log 228 Internal Server Error: /image_codes/56a42bee-41b1-453e-a310-2fce7e51dfc2/
Traceback (most recent call last):
  File "/home/lgl/virtualenvs/py3_django/lib/python3.6/site-packages/django/core/handlers/exception.py", line 34, in inner
    response = get_response(request)
  File "/home/lgl/virtualenvs/py3_django/lib/python3.6/site-packages/django/core/handlers/base.py", line 126, in _get_response
    response = self.process_exception_by_middleware(e, request)
  File "/home/lgl/virtualenvs/py3_django/lib/python3.6/site-packages/django/core/handlers/base.py", line 124, in _get_response
    response = wrapped_callback(request, *callback_args, **callback_kwargs)
  File "/home/lgl/virtualenvs/py3_django/lib/python3.6/site-packages/django/views/decorators/csrf.py", line 54, in wrapped_view
    return view_func(*args, **kwargs)
  File "/home/lgl/virtualenvs/py3_django/lib/python3.6/site-packages/django/views/generic/base.py", line 68, in view
    return self.dispatch(request, *args, **kwargs)
  File "/home/lgl/virtualenvs/py3_django/lib/python3.6/site-packages/rest_framework/views.py", line 483, in dispatch
    response = self.handle_exception(exc)
  File "/home/lgl/virtualenvs/py3_django/lib/python3.6/site-packages/rest_framework/views.py", line 443, in handle_exception
    self.raise_uncaught_exception(exc)
  File "/home/lgl/virtualenvs/py3_django/lib/python3.6/site-packages/rest_framework/views.py", line 480, in dispatch
    response = handler(request, *args, **kwargs)
  File "/home/lgl/workplace/django_project/meiduo_mall/meiduo_mall/apps/verifications/views.py", line 32, in get
    redis_conn.setex("img_%s" % image_code_id, constants.IMAGE_CODE_REDIS_EXPIRES, text)
AttributeError: module 'celery_tasks.sms.constants' has no attribute 'IMAGE_CODE_REDIS_EXPIRES'
ERROR 2019-10-08 14:26:47,782 basehttp 124 "GET /image_codes/56a42bee-41b1-453e-a310-2fce7e51dfc2/ HTTP/1.1" 500 19145
WARNING 2019-10-08 14:27:18,271 log 228 Not Found: /
WARNING 2019-10-08 14:27:18,271 basehttp 124 "GET / HTTP/1.1" 404 2114
WARNING 2019-10-08 14:27:18,317 log 228 Not Found: /favicon.ico
WARNING 2019-10-08 14:27:18,317 basehttp 124 "GET /favicon.ico HTTP/1.1" 404 2165
ERROR 2019-10-08 14:27:26,379 log 228 Internal Server Error: /image_codes/1659da81-c726-446c-8c67-454622f96bce/
Traceback (most recent call last):
  File "/home/lgl/virtualenvs/py3_django/lib/python3.6/site-packages/django/core/handlers/exception.py", line 34, in inner
    response = get_response(request)
  File "/home/lgl/virtualenvs/py3_django/lib/python3.6/site-packages/django/core/handlers/base.py", line 126, in _get_response
    response = self.process_exception_by_middleware(e, request)
  File "/home/lgl/virtualenvs/py3_django/lib/python3.6/site-packages/django/core/handlers/base.py", line 124, in _get_response
    response = wrapped_callback(request, *callback_args, **callback_kwargs)
  File "/home/lgl/virtualenvs/py3_django/lib/python3.6/site-packages/django/views/decorators/csrf.py", line 54, in wrapped_view
    return view_func(*args, **kwargs)
  File "/home/lgl/virtualenvs/py3_django/lib/python3.6/site-packages/django/views/generic/base.py", line 68, in view
    return self.dispatch(request, *args, **kwargs)
  File "/home/lgl/virtualenvs/py3_django/lib/python3.6/site-packages/rest_framework/views.py", line 483, in dispatch
    response = self.handle_exception(exc)
  File "/home/lgl/virtualenvs/py3_django/lib/python3.6/site-packages/rest_framework/views.py", line 443, in handle_exception
    self.raise_uncaught_exception(exc)
  File "/home/lgl/virtualenvs/py3_django/lib/python3.6/site-packages/rest_framework/views.py", line 480, in dispatch
    response = handler(request, *args, **kwargs)
  File "/home/lgl/workplace/django_project/meiduo_mall/meiduo_mall/apps/verifications/views.py", line 32, in get
    redis_conn.setex("img_%s" % image_code_id, constants.IMAGE_CODE_REDIS_EXPIRES, text)
AttributeError: module 'celery_tasks.sms.constants' has no attribute 'IMAGE_CODE_REDIS_EXPIRES'
ERROR 2019-10-08 14:27:26,380 basehttp 124 "GET /image_codes/1659da81-c726-446c-8c67-454622f96bce/ HTTP/1.1" 500 19145
ERROR 2019-10-08 14:27:27,629 log 228 Internal Server Error: /image_codes/b58ddc7e-6ee2-4b13-87d4-2ef27c83df8a/
Traceback (most recent call last):
  File "/home/lgl/virtualenvs/py3_django/lib/python3.6/site-packages/django/core/handlers/exception.py", line 34, in inner
    response = get_response(request)
  File "/home/lgl/virtualenvs/py3_django/lib/python3.6/site-packages/django/core/handlers/base.py", line 126, in _get_response
    response = self.process_exception_by_middleware(e, request)
  File "/home/lgl/virtualenvs/py3_django/lib/python3.6/site-packages/django/core/handlers/base.py", line 124, in _get_response
    response = wrapped_callback(request, *callback_args, **callback_kwargs)
  File "/home/lgl/virtualenvs/py3_django/lib/python3.6/site-packages/django/views/decorators/csrf.py", line 54, in wrapped_view
    return view_func(*args, **kwargs)
  File "/home/lgl/virtualenvs/py3_django/lib/python3.6/site-packages/django/views/generic/base.py", line 68, in view
    return self.dispatch(request, *args, **kwargs)
  File "/home/lgl/virtualenvs/py3_django/lib/python3.6/site-packages/rest_framework/views.py", line 483, in dispatch
    response = self.handle_exception(exc)
  File "/home/lgl/virtualenvs/py3_django/lib/python3.6/site-packages/rest_framework/views.py", line 443, in handle_exception
    self.raise_uncaught_exception(exc)
  File "/home/lgl/virtualenvs/py3_django/lib/python3.6/site-packages/rest_framework/views.py", line 480, in dispatch
    response = handler(request, *args, **kwargs)
  File "/home/lgl/workplace/django_project/meiduo_mall/meiduo_mall/apps/verifications/views.py", line 32, in get
    redis_conn.setex("img_%s" % image_code_id, constants.IMAGE_CODE_REDIS_EXPIRES, text)
AttributeError: module 'celery_tasks.sms.constants' has no attribute 'IMAGE_CODE_REDIS_EXPIRES'
ERROR 2019-10-08 14:27:27,630 basehttp 124 "GET /image_codes/b58ddc7e-6ee2-4b13-87d4-2ef27c83df8a/ HTTP/1.1" 500 19145
ERROR 2019-10-08 14:27:28,081 log 228 Internal Server Error: /image_codes/fcd96b37-3342-4aa5-925e-93a232ba4706/
Traceback (most recent call last):
  File "/home/lgl/virtualenvs/py3_django/lib/python3.6/site-packages/django/core/handlers/exception.py", line 34, in inner
    response = get_response(request)
  File "/home/lgl/virtualenvs/py3_django/lib/python3.6/site-packages/django/core/handlers/base.py", line 126, in _get_response
    response = self.process_exception_by_middleware(e, request)
  File "/home/lgl/virtualenvs/py3_django/lib/python3.6/site-packages/django/core/handlers/base.py", line 124, in _get_response
    response = wrapped_callback(request, *callback_args, **callback_kwargs)
  File "/home/lgl/virtualenvs/py3_django/lib/python3.6/site-packages/django/views/decorators/csrf.py", line 54, in wrapped_view
    return view_func(*args, **kwargs)
  File "/home/lgl/virtualenvs/py3_django/lib/python3.6/site-packages/django/views/generic/base.py", line 68, in view
    return self.dispatch(request, *args, **kwargs)
  File "/home/lgl/virtualenvs/py3_django/lib/python3.6/site-packages/rest_framework/views.py", line 483, in dispatch
    response = self.handle_exception(exc)
  File "/home/lgl/virtualenvs/py3_django/lib/python3.6/site-packages/rest_framework/views.py", line 443, in handle_exception
    self.raise_uncaught_exception(exc)
  File "/home/lgl/virtualenvs/py3_django/lib/python3.6/site-packages/rest_framework/views.py", line 480, in dispatch
    response = handler(request, *args, **kwargs)
  File "/home/lgl/workplace/django_project/meiduo_mall/meiduo_mall/apps/verifications/views.py", line 32, in get
    redis_conn.setex("img_%s" % image_code_id, constants.IMAGE_CODE_REDIS_EXPIRES, text)
AttributeError: module 'celery_tasks.sms.constants' has no attribute 'IMAGE_CODE_REDIS_EXPIRES'
ERROR 2019-10-08 14:27:28,082 basehttp 124 "GET /image_codes/fcd96b37-3342-4aa5-925e-93a232ba4706/ HTTP/1.1" 500 19145
ERROR 2019-10-08 14:27:28,256 log 228 Internal Server Error: /image_codes/afecb0a7-4815-4c53-aead-279c5716f081/
Traceback (most recent call last):
  File "/home/lgl/virtualenvs/py3_django/lib/python3.6/site-packages/django/core/handlers/exception.py", line 34, in inner
    response = get_response(request)
  File "/home/lgl/virtualenvs/py3_django/lib/python3.6/site-packages/django/core/handlers/base.py", line 126, in _get_response
    response = self.process_exception_by_middleware(e, request)
  File "/home/lgl/virtualenvs/py3_django/lib/python3.6/site-packages/django/core/handlers/base.py", line 124, in _get_response
    response = wrapped_callback(request, *callback_args, **callback_kwargs)
  File "/home/lgl/virtualenvs/py3_django/lib/python3.6/site-packages/django/views/decorators/csrf.py", line 54, in wrapped_view
    return view_func(*args, **kwargs)
  File "/home/lgl/virtualenvs/py3_django/lib/python3.6/site-packages/django/views/generic/base.py", line 68, in view
    return self.dispatch(request, *args, **kwargs)
  File "/home/lgl/virtualenvs/py3_django/lib/python3.6/site-packages/rest_framework/views.py", line 483, in dispatch
    response = self.handle_exception(exc)
  File "/home/lgl/virtualenvs/py3_django/lib/python3.6/site-packages/rest_framework/views.py", line 443, in handle_exception
    self.raise_uncaught_exception(exc)
  File "/home/lgl/virtualenvs/py3_django/lib/python3.6/site-packages/rest_framework/views.py", line 480, in dispatch
    response = handler(request, *args, **kwargs)
  File "/home/lgl/workplace/django_project/meiduo_mall/meiduo_mall/apps/verifications/views.py", line 32, in get
    redis_conn.setex("img_%s" % image_code_id, constants.IMAGE_CODE_REDIS_EXPIRES, text)
AttributeError: module 'celery_tasks.sms.constants' has no attribute 'IMAGE_CODE_REDIS_EXPIRES'
ERROR 2019-10-08 14:27:28,257 basehttp 124 "GET /image_codes/afecb0a7-4815-4c53-aead-279c5716f081/ HTTP/1.1" 500 19145
ERROR 2019-10-08 14:27:28,412 log 228 Internal Server Error: /image_codes/4264d985-674f-464f-99e7-74445cc56ef4/
Traceback (most recent call last):
  File "/home/lgl/virtualenvs/py3_django/lib/python3.6/site-packages/django/core/handlers/exception.py", line 34, in inner
    response = get_response(request)
  File "/home/lgl/virtualenvs/py3_django/lib/python3.6/site-packages/django/core/handlers/base.py", line 126, in _get_response
    response = self.process_exception_by_middleware(e, request)
  File "/home/lgl/virtualenvs/py3_django/lib/python3.6/site-packages/django/core/handlers/base.py", line 124, in _get_response
    response = wrapped_callback(request, *callback_args, **callback_kwargs)
  File "/home/lgl/virtualenvs/py3_django/lib/python3.6/site-packages/django/views/decorators/csrf.py", line 54, in wrapped_view
    return view_func(*args, **kwargs)
  File "/home/lgl/virtualenvs/py3_django/lib/python3.6/site-packages/django/views/generic/base.py", line 68, in view
    return self.dispatch(request, *args, **kwargs)
  File "/home/lgl/virtualenvs/py3_django/lib/python3.6/site-packages/rest_framework/views.py", line 483, in dispatch
    response = self.handle_exception(exc)
  File "/home/lgl/virtualenvs/py3_django/lib/python3.6/site-packages/rest_framework/views.py", line 443, in handle_exception
    self.raise_uncaught_exception(exc)
  File "/home/lgl/virtualenvs/py3_django/lib/python3.6/site-packages/rest_framework/views.py", line 480, in dispatch
    response = handler(request, *args, **kwargs)
  File "/home/lgl/workplace/django_project/meiduo_mall/meiduo_mall/apps/verifications/views.py", line 32, in get
    redis_conn.setex("img_%s" % image_code_id, constants.IMAGE_CODE_REDIS_EXPIRES, text)
AttributeError: module 'celery_tasks.sms.constants' has no attribute 'IMAGE_CODE_REDIS_EXPIRES'
ERROR 2019-10-08 14:27:28,413 basehttp 124 "GET /image_codes/4264d985-674f-464f-99e7-74445cc56ef4/ HTTP/1.1" 500 19145
ERROR 2019-10-08 14:29:48,712 log 228 Internal Server Error: /image_codes/22548280-9407-45c5-9361-864a937fb887/
Traceback (most recent call last):
  File "/home/lgl/virtualenvs/py3_django/lib/python3.6/site-packages/django/core/handlers/exception.py", line 34, in inner
    response = get_response(request)
  File "/home/lgl/virtualenvs/py3_django/lib/python3.6/site-packages/django/core/handlers/base.py", line 126, in _get_response
    response = self.process_exception_by_middleware(e, request)
  File "/home/lgl/virtualenvs/py3_django/lib/python3.6/site-packages/django/core/handlers/base.py", line 124, in _get_response
    response = wrapped_callback(request, *callback_args, **callback_kwargs)
  File "/home/lgl/virtualenvs/py3_django/lib/python3.6/site-packages/django/views/decorators/csrf.py", line 54, in wrapped_view
    return view_func(*args, **kwargs)
  File "/home/lgl/virtualenvs/py3_django/lib/python3.6/site-packages/django/views/generic/base.py", line 68, in view
    return self.dispatch(request, *args, **kwargs)
  File "/home/lgl/virtualenvs/py3_django/lib/python3.6/site-packages/rest_framework/views.py", line 483, in dispatch
    response = self.handle_exception(exc)
  File "/home/lgl/virtualenvs/py3_django/lib/python3.6/site-packages/rest_framework/views.py", line 443, in handle_exception
    self.raise_uncaught_exception(exc)
  File "/home/lgl/virtualenvs/py3_django/lib/python3.6/site-packages/rest_framework/views.py", line 480, in dispatch
    response = handler(request, *args, **kwargs)
  File "/home/lgl/workplace/django_project/meiduo_mall/meiduo_mall/apps/verifications/views.py", line 32, in get
    redis_conn.setex("img_%s" % image_code_id, constants.IMAGE_CODE_REDIS_EXPIRES, text)
AttributeError: module 'celery_tasks.sms.constants' has no attribute 'IMAGE_CODE_REDIS_EXPIRES'
ERROR 2019-10-08 14:29:48,713 basehttp 124 "GET /image_codes/22548280-9407-45c5-9361-864a937fb887/ HTTP/1.1" 500 19145
ERROR 2019-10-08 14:29:50,783 log 228 Internal Server Error: /image_codes/3f5d67b5-6643-48d2-a77f-087b86ae4d58/
Traceback (most recent call last):
  File "/home/lgl/virtualenvs/py3_django/lib/python3.6/site-packages/django/core/handlers/exception.py", line 34, in inner
    response = get_response(request)
  File "/home/lgl/virtualenvs/py3_django/lib/python3.6/site-packages/django/core/handlers/base.py", line 126, in _get_response
    response = self.process_exception_by_middleware(e, request)
  File "/home/lgl/virtualenvs/py3_django/lib/python3.6/site-packages/django/core/handlers/base.py", line 124, in _get_response
    response = wrapped_callback(request, *callback_args, **callback_kwargs)
  File "/home/lgl/virtualenvs/py3_django/lib/python3.6/site-packages/django/views/decorators/csrf.py", line 54, in wrapped_view
    return view_func(*args, **kwargs)
  File "/home/lgl/virtualenvs/py3_django/lib/python3.6/site-packages/django/views/generic/base.py", line 68, in view
    return self.dispatch(request, *args, **kwargs)
  File "/home/lgl/virtualenvs/py3_django/lib/python3.6/site-packages/rest_framework/views.py", line 483, in dispatch
    response = self.handle_exception(exc)
  File "/home/lgl/virtualenvs/py3_django/lib/python3.6/site-packages/rest_framework/views.py", line 443, in handle_exception
    self.raise_uncaught_exception(exc)
  File "/home/lgl/virtualenvs/py3_django/lib/python3.6/site-packages/rest_framework/views.py", line 480, in dispatch
    response = handler(request, *args, **kwargs)
  File "/home/lgl/workplace/django_project/meiduo_mall/meiduo_mall/apps/verifications/views.py", line 32, in get
    redis_conn.setex("img_%s" % image_code_id, constants.IMAGE_CODE_REDIS_EXPIRES, text)
AttributeError: module 'celery_tasks.sms.constants' has no attribute 'IMAGE_CODE_REDIS_EXPIRES'
ERROR 2019-10-08 14:29:50,784 basehttp 124 "GET /image_codes/3f5d67b5-6643-48d2-a77f-087b86ae4d58/ HTTP/1.1" 500 19145
INFO 2019-10-08 14:29:53,726 basehttp 124 "OPTIONS /cart/ HTTP/1.1" 200 0
WARNING 2019-10-08 14:29:53,759 log 228 Not Found: /cart/
WARNING 2019-10-08 14:29:53,759 basehttp 124 "GET /cart/ HTTP/1.1" 404 2152
INFO 2019-10-08 14:30:28,775 basehttp 124 "OPTIONS /cart/ HTTP/1.1" 200 0
WARNING 2019-10-08 14:30:28,822 log 228 Not Found: /cart/
WARNING 2019-10-08 14:30:28,823 basehttp 124 "GET /cart/ HTTP/1.1" 404 2152
WARNING 2019-10-08 14:30:36,957 log 228 Not Found: /cart/
WARNING 2019-10-08 14:30:36,958 basehttp 124 "GET /cart/ HTTP/1.1" 404 2152
WARNING 2019-10-08 14:30:37,252 log 228 Not Found: /cart/
WARNING 2019-10-08 14:30:37,253 basehttp 124 "GET /cart/ HTTP/1.1" 404 2152
ERROR 2019-10-08 14:30:39,952 log 228 Internal Server Error: /image_codes/a5e2f68d-a344-4d5c-94e2-dc5c599dbcec/
Traceback (most recent call last):
  File "/home/lgl/virtualenvs/py3_django/lib/python3.6/site-packages/django/core/handlers/exception.py", line 34, in inner
    response = get_response(request)
  File "/home/lgl/virtualenvs/py3_django/lib/python3.6/site-packages/django/core/handlers/base.py", line 126, in _get_response
    response = self.process_exception_by_middleware(e, request)
  File "/home/lgl/virtualenvs/py3_django/lib/python3.6/site-packages/django/core/handlers/base.py", line 124, in _get_response
    response = wrapped_callback(request, *callback_args, **callback_kwargs)
  File "/home/lgl/virtualenvs/py3_django/lib/python3.6/site-packages/django/views/decorators/csrf.py", line 54, in wrapped_view
    return view_func(*args, **kwargs)
  File "/home/lgl/virtualenvs/py3_django/lib/python3.6/site-packages/django/views/generic/base.py", line 68, in view
    return self.dispatch(request, *args, **kwargs)
  File "/home/lgl/virtualenvs/py3_django/lib/python3.6/site-packages/rest_framework/views.py", line 483, in dispatch
    response = self.handle_exception(exc)
  File "/home/lgl/virtualenvs/py3_django/lib/python3.6/site-packages/rest_framework/views.py", line 443, in handle_exception
    self.raise_uncaught_exception(exc)
  File "/home/lgl/virtualenvs/py3_django/lib/python3.6/site-packages/rest_framework/views.py", line 480, in dispatch
    response = handler(request, *args, **kwargs)
  File "/home/lgl/workplace/django_project/meiduo_mall/meiduo_mall/apps/verifications/views.py", line 32, in get
    redis_conn.setex("img_%s" % image_code_id, constants.IMAGE_CODE_REDIS_EXPIRES, text)
AttributeError: module 'celery_tasks.sms.constants' has no attribute 'IMAGE_CODE_REDIS_EXPIRES'
ERROR 2019-10-08 14:30:39,953 basehttp 124 "GET /image_codes/a5e2f68d-a344-4d5c-94e2-dc5c599dbcec/ HTTP/1.1" 500 19145
INFO 2019-10-08 14:31:12,736 basehttp 124 "OPTIONS /cart/ HTTP/1.1" 200 0
WARNING 2019-10-08 14:31:12,788 log 228 Not Found: /cart/
WARNING 2019-10-08 14:31:12,788 basehttp 124 "GET /cart/ HTTP/1.1" 404 2152
ERROR 2019-10-08 14:31:23,266 log 228 Internal Server Error: /image_codes/82a1dd06-3d0d-49dd-b349-ee94b4afceea/
Traceback (most recent call last):
  File "/home/lgl/virtualenvs/py3_django/lib/python3.6/site-packages/django/core/handlers/exception.py", line 34, in inner
    response = get_response(request)
  File "/home/lgl/virtualenvs/py3_django/lib/python3.6/site-packages/django/core/handlers/base.py", line 126, in _get_response
    response = self.process_exception_by_middleware(e, request)
  File "/home/lgl/virtualenvs/py3_django/lib/python3.6/site-packages/django/core/handlers/base.py", line 124, in _get_response
    response = wrapped_callback(request, *callback_args, **callback_kwargs)
  File "/home/lgl/virtualenvs/py3_django/lib/python3.6/site-packages/django/views/decorators/csrf.py", line 54, in wrapped_view
    return view_func(*args, **kwargs)
  File "/home/lgl/virtualenvs/py3_django/lib/python3.6/site-packages/django/views/generic/base.py", line 68, in view
    return self.dispatch(request, *args, **kwargs)
  File "/home/lgl/virtualenvs/py3_django/lib/python3.6/site-packages/rest_framework/views.py", line 483, in dispatch
    response = self.handle_exception(exc)
  File "/home/lgl/virtualenvs/py3_django/lib/python3.6/site-packages/rest_framework/views.py", line 443, in handle_exception
    self.raise_uncaught_exception(exc)
  File "/home/lgl/virtualenvs/py3_django/lib/python3.6/site-packages/rest_framework/views.py", line 480, in dispatch
    response = handler(request, *args, **kwargs)
  File "/home/lgl/workplace/django_project/meiduo_mall/meiduo_mall/apps/verifications/views.py", line 32, in get
    redis_conn.setex("img_%s" % image_code_id, constants.IMAGE_CODE_REDIS_EXPIRES, text)
AttributeError: module 'celery_tasks.sms.constants' has no attribute 'IMAGE_CODE_REDIS_EXPIRES'
ERROR 2019-10-08 14:31:23,267 basehttp 124 "GET /image_codes/82a1dd06-3d0d-49dd-b349-ee94b4afceea/ HTTP/1.1" 500 19145
ERROR 2019-10-08 14:31:26,438 log 228 Internal Server Error: /image_codes/ba589419-9976-4c40-acd6-423b4306e048/
Traceback (most recent call last):
  File "/home/lgl/virtualenvs/py3_django/lib/python3.6/site-packages/django/core/handlers/exception.py", line 34, in inner
    response = get_response(request)
  File "/home/lgl/virtualenvs/py3_django/lib/python3.6/site-packages/django/core/handlers/base.py", line 126, in _get_response
    response = self.process_exception_by_middleware(e, request)
  File "/home/lgl/virtualenvs/py3_django/lib/python3.6/site-packages/django/core/handlers/base.py", line 124, in _get_response
    response = wrapped_callback(request, *callback_args, **callback_kwargs)
  File "/home/lgl/virtualenvs/py3_django/lib/python3.6/site-packages/django/views/decorators/csrf.py", line 54, in wrapped_view
    return view_func(*args, **kwargs)
  File "/home/lgl/virtualenvs/py3_django/lib/python3.6/site-packages/django/views/generic/base.py", line 68, in view
    return self.dispatch(request, *args, **kwargs)
  File "/home/lgl/virtualenvs/py3_django/lib/python3.6/site-packages/rest_framework/views.py", line 483, in dispatch
    response = self.handle_exception(exc)
  File "/home/lgl/virtualenvs/py3_django/lib/python3.6/site-packages/rest_framework/views.py", line 443, in handle_exception
    self.raise_uncaught_exception(exc)
  File "/home/lgl/virtualenvs/py3_django/lib/python3.6/site-packages/rest_framework/views.py", line 480, in dispatch
    response = handler(request, *args, **kwargs)
  File "/home/lgl/workplace/django_project/meiduo_mall/meiduo_mall/apps/verifications/views.py", line 32, in get
    redis_conn.setex("img_%s" % image_code_id, constants.IMAGE_CODE_REDIS_EXPIRES, text)
AttributeError: module 'celery_tasks.sms.constants' has no attribute 'IMAGE_CODE_REDIS_EXPIRES'
ERROR 2019-10-08 14:31:26,439 basehttp 124 "GET /image_codes/ba589419-9976-4c40-acd6-423b4306e048/ HTTP/1.1" 500 19145
ERROR 2019-10-08 14:31:27,129 log 228 Internal Server Error: /image_codes/73ccb432-8f6e-4425-9a5a-1e29074b32fa/
Traceback (most recent call last):
  File "/home/lgl/virtualenvs/py3_django/lib/python3.6/site-packages/django/core/handlers/exception.py", line 34, in inner
    response = get_response(request)
  File "/home/lgl/virtualenvs/py3_django/lib/python3.6/site-packages/django/core/handlers/base.py", line 126, in _get_response
    response = self.process_exception_by_middleware(e, request)
  File "/home/lgl/virtualenvs/py3_django/lib/python3.6/site-packages/django/core/handlers/base.py", line 124, in _get_response
    response = wrapped_callback(request, *callback_args, **callback_kwargs)
  File "/home/lgl/virtualenvs/py3_django/lib/python3.6/site-packages/django/views/decorators/csrf.py", line 54, in wrapped_view
    return view_func(*args, **kwargs)
  File "/home/lgl/virtualenvs/py3_django/lib/python3.6/site-packages/django/views/generic/base.py", line 68, in view
    return self.dispatch(request, *args, **kwargs)
  File "/home/lgl/virtualenvs/py3_django/lib/python3.6/site-packages/rest_framework/views.py", line 483, in dispatch
    response = self.handle_exception(exc)
  File "/home/lgl/virtualenvs/py3_django/lib/python3.6/site-packages/rest_framework/views.py", line 443, in handle_exception
    self.raise_uncaught_exception(exc)
  File "/home/lgl/virtualenvs/py3_django/lib/python3.6/site-packages/rest_framework/views.py", line 480, in dispatch
    response = handler(request, *args, **kwargs)
  File "/home/lgl/workplace/django_project/meiduo_mall/meiduo_mall/apps/verifications/views.py", line 32, in get
    redis_conn.setex("img_%s" % image_code_id, constants.IMAGE_CODE_REDIS_EXPIRES, text)
AttributeError: module 'celery_tasks.sms.constants' has no attribute 'IMAGE_CODE_REDIS_EXPIRES'
ERROR 2019-10-08 14:31:27,130 basehttp 124 "GET /image_codes/73ccb432-8f6e-4425-9a5a-1e29074b32fa/ HTTP/1.1" 500 19145
ERROR 2019-10-08 14:31:30,934 log 228 Internal Server Error: /image_codes/680e72bd-247a-4461-8fca-b82d5138e0fb/
Traceback (most recent call last):
  File "/home/lgl/virtualenvs/py3_django/lib/python3.6/site-packages/django/core/handlers/exception.py", line 34, in inner
    response = get_response(request)
  File "/home/lgl/virtualenvs/py3_django/lib/python3.6/site-packages/django/core/handlers/base.py", line 126, in _get_response
    response = self.process_exception_by_middleware(e, request)
  File "/home/lgl/virtualenvs/py3_django/lib/python3.6/site-packages/django/core/handlers/base.py", line 124, in _get_response
    response = wrapped_callback(request, *callback_args, **callback_kwargs)
  File "/home/lgl/virtualenvs/py3_django/lib/python3.6/site-packages/django/views/decorators/csrf.py", line 54, in wrapped_view
    return view_func(*args, **kwargs)
  File "/home/lgl/virtualenvs/py3_django/lib/python3.6/site-packages/django/views/generic/base.py", line 68, in view
    return self.dispatch(request, *args, **kwargs)
  File "/home/lgl/virtualenvs/py3_django/lib/python3.6/site-packages/rest_framework/views.py", line 483, in dispatch
    response = self.handle_exception(exc)
  File "/home/lgl/virtualenvs/py3_django/lib/python3.6/site-packages/rest_framework/views.py", line 443, in handle_exception
    self.raise_uncaught_exception(exc)
  File "/home/lgl/virtualenvs/py3_django/lib/python3.6/site-packages/rest_framework/views.py", line 480, in dispatch
    response = handler(request, *args, **kwargs)
  File "/home/lgl/workplace/django_project/meiduo_mall/meiduo_mall/apps/verifications/views.py", line 32, in get
    redis_conn.setex("img_%s" % image_code_id, constants.IMAGE_CODE_REDIS_EXPIRES, text)
AttributeError: module 'celery_tasks.sms.constants' has no attribute 'IMAGE_CODE_REDIS_EXPIRES'
ERROR 2019-10-08 14:31:30,934 basehttp 124 "GET /image_codes/680e72bd-247a-4461-8fca-b82d5138e0fb/ HTTP/1.1" 500 19145
ERROR 2019-10-08 14:31:31,966 log 228 Internal Server Error: /image_codes/40596475-7c7e-481b-9dd0-7af882980914/
Traceback (most recent call last):
  File "/home/lgl/virtualenvs/py3_django/lib/python3.6/site-packages/django/core/handlers/exception.py", line 34, in inner
    response = get_response(request)
  File "/home/lgl/virtualenvs/py3_django/lib/python3.6/site-packages/django/core/handlers/base.py", line 126, in _get_response
    response = self.process_exception_by_middleware(e, request)
  File "/home/lgl/virtualenvs/py3_django/lib/python3.6/site-packages/django/core/handlers/base.py", line 124, in _get_response
    response = wrapped_callback(request, *callback_args, **callback_kwargs)
  File "/home/lgl/virtualenvs/py3_django/lib/python3.6/site-packages/django/views/decorators/csrf.py", line 54, in wrapped_view
    return view_func(*args, **kwargs)
  File "/home/lgl/virtualenvs/py3_django/lib/python3.6/site-packages/django/views/generic/base.py", line 68, in view
    return self.dispatch(request, *args, **kwargs)
  File "/home/lgl/virtualenvs/py3_django/lib/python3.6/site-packages/rest_framework/views.py", line 483, in dispatch
    response = self.handle_exception(exc)
  File "/home/lgl/virtualenvs/py3_django/lib/python3.6/site-packages/rest_framework/views.py", line 443, in handle_exception
    self.raise_uncaught_exception(exc)
  File "/home/lgl/virtualenvs/py3_django/lib/python3.6/site-packages/rest_framework/views.py", line 480, in dispatch
    response = handler(request, *args, **kwargs)
  File "/home/lgl/workplace/django_project/meiduo_mall/meiduo_mall/apps/verifications/views.py", line 32, in get
    redis_conn.setex("img_%s" % image_code_id, constants.IMAGE_CODE_REDIS_EXPIRES, text)
AttributeError: module 'celery_tasks.sms.constants' has no attribute 'IMAGE_CODE_REDIS_EXPIRES'
ERROR 2019-10-08 14:31:31,967 basehttp 124 "GET /image_codes/40596475-7c7e-481b-9dd0-7af882980914/ HTTP/1.1" 500 19145
INFO 2019-10-08 14:34:28,879 basehttp 124 "OPTIONS /cart/ HTTP/1.1" 200 0
WARNING 2019-10-08 14:34:28,918 log 228 Not Found: /cart/
WARNING 2019-10-08 14:34:28,919 basehttp 124 "GET /cart/ HTTP/1.1" 404 2152
WARNING 2019-10-08 14:34:38,579 log 228 Not Found: /cart/
WARNING 2019-10-08 14:34:38,580 basehttp 124 "GET /cart/ HTTP/1.1" 404 2152
ERROR 2019-10-08 14:34:40,824 log 228 Internal Server Error: /image_codes/900fd82c-d8b5-4fea-8e92-fe388d5d4e1a/
Traceback (most recent call last):
  File "/home/lgl/virtualenvs/py3_django/lib/python3.6/site-packages/django/core/handlers/exception.py", line 34, in inner
    response = get_response(request)
  File "/home/lgl/virtualenvs/py3_django/lib/python3.6/site-packages/django/core/handlers/base.py", line 126, in _get_response
    response = self.process_exception_by_middleware(e, request)
  File "/home/lgl/virtualenvs/py3_django/lib/python3.6/site-packages/django/core/handlers/base.py", line 124, in _get_response
    response = wrapped_callback(request, *callback_args, **callback_kwargs)
  File "/home/lgl/virtualenvs/py3_django/lib/python3.6/site-packages/django/views/decorators/csrf.py", line 54, in wrapped_view
    return view_func(*args, **kwargs)
  File "/home/lgl/virtualenvs/py3_django/lib/python3.6/site-packages/django/views/generic/base.py", line 68, in view
    return self.dispatch(request, *args, **kwargs)
  File "/home/lgl/virtualenvs/py3_django/lib/python3.6/site-packages/rest_framework/views.py", line 483, in dispatch
    response = self.handle_exception(exc)
  File "/home/lgl/virtualenvs/py3_django/lib/python3.6/site-packages/rest_framework/views.py", line 443, in handle_exception
    self.raise_uncaught_exception(exc)
  File "/home/lgl/virtualenvs/py3_django/lib/python3.6/site-packages/rest_framework/views.py", line 480, in dispatch
    response = handler(request, *args, **kwargs)
  File "/home/lgl/workplace/django_project/meiduo_mall/meiduo_mall/apps/verifications/views.py", line 19, in get
    text, image = captcha.generate_captcha()
ValueError: too many values to unpack (expected 2)
ERROR 2019-10-08 14:34:40,826 basehttp 124 "GET /image_codes/900fd82c-d8b5-4fea-8e92-fe388d5d4e1a/ HTTP/1.1" 500 18961
INFO 2019-10-08 14:35:09,743 basehttp 124 "GET /image_codes/4fd7e054-f5fa-4271-adb8-319223d1f61a/ HTTP/1.1" 200 3756
INFO 2019-10-08 14:35:11,205 basehttp 124 "GET /image_codes/95fcde7a-8518-4d50-842c-e492ad75c636/ HTTP/1.1" 200 3481
INFO 2019-10-08 14:35:36,307 basehttp 124 "GET /image_codes/c21b4a93-8909-4b85-92af-372ef6b9ba92/ HTTP/1.1" 200 3271
INFO 2019-10-08 14:53:58,805 basehttp 124 "GET /image_codes/75014896-957d-4b1a-be02-f540b42e4c1a/ HTTP/1.1" 200 3081
WARNING 2019-10-08 14:54:34,446 log 228 Not Found: /mobiles/13020785602/count/
WARNING 2019-10-08 14:54:34,447 basehttp 124 "GET /mobiles/13020785602/count/ HTTP/1.1" 404 2215
WARNING 2019-10-08 14:54:35,578 log 228 Not Found: /sms_codes/13020785602/
WARNING 2019-10-08 14:54:35,579 log 228 Not Found: /mobiles/13020785602/count/
WARNING 2019-10-08 14:54:35,582 basehttp 124 "GET /mobiles/13020785602/count/ HTTP/1.1" 404 2215
WARNING 2019-10-08 14:54:35,584 basehttp 124 "GET /sms_codes/13020785602/?text=7UOF&image_code_id=75014896-957d-4b1a-be02-f540b42e4c1a HTTP/1.1" 404 2268
WARNING 2019-10-08 14:54:38,960 log 228 Not Found: /mobiles/13020785602/count/
WARNING 2019-10-08 14:54:38,966 basehttp 124 "GET /mobiles/13020785602/count/ HTTP/1.1" 404 2215
WARNING 2019-10-08 14:54:38,967 log 228 Not Found: /sms_codes/13020785602/
WARNING 2019-10-08 14:54:38,970 basehttp 124 "GET /sms_codes/13020785602/?text=7UOF&image_code_id=75014896-957d-4b1a-be02-f540b42e4c1a HTTP/1.1" 404 2268
INFO 2019-10-08 14:56:04,728 basehttp 124 "GET /image_codes/cb2f06c2-5e4d-4a22-b500-2d4f0ced5c42/ HTTP/1.1" 200 3015
WARNING 2019-10-08 14:56:24,361 log 228 Not Found: /mobiles/13020785602/count/
WARNING 2019-10-08 14:56:24,362 basehttp 124 "GET /mobiles/13020785602/count/ HTTP/1.1" 404 2215
WARNING 2019-10-08 14:56:24,441 log 228 Not Found: /mobiles/13020785602/count/
WARNING 2019-10-08 14:56:24,443 basehttp 124 "GET /mobiles/13020785602/count/ HTTP/1.1" 404 2215
WARNING 2019-10-08 14:56:24,444 log 228 Not Found: /sms_codes/13020785602/
WARNING 2019-10-08 14:56:24,445 basehttp 124 "GET /sms_codes/13020785602/?text=P9JZ&image_code_id=cb2f06c2-5e4d-4a22-b500-2d4f0ced5c42 HTTP/1.1" 404 2268
WARNING 2019-10-08 14:58:29,962 log 228 Not Found: /mobiles/13020785602/count/
WARNING 2019-10-08 14:58:29,963 log 228 Not Found: /sms_codes/13020785602/
WARNING 2019-10-08 14:58:29,964 basehttp 124 "GET /mobiles/13020785602/count/ HTTP/1.1" 404 2215
WARNING 2019-10-08 14:58:29,966 basehttp 124 "GET /sms_codes/13020785602/?text=P9JZ&image_code_id=cb2f06c2-5e4d-4a22-b500-2d4f0ced5c42 HTTP/1.1" 404 2268
WARNING 2019-10-08 14:59:09,322 log 228 Not Found: /mobiles/13020785602/count/
WARNING 2019-10-08 14:59:09,323 basehttp 124 "GET /mobiles/13020785602/count/ HTTP/1.1" 404 2215
WARNING 2019-10-08 14:59:09,362 log 228 Not Found: /favicon.ico
WARNING 2019-10-08 14:59:09,362 basehttp 124 "GET /favicon.ico HTTP/1.1" 404 2170
INFO 2019-10-08 15:05:47,244 basehttp 124 "GET /image_codes/dbae30a9-fcd1-4417-9cc7-7888d0f22a2e/ HTTP/1.1" 200 3141
WARNING 2019-10-08 15:06:08,982 log 228 Not Found: /mobiles/13020785602/count/
WARNING 2019-10-08 15:06:08,983 basehttp 124 "GET /mobiles/13020785602/count/ HTTP/1.1" 404 2405
WARNING 2019-10-08 15:06:09,777 log 228 Not Found: /sms_codes/13020785602/
WARNING 2019-10-08 15:06:09,779 log 228 Not Found: /mobiles/13020785602/count/
WARNING 2019-10-08 15:06:09,781 basehttp 124 "GET /sms_codes/13020785602/?text=HIE8&image_code_id=dbae30a9-fcd1-4417-9cc7-7888d0f22a2e HTTP/1.1" 404 2458
WARNING 2019-10-08 15:06:09,783 basehttp 124 "GET /mobiles/13020785602/count/ HTTP/1.1" 404 2405
INFO 2019-10-08 15:14:51,288 basehttp 124 "GET /image_codes/da5e5375-54d7-46d3-b496-18f7b15cc475/ HTTP/1.1" 200 3512
WARNING 2019-10-08 15:15:08,213 log 228 Not Found: /mobiles/13020785602/count/
WARNING 2019-10-08 15:15:08,214 basehttp 124 "GET /mobiles/13020785602/count/ HTTP/1.1" 404 2406
WARNING 2019-10-08 15:19:25,888 log 228 Not Found: /sms_codes/13020785602/
WARNING 2019-10-08 15:19:25,889 log 228 Not Found: /mobiles/13020785602/count/
WARNING 2019-10-08 15:19:25,890 basehttp 124 "GET /sms_codes/13020785602/?text=QTEM&image_code_id=da5e5375-54d7-46d3-b496-18f7b15cc475 HTTP/1.1" 404 2459
WARNING 2019-10-08 15:19:25,890 basehttp 124 "GET /mobiles/13020785602/count/ HTTP/1.1" 404 2406
INFO 2019-10-08 15:22:54,122 basehttp 124 "GET /image_codes/e952e3b6-9875-44e8-9f89-dba0b453b309/ HTTP/1.1" 200 3268
WARNING 2019-10-08 15:23:10,317 log 228 Not Found: /mobiles/13020785602/count/
WARNING 2019-10-08 15:23:10,318 basehttp 124 "GET /mobiles/13020785602/count/ HTTP/1.1" 404 2405
WARNING 2019-10-08 15:23:11,745 log 228 Not Found: /mobiles/13020785602/count/
WARNING 2019-10-08 15:23:11,749 log 228 Not Found: /sms_codes/13020785602/
WARNING 2019-10-08 15:23:11,751 basehttp 124 "GET /mobiles/13020785602/count/ HTTP/1.1" 404 2405
WARNING 2019-10-08 15:23:11,752 basehttp 124 "GET /sms_codes/13020785602/?text=I6RC&image_code_id=e952e3b6-9875-44e8-9f89-dba0b453b309 HTTP/1.1" 404 2458
INFO 2019-10-08 15:24:15,030 basehttp 124 "GET /image_codes/4123321b-3502-4852-9fbd-0c317f89233a/ HTTP/1.1" 200 3414
WARNING 2019-10-08 15:24:20,722 log 228 Not Found: /mobiles/13020785602/count/
WARNING 2019-10-08 15:24:20,723 basehttp 124 "GET /mobiles/13020785602/count/ HTTP/1.1" 404 2403
INFO 2019-10-08 15:24:33,930 basehttp 124 "GET /image_codes/b8271dc7-5ea8-4133-a1e0-b8ec4cbf64a4/ HTTP/1.1" 200 3233
WARNING 2019-10-08 15:24:49,884 log 228 Not Found: /mobiles/13020785602/count/
WARNING 2019-10-08 15:24:49,885 basehttp 124 "GET /mobiles/13020785602/count/ HTTP/1.1" 404 2403
WARNING 2019-10-08 15:24:51,719 log 228 Not Found: /mobiles/13020785602/count/
WARNING 2019-10-08 15:24:51,722 basehttp 124 "GET /mobiles/13020785602/count/ HTTP/1.1" 404 2403
INFO 2019-10-08 15:25:06,792 basehttp 124 "GET /image_codes/a43206ff-f671-4c99-bd60-7f59b2bdf39c/ HTTP/1.1" 200 3149
WARNING 2019-10-08 15:25:25,406 log 228 Not Found: /mobiles/13020785602/count/
WARNING 2019-10-08 15:25:25,406 basehttp 124 "GET /mobiles/13020785602/count/ HTTP/1.1" 404 2404
WARNING 2019-10-08 15:55:30,523 log 228 Not Found: /
WARNING 2019-10-08 15:55:30,523 basehttp 124 "GET / HTTP/1.1" 404 2303
WARNING 2019-10-08 15:55:30,580 log 228 Not Found: /favicon.ico
WARNING 2019-10-08 15:55:30,581 basehttp 124 "GET /favicon.ico HTTP/1.1" 404 2354
INFO 2019-10-08 15:55:46,255 basehttp 124 "GET /image_codes/d5ef5169-7ad2-47be-b036-95359ed15eda/ HTTP/1.1" 200 3562
WARNING 2019-10-08 15:56:08,935 log 228 Not Found: /mobiles/13020785602/count/
WARNING 2019-10-08 15:56:08,936 basehttp 124 "GET /mobiles/13020785602/count/ HTTP/1.1" 404 2404
INFO 2019-10-08 16:01:08,174 basehttp 124 "GET /image_codes/0ee682b4-0308-4426-a80a-3b94ee717cae/ HTTP/1.1" 200 3338
WARNING 2019-10-08 16:01:37,102 log 228 Not Found: /mobiles/13020785602/count/
WARNING 2019-10-08 16:01:37,103 basehttp 124 "GET /mobiles/13020785602/count/ HTTP/1.1" 404 2404
INFO 2019-10-08 16:03:21,842 basehttp 124 "GET /image_codes/fb70ac81-2050-4c7a-b2cd-0be42528bf95/ HTTP/1.1" 200 3473
WARNING 2019-10-08 16:03:39,844 log 228 Not Found: /mobiles/13020785602/count/
WARNING 2019-10-08 16:03:39,845 basehttp 124 "GET /mobiles/13020785602/count/ HTTP/1.1" 404 2404
WARNING 2019-10-08 16:03:42,930 log 228 Not Found: /mobiles/13020785602/count/
WARNING 2019-10-08 16:03:42,930 basehttp 124 "GET /mobiles/13020785602/count/ HTTP/1.1" 404 2404
WARNING 2019-10-08 16:03:50,811 log 228 Not Found: /usernames/lgljy/count/
WARNING 2019-10-08 16:03:50,812 basehttp 124 "GET /usernames/lgljy/count/ HTTP/1.1" 404 2392
INFO 2019-10-08 16:31:12,656 basehttp 124 "GET /image_codes/2f670822-26ea-4c46-8b7e-d34cc73bf610/ HTTP/1.1" 200 2867
WARNING 2019-10-08 16:31:22,396 log 228 Not Found: /usernames/lgljy/count/
WARNING 2019-10-08 16:31:22,397 basehttp 124 "GET /usernames/lgljy/count/ HTTP/1.1" 404 2392
INFO 2019-10-08 16:31:26,997 basehttp 124 "GET /image_codes/c15bc184-3b25-4f50-a525-8347348a528e/ HTTP/1.1" 200 3402
WARNING 2019-10-08 16:31:39,504 log 228 Not Found: /
WARNING 2019-10-08 16:31:39,504 basehttp 124 "GET / HTTP/1.1" 404 2303
INFO 2019-10-08 16:32:12,119 basehttp 124 "GET /image_codes/6da08cc4-76a1-4905-af16-694724113efb/ HTTP/1.1" 200 3184
WARNING 2019-10-08 16:32:24,801 log 228 Not Found: /usernames/lgljy/count/
WARNING 2019-10-08 16:32:24,805 basehttp 124 "GET /usernames/lgljy/count/ HTTP/1.1" 404 2392
WARNING 2019-10-08 16:32:31,817 log 228 Not Found: /mobiles/13020785602/count/
WARNING 2019-10-08 16:32:31,818 basehttp 124 "GET /mobiles/13020785602/count/ HTTP/1.1" 404 2404
WARNING 2019-10-08 16:32:33,897 log 228 Not Found: /mobiles/13020785602/count/
WARNING 2019-10-08 16:32:33,898 basehttp 124 "GET /mobiles/13020785602/count/ HTTP/1.1" 404 2404
ERROR 2019-10-08 16:32:33,922 log 228 Internal Server Error: /sms_codes/13020785602/
Traceback (most recent call last):
  File "/home/lgl/virtualenvs/py3_django/lib/python3.6/site-packages/django/core/handlers/exception.py", line 34, in inner
    response = get_response(request)
  File "/home/lgl/virtualenvs/py3_django/lib/python3.6/site-packages/django/core/handlers/base.py", line 126, in _get_response
    response = self.process_exception_by_middleware(e, request)
  File "/home/lgl/virtualenvs/py3_django/lib/python3.6/site-packages/django/core/handlers/base.py", line 124, in _get_response
    response = wrapped_callback(request, *callback_args, **callback_kwargs)
  File "/home/lgl/virtualenvs/py3_django/lib/python3.6/site-packages/django/views/decorators/csrf.py", line 54, in wrapped_view
    return view_func(*args, **kwargs)
  File "/home/lgl/virtualenvs/py3_django/lib/python3.6/site-packages/django/views/generic/base.py", line 68, in view
    return self.dispatch(request, *args, **kwargs)
  File "/home/lgl/virtualenvs/py3_django/lib/python3.6/site-packages/rest_framework/views.py", line 483, in dispatch
    response = self.handle_exception(exc)
  File "/home/lgl/virtualenvs/py3_django/lib/python3.6/site-packages/rest_framework/views.py", line 443, in handle_exception
    self.raise_uncaught_exception(exc)
  File "/home/lgl/virtualenvs/py3_django/lib/python3.6/site-packages/rest_framework/views.py", line 480, in dispatch
    response = handler(request, *args, **kwargs)
TypeError: get() got an unexpected keyword argument 'mobiles'
ERROR 2019-10-08 16:32:33,923 basehttp 124 "GET /sms_codes/13020785602/?text=VWSP&image_code_id=6da08cc4-76a1-4905-af16-694724113efb HTTP/1.1" 500 18978
ERROR 2019-10-08 16:34:05,539 log 228 Internal Server Error: /sms_codes/13020785602/
Traceback (most recent call last):
  File "/home/lgl/virtualenvs/py3_django/lib/python3.6/site-packages/django/core/handlers/exception.py", line 34, in inner
    response = get_response(request)
  File "/home/lgl/virtualenvs/py3_django/lib/python3.6/site-packages/django/core/handlers/base.py", line 126, in _get_response
    response = self.process_exception_by_middleware(e, request)
  File "/home/lgl/virtualenvs/py3_django/lib/python3.6/site-packages/django/core/handlers/base.py", line 124, in _get_response
    response = wrapped_callback(request, *callback_args, **callback_kwargs)
  File "/home/lgl/virtualenvs/py3_django/lib/python3.6/site-packages/django/views/decorators/csrf.py", line 54, in wrapped_view
    return view_func(*args, **kwargs)
  File "/home/lgl/virtualenvs/py3_django/lib/python3.6/site-packages/django/views/generic/base.py", line 68, in view
    return self.dispatch(request, *args, **kwargs)
  File "/home/lgl/virtualenvs/py3_django/lib/python3.6/site-packages/rest_framework/views.py", line 483, in dispatch
    response = self.handle_exception(exc)
  File "/home/lgl/virtualenvs/py3_django/lib/python3.6/site-packages/rest_framework/views.py", line 443, in handle_exception
    self.raise_uncaught_exception(exc)
  File "/home/lgl/virtualenvs/py3_django/lib/python3.6/site-packages/rest_framework/views.py", line 480, in dispatch
    response = handler(request, *args, **kwargs)
TypeError: get() got an unexpected keyword argument 'mobiles'
WARNING 2019-10-08 16:34:05,540 log 228 Not Found: /mobiles/13020785602/count/
WARNING 2019-10-08 16:34:05,541 basehttp 124 "GET /mobiles/13020785602/count/ HTTP/1.1" 404 2404
ERROR 2019-10-08 16:34:05,542 basehttp 124 "GET /sms_codes/13020785602/?text=VWSP&image_code_id=6da08cc4-76a1-4905-af16-694724113efb HTTP/1.1" 500 18978
INFO 2019-10-08 16:44:01,224 basehttp 124 "GET /image_codes/e301cf67-c21b-4af8-a7e1-c9bfc18d90cb/ HTTP/1.1" 200 3235
WARNING 2019-10-08 16:44:11,822 log 228 Not Found: /mobiles/13020785602/count/
WARNING 2019-10-08 16:44:11,823 basehttp 124 "GET /mobiles/13020785602/count/ HTTP/1.1" 404 2404
WARNING 2019-10-08 16:44:17,636 log 228 Not Found: /usernames/lgljh/count/
WARNING 2019-10-08 16:44:17,636 basehttp 124 "GET /usernames/lgljh/count/ HTTP/1.1" 404 2392
WARNING 2019-10-08 16:44:17,718 log 228 Not Found: /mobiles/13020785602/count/
WARNING 2019-10-08 16:44:17,727 basehttp 124 "GET /mobiles/13020785602/count/ HTTP/1.1" 404 2404
ERROR 2019-10-08 16:44:17,754 log 228 Internal Server Error: /sms_codes/13020785602/
Traceback (most recent call last):
  File "/home/lgl/virtualenvs/py3_django/lib/python3.6/site-packages/django/core/handlers/exception.py", line 34, in inner
    response = get_response(request)
  File "/home/lgl/virtualenvs/py3_django/lib/python3.6/site-packages/django/core/handlers/base.py", line 126, in _get_response
    response = self.process_exception_by_middleware(e, request)
  File "/home/lgl/virtualenvs/py3_django/lib/python3.6/site-packages/django/core/handlers/base.py", line 124, in _get_response
    response = wrapped_callback(request, *callback_args, **callback_kwargs)
  File "/home/lgl/virtualenvs/py3_django/lib/python3.6/site-packages/django/views/decorators/csrf.py", line 54, in wrapped_view
    return view_func(*args, **kwargs)
  File "/home/lgl/virtualenvs/py3_django/lib/python3.6/site-packages/django/views/generic/base.py", line 68, in view
    return self.dispatch(request, *args, **kwargs)
  File "/home/lgl/virtualenvs/py3_django/lib/python3.6/site-packages/rest_framework/views.py", line 483, in dispatch
    response = self.handle_exception(exc)
  File "/home/lgl/virtualenvs/py3_django/lib/python3.6/site-packages/rest_framework/views.py", line 443, in handle_exception
    self.raise_uncaught_exception(exc)
  File "/home/lgl/virtualenvs/py3_django/lib/python3.6/site-packages/rest_framework/views.py", line 480, in dispatch
    response = handler(request, *args, **kwargs)
TypeError: get() got an unexpected keyword argument 'mobiles'
ERROR 2019-10-08 16:44:17,755 basehttp 124 "GET /sms_codes/13020785602/?text=FLT9&image_code_id=e301cf67-c21b-4af8-a7e1-c9bfc18d90cb HTTP/1.1" 500 18978
INFO 2019-10-09 15:30:14,428 basehttp 124 "OPTIONS /cart/ HTTP/1.1" 200 0
WARNING 2019-10-09 15:30:14,496 log 228 Not Found: /cart/
WARNING 2019-10-09 15:30:14,496 basehttp 124 "GET /cart/ HTTP/1.1" 404 2341
WARNING 2019-10-09 15:32:05,187 log 228 Not Found: /cart/
WARNING 2019-10-09 15:32:05,188 basehttp 124 "GET /cart/ HTTP/1.1" 404 2341
INFO 2019-10-09 15:32:07,279 basehttp 124 "GET /image_codes/7e42d18c-6968-4d5a-bdcc-a8e6334300b9/ HTTP/1.1" 200 3108
WARNING 2019-10-09 15:32:19,020 log 228 Not Found: /usernames/lglff/count/
WARNING 2019-10-09 15:32:19,021 basehttp 124 "GET /usernames/lglff/count/ HTTP/1.1" 404 2392
INFO 2019-10-09 15:32:51,126 basehttp 124 "GET /image_codes/2d1705be-93bc-417b-b02a-f2bb2f0de77b/ HTTP/1.1" 200 3448
WARNING 2019-10-09 15:33:03,476 log 228 Not Found: /usernames/lllll/count/
WARNING 2019-10-09 15:33:03,477 basehttp 124 "GET /usernames/lllll/count/ HTTP/1.1" 404 2392
WARNING 2019-10-09 15:33:08,817 log 228 Not Found: /mobiles/13020785602/count/
WARNING 2019-10-09 15:33:08,817 basehttp 124 "GET /mobiles/13020785602/count/ HTTP/1.1" 404 2404
WARNING 2019-10-09 15:33:09,608 log 228 Not Found: /mobiles/13020785602/count/
WARNING 2019-10-09 15:33:09,608 basehttp 124 "GET /mobiles/13020785602/count/ HTTP/1.1" 404 2404
ERROR 2019-10-09 15:33:10,089 log 228 Internal Server Error: /sms_codes/13020785602/
Traceback (most recent call last):
  File "/home/lgl/virtualenvs/py3_django/lib/python3.6/site-packages/django/core/handlers/exception.py", line 34, in inner
    response = get_response(request)
  File "/home/lgl/virtualenvs/py3_django/lib/python3.6/site-packages/django/core/handlers/base.py", line 126, in _get_response
    response = self.process_exception_by_middleware(e, request)
  File "/home/lgl/virtualenvs/py3_django/lib/python3.6/site-packages/django/core/handlers/base.py", line 124, in _get_response
    response = wrapped_callback(request, *callback_args, **callback_kwargs)
  File "/home/lgl/virtualenvs/py3_django/lib/python3.6/site-packages/django/views/decorators/csrf.py", line 54, in wrapped_view
    return view_func(*args, **kwargs)
  File "/home/lgl/virtualenvs/py3_django/lib/python3.6/site-packages/django/views/generic/base.py", line 68, in view
    return self.dispatch(request, *args, **kwargs)
  File "/home/lgl/virtualenvs/py3_django/lib/python3.6/site-packages/rest_framework/views.py", line 483, in dispatch
    response = self.handle_exception(exc)
  File "/home/lgl/virtualenvs/py3_django/lib/python3.6/site-packages/rest_framework/views.py", line 443, in handle_exception
    self.raise_uncaught_exception(exc)
  File "/home/lgl/virtualenvs/py3_django/lib/python3.6/site-packages/rest_framework/views.py", line 480, in dispatch
    response = handler(request, *args, **kwargs)
TypeError: get() got an unexpected keyword argument 'mobiles'
ERROR 2019-10-09 15:33:10,090 basehttp 124 "GET /sms_codes/13020785602/?text=HDBB&image_code_id=2d1705be-93bc-417b-b02a-f2bb2f0de77b HTTP/1.1" 500 18977
INFO 2019-10-09 15:37:47,355 basehttp 124 "GET /image_codes/aad172c8-0647-44ea-b083-4acb9df8007c/ HTTP/1.1" 200 2738
WARNING 2019-10-09 15:37:58,966 log 228 Not Found: /usernames/jjjjjj/count/
WARNING 2019-10-09 15:37:58,966 basehttp 124 "GET /usernames/jjjjjj/count/ HTTP/1.1" 404 2395
WARNING 2019-10-09 15:38:09,232 log 228 Not Found: /mobiles/13020785602/count/
WARNING 2019-10-09 15:38:09,232 basehttp 124 "GET /mobiles/13020785602/count/ HTTP/1.1" 404 2404
WARNING 2019-10-09 15:38:09,303 log 228 Not Found: /mobiles/13020785602/count/
WARNING 2019-10-09 15:38:09,304 basehttp 124 "GET /mobiles/13020785602/count/ HTTP/1.1" 404 2404
ERROR 2019-10-09 15:38:09,334 log 228 Internal Server Error: /sms_codes/13020785602/
Traceback (most recent call last):
  File "/home/lgl/virtualenvs/py3_django/lib/python3.6/site-packages/django/core/handlers/exception.py", line 34, in inner
    response = get_response(request)
  File "/home/lgl/virtualenvs/py3_django/lib/python3.6/site-packages/django/core/handlers/base.py", line 126, in _get_response
    response = self.process_exception_by_middleware(e, request)
  File "/home/lgl/virtualenvs/py3_django/lib/python3.6/site-packages/django/core/handlers/base.py", line 124, in _get_response
    response = wrapped_callback(request, *callback_args, **callback_kwargs)
  File "/home/lgl/virtualenvs/py3_django/lib/python3.6/site-packages/django/views/decorators/csrf.py", line 54, in wrapped_view
    return view_func(*args, **kwargs)
  File "/home/lgl/virtualenvs/py3_django/lib/python3.6/site-packages/django/views/generic/base.py", line 68, in view
    return self.dispatch(request, *args, **kwargs)
  File "/home/lgl/virtualenvs/py3_django/lib/python3.6/site-packages/rest_framework/views.py", line 483, in dispatch
    response = self.handle_exception(exc)
  File "/home/lgl/virtualenvs/py3_django/lib/python3.6/site-packages/rest_framework/views.py", line 443, in handle_exception
    self.raise_uncaught_exception(exc)
  File "/home/lgl/virtualenvs/py3_django/lib/python3.6/site-packages/rest_framework/views.py", line 480, in dispatch
    response = handler(request, *args, **kwargs)
TypeError: get() got an unexpected keyword argument 'mobiles'
ERROR 2019-10-09 15:38:09,335 basehttp 124 "GET /sms_codes/13020785602/?text=VZSL&image_code_id=aad172c8-0647-44ea-b083-4acb9df8007c HTTP/1.1" 500 18977
WARNING 2019-10-09 15:43:47,661 log 228 Not Found: /mobiles/13020785602/count/
WARNING 2019-10-09 15:43:47,662 basehttp 124 "GET /mobiles/13020785602/count/ HTTP/1.1" 404 2404
ERROR 2019-10-09 15:43:47,709 log 228 Internal Server Error: /sms_codes/13020785602/
Traceback (most recent call last):
  File "/home/lgl/virtualenvs/py3_django/lib/python3.6/site-packages/django/core/handlers/exception.py", line 34, in inner
    response = get_response(request)
  File "/home/lgl/virtualenvs/py3_django/lib/python3.6/site-packages/django/core/handlers/base.py", line 126, in _get_response
    response = self.process_exception_by_middleware(e, request)
  File "/home/lgl/virtualenvs/py3_django/lib/python3.6/site-packages/django/core/handlers/base.py", line 124, in _get_response
    response = wrapped_callback(request, *callback_args, **callback_kwargs)
  File "/home/lgl/virtualenvs/py3_django/lib/python3.6/site-packages/django/views/decorators/csrf.py", line 54, in wrapped_view
    return view_func(*args, **kwargs)
  File "/home/lgl/virtualenvs/py3_django/lib/python3.6/site-packages/django/views/generic/base.py", line 68, in view
    return self.dispatch(request, *args, **kwargs)
  File "/home/lgl/virtualenvs/py3_django/lib/python3.6/site-packages/rest_framework/views.py", line 483, in dispatch
    response = self.handle_exception(exc)
  File "/home/lgl/virtualenvs/py3_django/lib/python3.6/site-packages/rest_framework/views.py", line 443, in handle_exception
    self.raise_uncaught_exception(exc)
  File "/home/lgl/virtualenvs/py3_django/lib/python3.6/site-packages/rest_framework/views.py", line 480, in dispatch
    response = handler(request, *args, **kwargs)
TypeError: get() got an unexpected keyword argument 'mobiles'
ERROR 2019-10-09 15:43:47,710 basehttp 124 "GET /sms_codes/13020785602/?text=VZSL&image_code_id=aad172c8-0647-44ea-b083-4acb9df8007c HTTP/1.1" 500 17310
WARNING 2019-10-09 15:45:32,616 log 228 Not Found: /mobiles/13020785602/count/
WARNING 2019-10-09 15:45:32,617 basehttp 124 "GET /mobiles/13020785602/count/ HTTP/1.1" 404 2404
ERROR 2019-10-09 15:45:32,665 log 228 Internal Server Error: /sms_codes/13020785602/
Traceback (most recent call last):
  File "/home/lgl/virtualenvs/py3_django/lib/python3.6/site-packages/django/core/handlers/exception.py", line 34, in inner
    response = get_response(request)
  File "/home/lgl/virtualenvs/py3_django/lib/python3.6/site-packages/django/core/handlers/base.py", line 126, in _get_response
    response = self.process_exception_by_middleware(e, request)
  File "/home/lgl/virtualenvs/py3_django/lib/python3.6/site-packages/django/core/handlers/base.py", line 124, in _get_response
    response = wrapped_callback(request, *callback_args, **callback_kwargs)
  File "/home/lgl/virtualenvs/py3_django/lib/python3.6/site-packages/django/views/decorators/csrf.py", line 54, in wrapped_view
    return view_func(*args, **kwargs)
  File "/home/lgl/virtualenvs/py3_django/lib/python3.6/site-packages/django/views/generic/base.py", line 68, in view
    return self.dispatch(request, *args, **kwargs)
  File "/home/lgl/virtualenvs/py3_django/lib/python3.6/site-packages/rest_framework/views.py", line 483, in dispatch
    response = self.handle_exception(exc)
  File "/home/lgl/virtualenvs/py3_django/lib/python3.6/site-packages/rest_framework/views.py", line 443, in handle_exception
    self.raise_uncaught_exception(exc)
  File "/home/lgl/virtualenvs/py3_django/lib/python3.6/site-packages/rest_framework/views.py", line 480, in dispatch
    response = handler(request, *args, **kwargs)
TypeError: get() got an unexpected keyword argument 'mobiles'
ERROR 2019-10-09 15:45:32,665 basehttp 124 "GET /sms_codes/13020785602/?text=VZSL&image_code_id=aad172c8-0647-44ea-b083-4acb9df8007c HTTP/1.1" 500 17310
WARNING 2019-10-09 15:49:29,028 log 228 Not Found: /mobiles/13020785602/count/
WARNING 2019-10-09 15:49:29,030 basehttp 124 "GET /mobiles/13020785602/count/ HTTP/1.1" 404 2404
ERROR 2019-10-09 15:49:29,048 log 228 Internal Server Error: /sms_codes/13020785602/
Traceback (most recent call last):
  File "/home/lgl/virtualenvs/py3_django/lib/python3.6/site-packages/django/core/handlers/exception.py", line 34, in inner
    response = get_response(request)
  File "/home/lgl/virtualenvs/py3_django/lib/python3.6/site-packages/django/core/handlers/base.py", line 126, in _get_response
    response = self.process_exception_by_middleware(e, request)
  File "/home/lgl/virtualenvs/py3_django/lib/python3.6/site-packages/django/core/handlers/base.py", line 124, in _get_response
    response = wrapped_callback(request, *callback_args, **callback_kwargs)
  File "/home/lgl/virtualenvs/py3_django/lib/python3.6/site-packages/django/views/decorators/csrf.py", line 54, in wrapped_view
    return view_func(*args, **kwargs)
  File "/home/lgl/virtualenvs/py3_django/lib/python3.6/site-packages/django/views/generic/base.py", line 68, in view
    return self.dispatch(request, *args, **kwargs)
  File "/home/lgl/virtualenvs/py3_django/lib/python3.6/site-packages/rest_framework/views.py", line 483, in dispatch
    response = self.handle_exception(exc)
  File "/home/lgl/virtualenvs/py3_django/lib/python3.6/site-packages/rest_framework/views.py", line 443, in handle_exception
    self.raise_uncaught_exception(exc)
  File "/home/lgl/virtualenvs/py3_django/lib/python3.6/site-packages/rest_framework/views.py", line 480, in dispatch
    response = handler(request, *args, **kwargs)
TypeError: get() got an unexpected keyword argument 'mobiles'
ERROR 2019-10-09 15:49:29,049 basehttp 124 "GET /sms_codes/13020785602/?text=VZSL&image_code_id=aad172c8-0647-44ea-b083-4acb9df8007c HTTP/1.1" 500 17310
INFO 2019-10-09 15:50:43,574 basehttp 124 "GET /image_codes/263ae554-95a3-4e6c-b37f-ffaa85b1eeb9/ HTTP/1.1" 200 3013
INFO 2019-10-09 15:50:50,741 basehttp 124 "GET /image_codes/ad885abd-57c2-4505-9464-a5e246582bb2/ HTTP/1.1" 200 3268
INFO 2019-10-09 15:51:31,242 basehttp 124 "GET /image_codes/8f20825e-8773-4095-a894-b89ccc1cf2e9/ HTTP/1.1" 200 3226
WARNING 2019-10-09 15:51:38,969 log 228 Not Found: /mobiles/13578945612/count/
WARNING 2019-10-09 15:51:38,969 basehttp 124 "GET /mobiles/13578945612/count/ HTTP/1.1" 404 2403
WARNING 2019-10-09 15:51:51,402 log 228 Not Found: /mobiles/13578945612/count/
WARNING 2019-10-09 15:51:51,407 basehttp 124 "GET /mobiles/13578945612/count/ HTTP/1.1" 404 2403
ERROR 2019-10-09 15:51:51,557 log 228 Internal Server Error: /sms_codes/13578945612/
Traceback (most recent call last):
  File "/home/lgl/virtualenvs/py3_django/lib/python3.6/site-packages/django/core/handlers/exception.py", line 34, in inner
    response = get_response(request)
  File "/home/lgl/virtualenvs/py3_django/lib/python3.6/site-packages/django/core/handlers/base.py", line 126, in _get_response
    response = self.process_exception_by_middleware(e, request)
  File "/home/lgl/virtualenvs/py3_django/lib/python3.6/site-packages/django/core/handlers/base.py", line 124, in _get_response
    response = wrapped_callback(request, *callback_args, **callback_kwargs)
  File "/home/lgl/virtualenvs/py3_django/lib/python3.6/site-packages/django/views/decorators/csrf.py", line 54, in wrapped_view
    return view_func(*args, **kwargs)
  File "/home/lgl/virtualenvs/py3_django/lib/python3.6/site-packages/django/views/generic/base.py", line 68, in view
    return self.dispatch(request, *args, **kwargs)
  File "/home/lgl/virtualenvs/py3_django/lib/python3.6/site-packages/rest_framework/views.py", line 483, in dispatch
    response = self.handle_exception(exc)
  File "/home/lgl/virtualenvs/py3_django/lib/python3.6/site-packages/rest_framework/views.py", line 443, in handle_exception
    self.raise_uncaught_exception(exc)
  File "/home/lgl/virtualenvs/py3_django/lib/python3.6/site-packages/rest_framework/views.py", line 480, in dispatch
    response = handler(request, *args, **kwargs)
  File "/home/lgl/workplace/django_project/meiduo_mall/meiduo_mall/apps/verifications/views.py", line 51, in get
    serializer = self.get_serializer(data=request.query_params)
  File "/home/lgl/virtualenvs/py3_django/lib/python3.6/site-packages/rest_framework/generics.py", line 110, in get_serializer
    serializer_class = self.get_serializer_class()
  File "/home/lgl/virtualenvs/py3_django/lib/python3.6/site-packages/rest_framework/generics.py", line 127, in get_serializer_class
    % self.__class__.__name__
AssertionError: 'SMSCodeView' should either include a `serializer_class` attribute, or override the `get_serializer_class()` method.
ERROR 2019-10-09 15:51:51,558 basehttp 124 "GET /sms_codes/13578945612/?text=AUGB&image_code_id=8f20825e-8773-4095-a894-b89ccc1cf2e9 HTTP/1.1" 500 17969
INFO 2019-10-09 15:54:51,594 basehttp 124 "GET /image_codes/022ffdce-54cc-4d04-afcd-a4014390e3b3/ HTTP/1.1" 200 3154
WARNING 2019-10-09 15:54:59,821 log 228 Not Found: /mobiles/13578945612/count/
WARNING 2019-10-09 15:54:59,821 basehttp 124 "GET /mobiles/13578945612/count/ HTTP/1.1" 404 2403
WARNING 2019-10-09 15:55:07,148 log 228 Not Found: /mobiles/13578945612/count/
WARNING 2019-10-09 15:55:07,149 basehttp 124 "GET /mobiles/13578945612/count/ HTTP/1.1" 404 2403
WARNING 2019-10-09 15:55:09,211 log 228 Not Found: /mobiles/13578945612/count/
WARNING 2019-10-09 15:55:09,214 basehttp 124 "GET /mobiles/13578945612/count/ HTTP/1.1" 404 2403
ERROR 2019-10-09 15:55:09,260 log 228 Internal Server Error: /sms_codes/13578945612/
Traceback (most recent call last):
  File "/home/lgl/virtualenvs/py3_django/lib/python3.6/site-packages/django/core/handlers/exception.py", line 34, in inner
    response = get_response(request)
  File "/home/lgl/virtualenvs/py3_django/lib/python3.6/site-packages/django/core/handlers/base.py", line 126, in _get_response
    response = self.process_exception_by_middleware(e, request)
  File "/home/lgl/virtualenvs/py3_django/lib/python3.6/site-packages/django/core/handlers/base.py", line 124, in _get_response
    response = wrapped_callback(request, *callback_args, **callback_kwargs)
  File "/home/lgl/virtualenvs/py3_django/lib/python3.6/site-packages/django/views/decorators/csrf.py", line 54, in wrapped_view
    return view_func(*args, **kwargs)
  File "/home/lgl/virtualenvs/py3_django/lib/python3.6/site-packages/django/views/generic/base.py", line 68, in view
    return self.dispatch(request, *args, **kwargs)
  File "/home/lgl/virtualenvs/py3_django/lib/python3.6/site-packages/rest_framework/views.py", line 483, in dispatch
    response = self.handle_exception(exc)
  File "/home/lgl/virtualenvs/py3_django/lib/python3.6/site-packages/rest_framework/views.py", line 443, in handle_exception
    self.raise_uncaught_exception(exc)
  File "/home/lgl/virtualenvs/py3_django/lib/python3.6/site-packages/rest_framework/views.py", line 480, in dispatch
    response = handler(request, *args, **kwargs)
  File "/home/lgl/workplace/django_project/meiduo_mall/meiduo_mall/apps/verifications/views.py", line 51, in get
    serializer = self.get_serializer(data=request.query_params)
  File "/home/lgl/virtualenvs/py3_django/lib/python3.6/site-packages/rest_framework/generics.py", line 110, in get_serializer
    serializer_class = self.get_serializer_class()
  File "/home/lgl/virtualenvs/py3_django/lib/python3.6/site-packages/rest_framework/generics.py", line 127, in get_serializer_class
    % self.__class__.__name__
AssertionError: 'SMSCodeView' should either include a `serializer_class` attribute, or override the `get_serializer_class()` method.
ERROR 2019-10-09 15:55:09,261 basehttp 124 "GET /sms_codes/13578945612/?text=7WDY&image_code_id=022ffdce-54cc-4d04-afcd-a4014390e3b3 HTTP/1.1" 500 17969
WARNING 2019-10-09 15:55:51,232 log 228 Not Found: /mobiles/13578945612/count/
WARNING 2019-10-09 15:55:51,239 basehttp 124 "GET /mobiles/13578945612/count/ HTTP/1.1" 404 2403
ERROR 2019-10-09 15:55:51,291 log 228 Internal Server Error: /sms_codes/13578945612/
Traceback (most recent call last):
  File "/home/lgl/virtualenvs/py3_django/lib/python3.6/site-packages/django/core/handlers/exception.py", line 34, in inner
    response = get_response(request)
  File "/home/lgl/virtualenvs/py3_django/lib/python3.6/site-packages/django/core/handlers/base.py", line 126, in _get_response
    response = self.process_exception_by_middleware(e, request)
  File "/home/lgl/virtualenvs/py3_django/lib/python3.6/site-packages/django/core/handlers/base.py", line 124, in _get_response
    response = wrapped_callback(request, *callback_args, **callback_kwargs)
  File "/home/lgl/virtualenvs/py3_django/lib/python3.6/site-packages/django/views/decorators/csrf.py", line 54, in wrapped_view
    return view_func(*args, **kwargs)
  File "/home/lgl/virtualenvs/py3_django/lib/python3.6/site-packages/django/views/generic/base.py", line 68, in view
    return self.dispatch(request, *args, **kwargs)
  File "/home/lgl/virtualenvs/py3_django/lib/python3.6/site-packages/rest_framework/views.py", line 483, in dispatch
    response = self.handle_exception(exc)
  File "/home/lgl/virtualenvs/py3_django/lib/python3.6/site-packages/rest_framework/views.py", line 443, in handle_exception
    self.raise_uncaught_exception(exc)
  File "/home/lgl/virtualenvs/py3_django/lib/python3.6/site-packages/rest_framework/views.py", line 480, in dispatch
    response = handler(request, *args, **kwargs)
  File "/home/lgl/workplace/django_project/meiduo_mall/meiduo_mall/apps/verifications/views.py", line 51, in get
    serializer = self.get_serializer(data=request.query_params)
  File "/home/lgl/virtualenvs/py3_django/lib/python3.6/site-packages/rest_framework/generics.py", line 110, in get_serializer
    serializer_class = self.get_serializer_class()
  File "/home/lgl/virtualenvs/py3_django/lib/python3.6/site-packages/rest_framework/generics.py", line 127, in get_serializer_class
    % self.__class__.__name__
AssertionError: 'SMSCodeView' should either include a `serializer_class` attribute, or override the `get_serializer_class()` method.
ERROR 2019-10-09 15:55:51,292 basehttp 124 "GET /sms_codes/13578945612/?text=7WDY&image_code_id=022ffdce-54cc-4d04-afcd-a4014390e3b3 HTTP/1.1" 500 17969
WARNING 2019-10-09 15:56:22,787 log 228 Not Found: /mobiles/13578945612/count/
WARNING 2019-10-09 15:56:22,788 basehttp 124 "GET /mobiles/13578945612/count/ HTTP/1.1" 404 2403
ERROR 2019-10-09 15:56:22,831 log 228 Internal Server Error: /sms_codes/13578945612/
Traceback (most recent call last):
  File "/home/lgl/virtualenvs/py3_django/lib/python3.6/site-packages/django/core/handlers/exception.py", line 34, in inner
    response = get_response(request)
  File "/home/lgl/virtualenvs/py3_django/lib/python3.6/site-packages/django/core/handlers/base.py", line 126, in _get_response
    response = self.process_exception_by_middleware(e, request)
  File "/home/lgl/virtualenvs/py3_django/lib/python3.6/site-packages/django/core/handlers/base.py", line 124, in _get_response
    response = wrapped_callback(request, *callback_args, **callback_kwargs)
  File "/home/lgl/virtualenvs/py3_django/lib/python3.6/site-packages/django/views/decorators/csrf.py", line 54, in wrapped_view
    return view_func(*args, **kwargs)
  File "/home/lgl/virtualenvs/py3_django/lib/python3.6/site-packages/django/views/generic/base.py", line 68, in view
    return self.dispatch(request, *args, **kwargs)
  File "/home/lgl/virtualenvs/py3_django/lib/python3.6/site-packages/rest_framework/views.py", line 483, in dispatch
    response = self.handle_exception(exc)
  File "/home/lgl/virtualenvs/py3_django/lib/python3.6/site-packages/rest_framework/views.py", line 443, in handle_exception
    self.raise_uncaught_exception(exc)
  File "/home/lgl/virtualenvs/py3_django/lib/python3.6/site-packages/rest_framework/views.py", line 480, in dispatch
    response = handler(request, *args, **kwargs)
  File "/home/lgl/workplace/django_project/meiduo_mall/meiduo_mall/apps/verifications/views.py", line 57, in get
    sms_code = "%06d" % random.randint(0, 999999)
AttributeError: 'builtin_function_or_method' object has no attribute 'randint'
ERROR 2019-10-09 15:56:22,831 basehttp 124 "GET /sms_codes/13578945612/?text=7WDY&image_code_id=022ffdce-54cc-4d04-afcd-a4014390e3b3 HTTP/1.1" 500 17506
INFO 2019-10-09 15:57:06,122 basehttp 124 "GET /image_codes/98684ece-b713-42cc-a4c2-8d19b3458c96/ HTTP/1.1" 200 2976
WARNING 2019-10-09 15:57:11,912 log 228 Not Found: /mobiles/13578945612/count/
WARNING 2019-10-09 15:57:11,913 basehttp 124 "GET /mobiles/13578945612/count/ HTTP/1.1" 404 2403
WARNING 2019-10-09 15:57:21,535 log 228 Not Found: /mobiles/13578945612/count/
WARNING 2019-10-09 15:57:21,543 basehttp 124 "GET /mobiles/13578945612/count/ HTTP/1.1" 404 2403
ERROR 2019-10-09 15:57:21,587 log 228 Internal Server Error: /sms_codes/13578945612/
Traceback (most recent call last):
  File "/home/lgl/virtualenvs/py3_django/lib/python3.6/site-packages/django/core/handlers/exception.py", line 34, in inner
    response = get_response(request)
  File "/home/lgl/virtualenvs/py3_django/lib/python3.6/site-packages/django/core/handlers/base.py", line 126, in _get_response
    response = self.process_exception_by_middleware(e, request)
  File "/home/lgl/virtualenvs/py3_django/lib/python3.6/site-packages/django/core/handlers/base.py", line 124, in _get_response
    response = wrapped_callback(request, *callback_args, **callback_kwargs)
  File "/home/lgl/virtualenvs/py3_django/lib/python3.6/site-packages/django/views/decorators/csrf.py", line 54, in wrapped_view
    return view_func(*args, **kwargs)
  File "/home/lgl/virtualenvs/py3_django/lib/python3.6/site-packages/django/views/generic/base.py", line 68, in view
    return self.dispatch(request, *args, **kwargs)
  File "/home/lgl/virtualenvs/py3_django/lib/python3.6/site-packages/rest_framework/views.py", line 483, in dispatch
    response = self.handle_exception(exc)
  File "/home/lgl/virtualenvs/py3_django/lib/python3.6/site-packages/rest_framework/views.py", line 443, in handle_exception
    self.raise_uncaught_exception(exc)
  File "/home/lgl/virtualenvs/py3_django/lib/python3.6/site-packages/rest_framework/views.py", line 480, in dispatch
    response = handler(request, *args, **kwargs)
  File "/home/lgl/workplace/django_project/meiduo_mall/meiduo_mall/apps/verifications/views.py", line 57, in get
    sms_code = "%06d" % random.randint(0, 999999)
AttributeError: 'builtin_function_or_method' object has no attribute 'randint'
ERROR 2019-10-09 15:57:21,588 basehttp 124 "GET /sms_codes/13578945612/?text=craf&image_code_id=98684ece-b713-42cc-a4c2-8d19b3458c96 HTTP/1.1" 500 17506
WARNING 2019-10-09 15:58:04,214 log 228 Not Found: /mobiles/13578945612/count/
WARNING 2019-10-09 15:58:04,216 basehttp 124 "GET /mobiles/13578945612/count/ HTTP/1.1" 404 2403
WARNING 2019-10-09 15:58:04,222 log 228 Bad Request: /sms_codes/13578945612/
WARNING 2019-10-09 15:58:04,223 basehttp 124 "GET /sms_codes/13578945612/?text=craf&image_code_id=98684ece-b713-42cc-a4c2-8d19b3458c96 HTTP/1.1" 400 49
INFO 2019-10-09 15:58:22,985 basehttp 124 "GET /image_codes/e48b62cf-bf1f-4c55-a646-231dc9803e20/ HTTP/1.1" 200 3732
INFO 2019-10-09 15:58:39,772 basehttp 124 "GET /sms_codes/13578945612/?text=FOWZ&image_code_id=e48b62cf-bf1f-4c55-a646-231dc9803e20 HTTP/1.1" 200 16
WARNING 2019-10-09 15:58:39,774 log 228 Not Found: /mobiles/13578945612/count/
WARNING 2019-10-09 15:58:39,776 basehttp 124 "GET /mobiles/13578945612/count/ HTTP/1.1" 404 2403
INFO 2019-10-09 16:00:21,686 basehttp 124 "GET /image_codes/864af517-84fb-467b-9d2b-d3f79beba702/ HTTP/1.1" 200 3337
INFO 2019-10-09 16:01:03,350 basehttp 124 "GET /image_codes/b8da6779-26d6-4f75-8f38-cda142ab0390/ HTTP/1.1" 200 3759
WARNING 2019-10-09 16:01:16,383 log 228 Not Found: /mobiles/13578945612/count/
WARNING 2019-10-09 16:01:16,384 basehttp 124 "GET /mobiles/13578945612/count/ HTTP/1.1" 404 2395
WARNING 2019-10-09 16:01:19,442 log 228 Not Found: /mobiles/13578945612/count/
WARNING 2019-10-09 16:01:19,449 basehttp 124 "GET /mobiles/13578945612/count/ HTTP/1.1" 404 2395
INFO 2019-10-09 16:01:19,453 basehttp 124 "GET /sms_codes/13578945612/?text=A6XK&image_code_id=b8da6779-26d6-4f75-8f38-cda142ab0390 HTTP/1.1" 200 16
INFO 2019-10-09 16:11:09,638 basehttp 124 "GET /image_codes/70333527-1e5b-43f3-ae39-7bc6fa91e11d/ HTTP/1.1" 200 3260
WARNING 2019-10-09 16:11:24,840 log 228 Not Found: /usernames/lglgg/count/
WARNING 2019-10-09 16:11:24,840 basehttp 124 "GET /usernames/lglgg/count/ HTTP/1.1" 404 2383
WARNING 2019-10-09 16:11:24,889 log 228 Not Found: /mobiles/13578945612/count/
WARNING 2019-10-09 16:11:24,889 basehttp 124 "GET /mobiles/13578945612/count/ HTTP/1.1" 404 2395
INFO 2019-10-09 16:11:24,891 basehttp 124 "GET /sms_codes/13578945612/?text=QIGH&image_code_id=70333527-1e5b-43f3-ae39-7bc6fa91e11d HTTP/1.1" 200 16
WARNING 2019-10-09 16:11:38,371 log 228 Not Found: /mobiles/13578945612/count/
WARNING 2019-10-09 16:11:38,373 log 228 Not Found: /usernames/lglgg/count/
WARNING 2019-10-09 16:11:38,376 basehttp 124 "GET /mobiles/13578945612/count/ HTTP/1.1" 404 2395
WARNING 2019-10-09 16:11:38,378 basehttp 124 "GET /usernames/lglgg/count/ HTTP/1.1" 404 2383
INFO 2019-10-09 17:46:52,033 basehttp 124 "GET /image_codes/db88988d-6829-4d46-85b2-d716e6ab3d6f/ HTTP/1.1" 200 3070
WARNING 2019-10-09 17:47:07,979 log 228 Not Found: /usernames/lgljy/count/
WARNING 2019-10-09 17:47:07,979 basehttp 124 "GET /usernames/lgljy/count/ HTTP/1.1" 404 2383
WARNING 2019-10-09 17:47:22,054 log 228 Not Found: /mobiles/13020785602/count/
WARNING 2019-10-09 17:47:22,055 basehttp 124 "GET /mobiles/13020785602/count/ HTTP/1.1" 404 2395
WARNING 2019-10-09 17:47:22,150 log 228 Not Found: /mobiles/13020785602/count/
WARNING 2019-10-09 17:47:22,156 basehttp 124 "GET /mobiles/13020785602/count/ HTTP/1.1" 404 2395
INFO 2019-10-09 17:47:22,162 basehttp 124 "GET /sms_codes/13020785602/?text=TVAZ&image_code_id=db88988d-6829-4d46-85b2-d716e6ab3d6f HTTP/1.1" 200 16
WARNING 2019-10-09 17:47:34,002 log 228 Not Found: /mobiles/13020785602/count/
WARNING 2019-10-09 17:47:34,004 log 228 Not Found: /usernames/lgljy/count/
INFO 2019-10-09 17:47:34,005 basehttp 124 "OPTIONS /users/ HTTP/1.1" 200 0
WARNING 2019-10-09 17:47:34,005 basehttp 124 "GET /mobiles/13020785602/count/ HTTP/1.1" 404 2395
WARNING 2019-10-09 17:47:34,009 basehttp 124 "GET /usernames/lgljy/count/ HTTP/1.1" 404 2383
WARNING 2019-10-09 17:47:34,020 log 228 Not Found: /users/
WARNING 2019-10-09 17:47:34,021 basehttp 124 "POST /users/ HTTP/1.1" 404 2336
WARNING 2019-10-09 17:47:37,245 log 228 Not Found: /usernames/lgljy/count/
WARNING 2019-10-09 17:47:37,254 log 228 Not Found: /mobiles/13020785602/count/
WARNING 2019-10-09 17:47:37,266 log 228 Not Found: /users/
WARNING 2019-10-09 17:47:37,267 basehttp 124 "GET /usernames/lgljy/count/ HTTP/1.1" 404 2383
WARNING 2019-10-09 17:47:37,268 basehttp 124 "GET /mobiles/13020785602/count/ HTTP/1.1" 404 2395
WARNING 2019-10-09 17:47:37,271 basehttp 124 "POST /users/ HTTP/1.1" 404 2336
WARNING 2019-10-09 17:53:37,633 log 228 Not Found: /mobiles/13020785602/count/
WARNING 2019-10-09 17:53:37,637 basehttp 124 "GET /mobiles/13020785602/count/ HTTP/1.1" 404 2395
WARNING 2019-10-09 17:53:37,639 log 228 Bad Request: /sms_codes/13020785602/
WARNING 2019-10-09 17:53:37,641 basehttp 124 "GET /sms_codes/13020785602/?text=TVAZ&image_code_id=db88988d-6829-4d46-85b2-d716e6ab3d6f HTTP/1.1" 400 49
INFO 2019-10-09 17:53:42,909 basehttp 124 "GET /image_codes/efdc2cd3-cfab-42a9-9954-adf6cd4c168d/ HTTP/1.1" 200 2855
WARNING 2019-10-09 17:53:59,919 log 228 Not Found: /usernames/lgljy/count/
WARNING 2019-10-09 17:53:59,920 basehttp 124 "GET /usernames/lgljy/count/ HTTP/1.1" 404 2383
WARNING 2019-10-09 17:54:36,424 log 228 Not Found: /mobiles/13020785602/count/
WARNING 2019-10-09 17:54:36,424 basehttp 124 "GET /mobiles/13020785602/count/ HTTP/1.1" 404 2395
WARNING 2019-10-09 17:54:36,511 log 228 Not Found: /mobiles/13020785602/count/
WARNING 2019-10-09 17:54:36,513 basehttp 124 "GET /mobiles/13020785602/count/ HTTP/1.1" 404 2395
INFO 2019-10-09 17:54:36,516 basehttp 124 "GET /sms_codes/13020785602/?text=NVBS&image_code_id=efdc2cd3-cfab-42a9-9954-adf6cd4c168d HTTP/1.1" 200 16
WARNING 2019-10-09 17:54:49,117 log 228 Not Found: /usernames/lgljy/count/
WARNING 2019-10-09 17:54:49,119 log 228 Not Found: /users/
WARNING 2019-10-09 17:54:49,121 log 228 Not Found: /mobiles/13020785602/count/
WARNING 2019-10-09 17:54:49,123 basehttp 124 "POST /users/ HTTP/1.1" 404 2336
WARNING 2019-10-09 17:54:49,124 basehttp 124 "GET /usernames/lgljy/count/ HTTP/1.1" 404 2383
WARNING 2019-10-09 17:54:49,125 basehttp 124 "GET /mobiles/13020785602/count/ HTTP/1.1" 404 2395
WARNING 2019-10-09 17:54:52,450 log 228 Not Found: /mobiles/13020785602/count/
WARNING 2019-10-09 17:54:52,453 log 228 Not Found: /usernames/lgljy/count/
WARNING 2019-10-09 17:54:52,453 basehttp 124 "GET /mobiles/13020785602/count/ HTTP/1.1" 404 2395
WARNING 2019-10-09 17:54:52,456 basehttp 124 "GET /usernames/lgljy/count/ HTTP/1.1" 404 2383
WARNING 2019-10-09 17:54:52,456 log 228 Not Found: /users/
WARNING 2019-10-09 17:54:52,457 basehttp 124 "POST /users/ HTTP/1.1" 404 2336
INFO 2019-10-09 18:16:14,636 basehttp 124 "GET /image_codes/f94d4fc8-763c-4c5c-aee0-3e6de13a927b/ HTTP/1.1" 200 3080
WARNING 2019-10-09 18:16:24,073 log 228 Not Found: /usernames/lgljy/count/
WARNING 2019-10-09 18:16:24,074 basehttp 124 "GET /usernames/lgljy/count/ HTTP/1.1" 404 96
WARNING 2019-10-09 18:16:38,154 log 228 Not Found: /mobiles/13020785602/count/
WARNING 2019-10-09 18:16:38,155 basehttp 124 "GET /mobiles/13020785602/count/ HTTP/1.1" 404 100
WARNING 2019-10-09 18:16:39,127 log 228 Not Found: /mobiles/13020785602/count/
WARNING 2019-10-09 18:16:39,140 basehttp 124 "GET /mobiles/13020785602/count/ HTTP/1.1" 404 100
INFO 2019-10-09 18:16:39,144 basehttp 124 "GET /sms_codes/13020785602/?text=7TIS&image_code_id=f94d4fc8-763c-4c5c-aee0-3e6de13a927b HTTP/1.1" 200 16
WARNING 2019-10-09 18:16:48,200 log 228 Not Found: /usernames/lgljy/count/
WARNING 2019-10-09 18:16:48,203 log 228 Not Found: /mobiles/13020785602/count/
WARNING 2019-10-09 18:16:48,208 log 228 Not Found: /users/
WARNING 2019-10-09 18:16:48,209 basehttp 124 "GET /usernames/lgljy/count/ HTTP/1.1" 404 96
WARNING 2019-10-09 18:16:48,210 basehttp 124 "GET /mobiles/13020785602/count/ HTTP/1.1" 404 100
WARNING 2019-10-09 18:16:48,215 basehttp 124 "POST /users/ HTTP/1.1" 404 80
WARNING 2019-10-09 18:16:52,438 log 228 Not Found: /usernames/lgljy/count/
WARNING 2019-10-09 18:16:52,440 basehttp 124 "GET /usernames/lgljy/count/ HTTP/1.1" 404 96
WARNING 2019-10-09 18:16:52,443 log 228 Not Found: /mobiles/13020785602/count/
WARNING 2019-10-09 18:16:52,448 log 228 Not Found: /users/
WARNING 2019-10-09 18:16:52,448 basehttp 124 "GET /mobiles/13020785602/count/ HTTP/1.1" 404 100
WARNING 2019-10-09 18:16:52,449 basehttp 124 "POST /users/ HTTP/1.1" 404 80
WARNING 2019-10-09 18:16:53,404 log 228 Not Found: /usernames/lgljy/count/
WARNING 2019-10-09 18:16:53,409 log 228 Not Found: /mobiles/13020785602/count/
WARNING 2019-10-09 18:16:53,412 log 228 Not Found: /users/
WARNING 2019-10-09 18:16:53,413 basehttp 124 "GET /usernames/lgljy/count/ HTTP/1.1" 404 96
WARNING 2019-10-09 18:16:53,415 basehttp 124 "GET /mobiles/13020785602/count/ HTTP/1.1" 404 100
WARNING 2019-10-09 18:16:53,417 basehttp 124 "POST /users/ HTTP/1.1" 404 80
WARNING 2019-10-09 18:17:31,230 log 228 Not Found: /users/
WARNING 2019-10-09 18:17:31,231 log 228 Not Found: /usernames/lgljy/count/
WARNING 2019-10-09 18:17:31,232 log 228 Not Found: /mobiles/13020785602/count/
WARNING 2019-10-09 18:17:31,233 basehttp 124 "GET /mobiles/13020785602/count/ HTTP/1.1" 404 100
WARNING 2019-10-09 18:17:31,233 basehttp 124 "GET /usernames/lgljy/count/ HTTP/1.1" 404 96
WARNING 2019-10-09 18:17:31,234 basehttp 124 "POST /users/ HTTP/1.1" 404 80
INFO 2019-10-09 18:17:36,373 basehttp 124 "OPTIONS /cart/ HTTP/1.1" 200 0
INFO 2019-10-09 18:17:39,147 basehttp 124 "GET /image_codes/a8312e67-3cef-4b67-98a8-aa09aed013fe/ HTTP/1.1" 200 3103
WARNING 2019-10-09 18:17:49,397 log 228 Not Found: /usernames/lglgg/count/
WARNING 2019-10-09 18:17:49,398 basehttp 124 "GET /usernames/lglgg/count/ HTTP/1.1" 404 96
WARNING 2019-10-09 18:17:58,339 log 228 Not Found: /mobiles/13020785602/count/
WARNING 2019-10-09 18:17:58,340 basehttp 124 "GET /mobiles/13020785602/count/ HTTP/1.1" 404 100
WARNING 2019-10-09 18:18:07,434 log 228 Not Found: /mobiles/13020785602/count/
WARNING 2019-10-09 18:18:07,441 basehttp 124 "GET /mobiles/13020785602/count/ HTTP/1.1" 404 100
INFO 2019-10-09 18:18:07,446 basehttp 124 "GET /sms_codes/13020785602/?text=AUD7&image_code_id=a8312e67-3cef-4b67-98a8-aa09aed013fe HTTP/1.1" 200 16
WARNING 2019-10-09 18:18:14,687 log 228 Not Found: /usernames/lglgg/count/
WARNING 2019-10-09 18:18:14,690 log 228 Not Found: /mobiles/13020785602/count/
WARNING 2019-10-09 18:18:14,693 log 228 Not Found: /users/
WARNING 2019-10-09 18:18:14,695 basehttp 124 "GET /usernames/lglgg/count/ HTTP/1.1" 404 96
WARNING 2019-10-09 18:18:14,696 basehttp 124 "POST /users/ HTTP/1.1" 404 80
WARNING 2019-10-09 18:18:14,701 basehttp 124 "GET /mobiles/13020785602/count/ HTTP/1.1" 404 100
WARNING 2019-10-09 18:18:15,608 log 228 Not Found: /usernames/lglgg/count/
WARNING 2019-10-09 18:18:15,610 log 228 Not Found: /mobiles/13020785602/count/
WARNING 2019-10-09 18:18:15,610 basehttp 124 "GET /mobiles/13020785602/count/ HTTP/1.1" 404 100
WARNING 2019-10-09 18:18:15,610 basehttp 124 "GET /usernames/lglgg/count/ HTTP/1.1" 404 96
WARNING 2019-10-09 18:18:15,612 log 228 Not Found: /users/
WARNING 2019-10-09 18:18:15,613 basehttp 124 "POST /users/ HTTP/1.1" 404 80
WARNING 2019-10-09 18:18:15,759 log 228 Not Found: /mobiles/13020785602/count/
WARNING 2019-10-09 18:18:15,761 log 228 Not Found: /usernames/lglgg/count/
WARNING 2019-10-09 18:18:15,764 log 228 Not Found: /users/
WARNING 2019-10-09 18:18:15,766 basehttp 124 "GET /mobiles/13020785602/count/ HTTP/1.1" 404 100
WARNING 2019-10-09 18:18:15,768 basehttp 124 "GET /usernames/lglgg/count/ HTTP/1.1" 404 96
WARNING 2019-10-09 18:18:15,769 basehttp 124 "POST /users/ HTTP/1.1" 404 80
WARNING 2019-10-09 18:21:47,757 log 228 Not Found: /usernames/lglgg/count/
WARNING 2019-10-09 18:21:47,759 basehttp 124 "GET /usernames/lglgg/count/ HTTP/1.1" 404 96
WARNING 2019-10-09 18:21:47,766 log 228 Not Found: /users/
WARNING 2019-10-09 18:21:47,770 log 228 Not Found: /mobiles/13020785602/count/
WARNING 2019-10-09 18:21:47,771 basehttp 124 "POST /users/ HTTP/1.1" 404 80
WARNING 2019-10-09 18:21:47,772 basehttp 124 "GET /mobiles/13020785602/count/ HTTP/1.1" 404 100
WARNING 2019-10-09 18:22:02,646 log 228 Not Found: /usernames/lglgg/count/
WARNING 2019-10-09 18:22:02,646 basehttp 124 "GET /usernames/lglgg/count/ HTTP/1.1" 404 96
WARNING 2019-10-09 18:22:02,671 log 228 Not Found: /favicon.ico
WARNING 2019-10-09 18:22:02,671 basehttp 124 "GET /favicon.ico HTTP/1.1" 404 85
WARNING 2019-10-09 18:28:35,736 log 228 Not Found: /users/
WARNING 2019-10-09 18:28:35,737 log 228 Not Found: /usernames/lglgg/count/
WARNING 2019-10-09 18:28:35,738 log 228 Not Found: /mobiles/13020785602/count/
WARNING 2019-10-09 18:28:35,739 basehttp 124 "POST /users/ HTTP/1.1" 404 2336
WARNING 2019-10-09 18:28:35,742 basehttp 124 "GET /mobiles/13020785602/count/ HTTP/1.1" 404 2395
WARNING 2019-10-09 18:28:35,742 basehttp 124 "GET /usernames/lglgg/count/ HTTP/1.1" 404 2383
INFO 2019-10-10 17:19:52,183 basehttp 124 "OPTIONS /cart/ HTTP/1.1" 200 0
WARNING 2019-10-10 17:19:52,259 log 228 Not Found: /cart/
WARNING 2019-10-10 17:19:52,261 basehttp 124 "GET /cart/ HTTP/1.1" 404 2332
WARNING 2019-10-10 17:19:53,458 log 228 Not Found: /cart/
WARNING 2019-10-10 17:19:53,460 basehttp 124 "GET /cart/ HTTP/1.1" 404 2332
WARNING 2019-10-10 17:19:53,518 log 228 Not Found: /cart/
WARNING 2019-10-10 17:19:53,518 basehttp 124 "GET /cart/ HTTP/1.1" 404 2332
WARNING 2019-10-10 17:19:53,911 log 228 Not Found: /cart/
WARNING 2019-10-10 17:19:53,912 basehttp 124 "GET /cart/ HTTP/1.1" 404 2332
WARNING 2019-10-10 17:19:54,492 log 228 Not Found: /cart/
WARNING 2019-10-10 17:19:54,494 basehttp 124 "GET /cart/ HTTP/1.1" 404 2332
INFO 2019-10-10 17:19:55,643 basehttp 124 "GET /image_codes/a96988cc-80f6-48d8-b714-923369e54f9a/ HTTP/1.1" 200 3385
WARNING 2019-10-10 17:20:09,179 log 228 Not Found: /usernames/lgljy/count/
WARNING 2019-10-10 17:20:09,179 basehttp 124 "GET /usernames/lgljy/count/ HTTP/1.1" 404 2383
WARNING 2019-10-10 17:20:18,743 log 228 Not Found: /mobiles/13020785602/count/
WARNING 2019-10-10 17:20:18,744 basehttp 124 "GET /mobiles/13020785602/count/ HTTP/1.1" 404 2395
WARNING 2019-10-10 17:20:33,351 log 228 Not Found: /mobiles/13020785602/count/
WARNING 2019-10-10 17:20:33,352 basehttp 124 "GET /mobiles/13020785602/count/ HTTP/1.1" 404 2395
INFO 2019-10-10 17:20:33,355 basehttp 124 "GET /sms_codes/13020785602/?text=HLZG&image_code_id=a96988cc-80f6-48d8-b714-923369e54f9a HTTP/1.1" 200 16
INFO 2019-10-10 17:20:46,369 basehttp 124 "OPTIONS /users/ HTTP/1.1" 200 0
WARNING 2019-10-10 17:20:46,377 log 228 Not Found: /usernames/lgljy/count/
WARNING 2019-10-10 17:20:46,389 log 228 Not Found: /mobiles/13020785602/count/
WARNING 2019-10-10 17:20:46,394 log 228 Not Found: /users/
WARNING 2019-10-10 17:20:46,394 basehttp 124 "GET /usernames/lgljy/count/ HTTP/1.1" 404 2383
WARNING 2019-10-10 17:20:46,395 basehttp 124 "GET /mobiles/13020785602/count/ HTTP/1.1" 404 2395
WARNING 2019-10-10 17:20:46,396 basehttp 124 "POST /users/ HTTP/1.1" 404 2336
WARNING 2019-10-10 17:20:46,856 log 228 Not Found: /mobiles/13020785602/count/
WARNING 2019-10-10 17:20:46,867 log 228 Not Found: /users/
WARNING 2019-10-10 17:20:46,869 log 228 Not Found: /usernames/lgljy/count/
WARNING 2019-10-10 17:20:46,870 basehttp 124 "GET /mobiles/13020785602/count/ HTTP/1.1" 404 2395
WARNING 2019-10-10 17:20:46,872 basehttp 124 "POST /users/ HTTP/1.1" 404 2336
WARNING 2019-10-10 17:20:46,873 basehttp 124 "GET /usernames/lgljy/count/ HTTP/1.1" 404 2383
WARNING 2019-10-10 17:20:47,029 log 228 Not Found: /users/
WARNING 2019-10-10 17:20:47,032 basehttp 124 "POST /users/ HTTP/1.1" 404 2336
WARNING 2019-10-10 17:20:47,040 log 228 Not Found: /usernames/lgljy/count/
WARNING 2019-10-10 17:20:47,047 log 228 Not Found: /mobiles/13020785602/count/
WARNING 2019-10-10 17:20:47,048 basehttp 124 "GET /usernames/lgljy/count/ HTTP/1.1" 404 2383
WARNING 2019-10-10 17:20:47,049 basehttp 124 "GET /mobiles/13020785602/count/ HTTP/1.1" 404 2395
WARNING 2019-10-10 17:22:13,278 log 228 Not Found: /users/
WARNING 2019-10-10 17:22:13,280 log 228 Not Found: /usernames/lgljy/count/
WARNING 2019-10-10 17:22:13,282 log 228 Not Found: /mobiles/13020785602/count/
WARNING 2019-10-10 17:22:13,283 basehttp 124 "POST /users/ HTTP/1.1" 404 80
WARNING 2019-10-10 17:22:13,283 basehttp 124 "GET /usernames/lgljy/count/ HTTP/1.1" 404 96
WARNING 2019-10-10 17:22:13,285 basehttp 124 "GET /mobiles/13020785602/count/ HTTP/1.1" 404 100
WARNING 2019-10-10 17:22:17,198 log 228 Not Found: /mobiles/13020785602/count/
WARNING 2019-10-10 17:22:17,200 basehttp 124 "GET /mobiles/13020785602/count/ HTTP/1.1" 404 100
INFO 2019-10-10 17:22:19,199 basehttp 124 "GET /image_codes/800673f6-c62f-4f9c-a1b3-b18e4938babe/ HTTP/1.1" 200 3647
WARNING 2019-10-10 17:22:34,161 log 228 Not Found: /mobiles/13020785602/count/
WARNING 2019-10-10 17:22:34,162 basehttp 124 "GET /mobiles/13020785602/count/ HTTP/1.1" 404 100
WARNING 2019-10-10 17:22:35,263 log 228 Not Found: /usernames/lgljy/count/
WARNING 2019-10-10 17:22:35,264 basehttp 124 "GET /usernames/lgljy/count/ HTTP/1.1" 404 96
WARNING 2019-10-10 17:22:41,529 log 228 Not Found: /mobiles/13020785602/count/
WARNING 2019-10-10 17:22:41,530 basehttp 124 "GET /mobiles/13020785602/count/ HTTP/1.1" 404 100
WARNING 2019-10-10 17:22:44,235 log 228 Not Found: /mobiles/13020785602/count/
WARNING 2019-10-10 17:22:44,238 basehttp 124 "GET /mobiles/13020785602/count/ HTTP/1.1" 404 100
INFO 2019-10-10 17:22:44,239 basehttp 124 "GET /sms_codes/13020785602/?text=RHWN%20&image_code_id=800673f6-c62f-4f9c-a1b3-b18e4938babe HTTP/1.1" 200 16
WARNING 2019-10-10 17:22:52,085 log 228 Not Found: /usernames/lgljy/count/
WARNING 2019-10-10 17:22:52,088 log 228 Not Found: /mobiles/13020785602/count/
WARNING 2019-10-10 17:22:52,089 basehttp 124 "GET /usernames/lgljy/count/ HTTP/1.1" 404 96
WARNING 2019-10-10 17:22:52,091 basehttp 124 "GET /mobiles/13020785602/count/ HTTP/1.1" 404 100
WARNING 2019-10-10 17:22:52,095 log 228 Not Found: /users/
WARNING 2019-10-10 17:22:52,097 basehttp 124 "POST /users/ HTTP/1.1" 404 80
WARNING 2019-10-10 17:22:52,250 log 228 Not Found: /usernames/lgljy/count/
WARNING 2019-10-10 17:22:52,252 log 228 Not Found: /mobiles/13020785602/count/
WARNING 2019-10-10 17:22:52,254 log 228 Not Found: /users/
WARNING 2019-10-10 17:22:52,255 basehttp 124 "GET /usernames/lgljy/count/ HTTP/1.1" 404 96
WARNING 2019-10-10 17:22:52,255 basehttp 124 "GET /mobiles/13020785602/count/ HTTP/1.1" 404 100
WARNING 2019-10-10 17:22:52,259 basehttp 124 "POST /users/ HTTP/1.1" 404 80
WARNING 2019-10-10 17:22:52,428 log 228 Not Found: /users/
WARNING 2019-10-10 17:22:52,431 log 228 Not Found: /usernames/lgljy/count/
WARNING 2019-10-10 17:22:52,434 basehttp 124 "POST /users/ HTTP/1.1" 404 80
WARNING 2019-10-10 17:22:52,437 log 228 Not Found: /mobiles/13020785602/count/
WARNING 2019-10-10 17:22:52,438 basehttp 124 "GET /usernames/lgljy/count/ HTTP/1.1" 404 96
WARNING 2019-10-10 17:22:52,440 basehttp 124 "GET /mobiles/13020785602/count/ HTTP/1.1" 404 100
WARNING 2019-10-10 17:23:12,029 log 228 Not Found: /mobiles/13020785602/count/
WARNING 2019-10-10 17:23:12,031 basehttp 124 "GET /mobiles/13020785602/count/ HTTP/1.1" 404 100
WARNING 2019-10-10 17:23:12,074 log 228 Not Found: /favicon.ico
WARNING 2019-10-10 17:23:12,074 basehttp 124 "GET /favicon.ico HTTP/1.1" 404 85
WARNING 2019-10-10 17:23:17,792 log 228 Not Found: /mobiles/13020785602/count/
WARNING 2019-10-10 17:23:17,802 basehttp 124 "GET /mobiles/13020785602/count/ HTTP/1.1" 404 100
WARNING 2019-10-10 17:23:21,708 log 228 Not Found: /usernames/lgljy/count/
WARNING 2019-10-10 17:23:21,709 basehttp 124 "GET /usernames/lgljy/count/ HTTP/1.1" 404 96
WARNING 2019-10-10 17:24:46,270 log 228 Not Found: /
WARNING 2019-10-10 17:24:46,271 basehttp 124 "GET / HTTP/1.1" 404 74
WARNING 2019-10-10 17:24:46,311 log 228 Not Found: /favicon.ico
WARNING 2019-10-10 17:24:46,312 basehttp 124 "GET /favicon.ico HTTP/1.1" 404 85
INFO 2019-10-10 17:25:15,840 basehttp 124 "OPTIONS /cart/ HTTP/1.1" 200 0
WARNING 2019-10-10 17:25:15,891 log 228 Not Found: /cart/
WARNING 2019-10-10 17:25:15,891 basehttp 124 "GET /cart/ HTTP/1.1" 404 79
WARNING 2019-10-10 17:25:17,346 log 228 Not Found: /cart/
WARNING 2019-10-10 17:25:17,347 basehttp 124 "GET /cart/ HTTP/1.1" 404 79
INFO 2019-10-10 17:25:21,299 basehttp 124 "GET /image_codes/78bda7e1-41dd-4126-ac7d-ba52c0a07bb7/ HTTP/1.1" 200 2898
WARNING 2019-10-10 17:25:32,597 log 228 Not Found: /usernames/lgljy/count/
WARNING 2019-10-10 17:25:32,599 basehttp 124 "GET /usernames/lgljy/count/ HTTP/1.1" 404 96
WARNING 2019-10-10 17:25:47,766 log 228 Not Found: /mobiles/13578945612/count/
WARNING 2019-10-10 17:25:47,767 basehttp 124 "GET /mobiles/13578945612/count/ HTTP/1.1" 404 100
WARNING 2019-10-10 17:26:03,825 log 228 Not Found: /mobiles/13578945612/count/
WARNING 2019-10-10 17:26:03,826 basehttp 124 "GET /mobiles/13578945612/count/ HTTP/1.1" 404 100
INFO 2019-10-10 17:26:03,836 basehttp 124 "GET /sms_codes/13578945612/?text=S8JY&image_code_id=78bda7e1-41dd-4126-ac7d-ba52c0a07bb7 HTTP/1.1" 200 16
WARNING 2019-10-10 17:26:16,299 log 228 Not Found: /usernames/lgljy/count/
WARNING 2019-10-10 17:26:16,302 log 228 Not Found: /mobiles/13578945612/count/
WARNING 2019-10-10 17:26:16,305 basehttp 124 "GET /usernames/lgljy/count/ HTTP/1.1" 404 96
INFO 2019-10-10 17:26:16,308 basehttp 124 "OPTIONS /users/ HTTP/1.1" 200 0
WARNING 2019-10-10 17:26:16,309 basehttp 124 "GET /mobiles/13578945612/count/ HTTP/1.1" 404 100
WARNING 2019-10-10 17:26:16,315 log 228 Not Found: /users/
WARNING 2019-10-10 17:26:16,316 basehttp 124 "POST /users/ HTTP/1.1" 404 80
WARNING 2019-10-10 17:26:43,004 log 228 Not Found: /usernames/lgljy/count/
WARNING 2019-10-10 17:26:43,006 log 228 Not Found: /users/
WARNING 2019-10-10 17:26:43,008 basehttp 124 "GET /usernames/lgljy/count/ HTTP/1.1" 404 2383
WARNING 2019-10-10 17:26:43,009 log 228 Not Found: /mobiles/13578945612/count/
WARNING 2019-10-10 17:26:43,013 basehttp 124 "GET /mobiles/13578945612/count/ HTTP/1.1" 404 2395
WARNING 2019-10-10 17:26:43,014 basehttp 124 "POST /users/ HTTP/1.1" 404 2336
INFO 2019-10-10 17:34:17,038 basehttp 124 "GET /mobiles/13578945612/count/ HTTP/1.1" 200 34
INFO 2019-10-10 17:34:17,039 basehttp 124 "GET /usernames/lgljy/count/ HTTP/1.1" 200 30
ERROR 2019-10-10 17:34:17,128 log 228 Internal Server Error: /users/
Traceback (most recent call last):
  File "/home/lgl/virtualenvs/py3_django/lib/python3.6/site-packages/django/core/handlers/exception.py", line 34, in inner
    response = get_response(request)
  File "/home/lgl/virtualenvs/py3_django/lib/python3.6/site-packages/django/core/handlers/base.py", line 126, in _get_response
    response = self.process_exception_by_middleware(e, request)
  File "/home/lgl/virtualenvs/py3_django/lib/python3.6/site-packages/django/core/handlers/base.py", line 124, in _get_response
    response = wrapped_callback(request, *callback_args, **callback_kwargs)
  File "/home/lgl/virtualenvs/py3_django/lib/python3.6/site-packages/django/views/decorators/csrf.py", line 54, in wrapped_view
    return view_func(*args, **kwargs)
  File "/home/lgl/virtualenvs/py3_django/lib/python3.6/site-packages/django/views/generic/base.py", line 68, in view
    return self.dispatch(request, *args, **kwargs)
  File "/home/lgl/virtualenvs/py3_django/lib/python3.6/site-packages/rest_framework/views.py", line 483, in dispatch
    response = self.handle_exception(exc)
  File "/home/lgl/virtualenvs/py3_django/lib/python3.6/site-packages/rest_framework/views.py", line 443, in handle_exception
    self.raise_uncaught_exception(exc)
  File "/home/lgl/virtualenvs/py3_django/lib/python3.6/site-packages/rest_framework/views.py", line 480, in dispatch
    response = handler(request, *args, **kwargs)
  File "/home/lgl/virtualenvs/py3_django/lib/python3.6/site-packages/rest_framework/generics.py", line 192, in post
    return self.create(request, *args, **kwargs)
  File "/home/lgl/virtualenvs/py3_django/lib/python3.6/site-packages/rest_framework/mixins.py", line 20, in create
    serializer.is_valid(raise_exception=True)
  File "/home/lgl/virtualenvs/py3_django/lib/python3.6/site-packages/rest_framework/serializers.py", line 236, in is_valid
    self._validated_data = self.run_validation(self.initial_data)
  File "/home/lgl/virtualenvs/py3_django/lib/python3.6/site-packages/rest_framework/serializers.py", line 434, in run_validation
    value = self.to_internal_value(data)
  File "/home/lgl/virtualenvs/py3_django/lib/python3.6/site-packages/rest_framework/serializers.py", line 482, in to_internal_value
    fields = self._writable_fields
  File "/home/lgl/virtualenvs/py3_django/lib/python3.6/site-packages/django/utils/functional.py", line 37, in __get__
    res = instance.__dict__[self.name] = self.func(instance)
  File "/home/lgl/virtualenvs/py3_django/lib/python3.6/site-packages/rest_framework/serializers.py", line 370, in _writable_fields
    field for field in self.fields.values() if not field.read_only
  File "/home/lgl/virtualenvs/py3_django/lib/python3.6/site-packages/rest_framework/serializers.py", line 363, in fields
    for key, value in self.get_fields().items():
  File "/home/lgl/virtualenvs/py3_django/lib/python3.6/site-packages/rest_framework/serializers.py", line 1045, in get_fields
    source, info, model, depth
  File "/home/lgl/virtualenvs/py3_django/lib/python3.6/site-packages/rest_framework/serializers.py", line 1190, in build_field
    return self.build_unknown_field(field_name, model_class)
  File "/home/lgl/virtualenvs/py3_django/lib/python3.6/site-packages/rest_framework/serializers.py", line 1302, in build_unknown_field
    (field_name, model_class.__name__)
django.core.exceptions.ImproperlyConfigured: Field name `usernames` is not valid for model `User`.
ERROR 2019-10-10 17:34:17,129 basehttp 124 "POST /users/ HTTP/1.1" 500 19324
INFO 2019-10-10 17:38:43,556 basehttp 124 "GET /image_codes/5a4c351a-a476-44e8-a425-5976461481bf/ HTTP/1.1" 200 3464
INFO 2019-10-10 17:39:00,116 basehttp 124 "GET /image_codes/5c9e50c2-6def-486f-8245-438680f891cb/ HTTP/1.1" 200 3215
INFO 2019-10-10 17:39:07,753 basehttp 124 "GET /usernames/111111/count/ HTTP/1.1" 200 31
INFO 2019-10-10 17:39:24,367 basehttp 124 "GET /mobiles/13578945612/count/ HTTP/1.1" 200 34
INFO 2019-10-10 17:39:33,846 basehttp 124 "GET /sms_codes/13578945612/?text=6AJM&image_code_id=5c9e50c2-6def-486f-8245-438680f891cb HTTP/1.1" 200 16
INFO 2019-10-10 17:39:33,852 basehttp 124 "GET /mobiles/13578945612/count/ HTTP/1.1" 200 34
INFO 2019-10-10 17:39:52,506 basehttp 124 "GET /usernames/111111/count/ HTTP/1.1" 200 31
INFO 2019-10-10 17:39:52,511 basehttp 124 "GET /mobiles/13578945612/count/ HTTP/1.1" 200 34
ERROR 2019-10-10 17:39:52,540 log 228 Internal Server Error: /users/
Traceback (most recent call last):
  File "/home/lgl/virtualenvs/py3_django/lib/python3.6/site-packages/django/core/handlers/exception.py", line 34, in inner
    response = get_response(request)
  File "/home/lgl/virtualenvs/py3_django/lib/python3.6/site-packages/django/core/handlers/base.py", line 126, in _get_response
    response = self.process_exception_by_middleware(e, request)
  File "/home/lgl/virtualenvs/py3_django/lib/python3.6/site-packages/django/core/handlers/base.py", line 124, in _get_response
    response = wrapped_callback(request, *callback_args, **callback_kwargs)
  File "/home/lgl/virtualenvs/py3_django/lib/python3.6/site-packages/django/views/decorators/csrf.py", line 54, in wrapped_view
    return view_func(*args, **kwargs)
  File "/home/lgl/virtualenvs/py3_django/lib/python3.6/site-packages/django/views/generic/base.py", line 68, in view
    return self.dispatch(request, *args, **kwargs)
  File "/home/lgl/virtualenvs/py3_django/lib/python3.6/site-packages/rest_framework/views.py", line 483, in dispatch
    response = self.handle_exception(exc)
  File "/home/lgl/virtualenvs/py3_django/lib/python3.6/site-packages/rest_framework/views.py", line 443, in handle_exception
    self.raise_uncaught_exception(exc)
  File "/home/lgl/virtualenvs/py3_django/lib/python3.6/site-packages/rest_framework/views.py", line 480, in dispatch
    response = handler(request, *args, **kwargs)
  File "/home/lgl/virtualenvs/py3_django/lib/python3.6/site-packages/rest_framework/generics.py", line 192, in post
    return self.create(request, *args, **kwargs)
  File "/home/lgl/virtualenvs/py3_django/lib/python3.6/site-packages/rest_framework/mixins.py", line 20, in create
    serializer.is_valid(raise_exception=True)
  File "/home/lgl/virtualenvs/py3_django/lib/python3.6/site-packages/rest_framework/serializers.py", line 236, in is_valid
    self._validated_data = self.run_validation(self.initial_data)
  File "/home/lgl/virtualenvs/py3_django/lib/python3.6/site-packages/rest_framework/serializers.py", line 434, in run_validation
    value = self.to_internal_value(data)
  File "/home/lgl/virtualenvs/py3_django/lib/python3.6/site-packages/rest_framework/serializers.py", line 482, in to_internal_value
    fields = self._writable_fields
  File "/home/lgl/virtualenvs/py3_django/lib/python3.6/site-packages/django/utils/functional.py", line 37, in __get__
    res = instance.__dict__[self.name] = self.func(instance)
  File "/home/lgl/virtualenvs/py3_django/lib/python3.6/site-packages/rest_framework/serializers.py", line 370, in _writable_fields
    field for field in self.fields.values() if not field.read_only
  File "/home/lgl/virtualenvs/py3_django/lib/python3.6/site-packages/rest_framework/serializers.py", line 363, in fields
    for key, value in self.get_fields().items():
  File "/home/lgl/virtualenvs/py3_django/lib/python3.6/site-packages/rest_framework/serializers.py", line 1045, in get_fields
    source, info, model, depth
  File "/home/lgl/virtualenvs/py3_django/lib/python3.6/site-packages/rest_framework/serializers.py", line 1190, in build_field
    return self.build_unknown_field(field_name, model_class)
  File "/home/lgl/virtualenvs/py3_django/lib/python3.6/site-packages/rest_framework/serializers.py", line 1302, in build_unknown_field
    (field_name, model_class.__name__)
django.core.exceptions.ImproperlyConfigured: Field name `usernames` is not valid for model `User`.
ERROR 2019-10-10 17:39:52,542 basehttp 124 "POST /users/ HTTP/1.1" 500 19325
INFO 2019-10-10 17:41:51,374 basehttp 124 "GET /usernames/111111/count/ HTTP/1.1" 200 31
INFO 2019-10-10 17:41:51,374 basehttp 124 "GET /mobiles/13578945612/count/ HTTP/1.1" 200 34
ERROR 2019-10-10 17:41:51,405 log 228 Internal Server Error: /users/
Traceback (most recent call last):
  File "/home/lgl/virtualenvs/py3_django/lib/python3.6/site-packages/django/core/handlers/exception.py", line 34, in inner
    response = get_response(request)
  File "/home/lgl/virtualenvs/py3_django/lib/python3.6/site-packages/django/core/handlers/base.py", line 126, in _get_response
    response = self.process_exception_by_middleware(e, request)
  File "/home/lgl/virtualenvs/py3_django/lib/python3.6/site-packages/django/core/handlers/base.py", line 124, in _get_response
    response = wrapped_callback(request, *callback_args, **callback_kwargs)
  File "/home/lgl/virtualenvs/py3_django/lib/python3.6/site-packages/django/views/decorators/csrf.py", line 54, in wrapped_view
    return view_func(*args, **kwargs)
  File "/home/lgl/virtualenvs/py3_django/lib/python3.6/site-packages/django/views/generic/base.py", line 68, in view
    return self.dispatch(request, *args, **kwargs)
  File "/home/lgl/virtualenvs/py3_django/lib/python3.6/site-packages/rest_framework/views.py", line 483, in dispatch
    response = self.handle_exception(exc)
  File "/home/lgl/virtualenvs/py3_django/lib/python3.6/site-packages/rest_framework/views.py", line 443, in handle_exception
    self.raise_uncaught_exception(exc)
  File "/home/lgl/virtualenvs/py3_django/lib/python3.6/site-packages/rest_framework/views.py", line 480, in dispatch
    response = handler(request, *args, **kwargs)
  File "/home/lgl/virtualenvs/py3_django/lib/python3.6/site-packages/rest_framework/generics.py", line 192, in post
    return self.create(request, *args, **kwargs)
  File "/home/lgl/virtualenvs/py3_django/lib/python3.6/site-packages/rest_framework/mixins.py", line 20, in create
    serializer.is_valid(raise_exception=True)
  File "/home/lgl/virtualenvs/py3_django/lib/python3.6/site-packages/rest_framework/serializers.py", line 236, in is_valid
    self._validated_data = self.run_validation(self.initial_data)
  File "/home/lgl/virtualenvs/py3_django/lib/python3.6/site-packages/rest_framework/serializers.py", line 434, in run_validation
    value = self.to_internal_value(data)
  File "/home/lgl/virtualenvs/py3_django/lib/python3.6/site-packages/rest_framework/serializers.py", line 482, in to_internal_value
    fields = self._writable_fields
  File "/home/lgl/virtualenvs/py3_django/lib/python3.6/site-packages/django/utils/functional.py", line 37, in __get__
    res = instance.__dict__[self.name] = self.func(instance)
  File "/home/lgl/virtualenvs/py3_django/lib/python3.6/site-packages/rest_framework/serializers.py", line 370, in _writable_fields
    field for field in self.fields.values() if not field.read_only
  File "/home/lgl/virtualenvs/py3_django/lib/python3.6/site-packages/rest_framework/serializers.py", line 363, in fields
    for key, value in self.get_fields().items():
  File "/home/lgl/virtualenvs/py3_django/lib/python3.6/site-packages/rest_framework/serializers.py", line 1045, in get_fields
    source, info, model, depth
  File "/home/lgl/virtualenvs/py3_django/lib/python3.6/site-packages/rest_framework/serializers.py", line 1190, in build_field
    return self.build_unknown_field(field_name, model_class)
  File "/home/lgl/virtualenvs/py3_django/lib/python3.6/site-packages/rest_framework/serializers.py", line 1302, in build_unknown_field
    (field_name, model_class.__name__)
django.core.exceptions.ImproperlyConfigured: Field name `usernames` is not valid for model `User`.
ERROR 2019-10-10 17:41:51,406 basehttp 124 "POST /users/ HTTP/1.1" 500 19324
INFO 2019-10-10 17:42:55,846 basehttp 124 "GET /usernames/111111/count/ HTTP/1.1" 200 31
INFO 2019-10-10 17:42:55,848 basehttp 124 "GET /mobiles/13578945612/count/ HTTP/1.1" 200 34
ERROR 2019-10-10 17:42:55,905 log 228 Internal Server Error: /users/
Traceback (most recent call last):
  File "/home/lgl/virtualenvs/py3_django/lib/python3.6/site-packages/django/core/handlers/exception.py", line 34, in inner
    response = get_response(request)
  File "/home/lgl/virtualenvs/py3_django/lib/python3.6/site-packages/django/core/handlers/base.py", line 126, in _get_response
    response = self.process_exception_by_middleware(e, request)
  File "/home/lgl/virtualenvs/py3_django/lib/python3.6/site-packages/django/core/handlers/base.py", line 124, in _get_response
    response = wrapped_callback(request, *callback_args, **callback_kwargs)
  File "/home/lgl/virtualenvs/py3_django/lib/python3.6/site-packages/django/views/decorators/csrf.py", line 54, in wrapped_view
    return view_func(*args, **kwargs)
  File "/home/lgl/virtualenvs/py3_django/lib/python3.6/site-packages/django/views/generic/base.py", line 68, in view
    return self.dispatch(request, *args, **kwargs)
  File "/home/lgl/virtualenvs/py3_django/lib/python3.6/site-packages/rest_framework/views.py", line 483, in dispatch
    response = self.handle_exception(exc)
  File "/home/lgl/virtualenvs/py3_django/lib/python3.6/site-packages/rest_framework/views.py", line 443, in handle_exception
    self.raise_uncaught_exception(exc)
  File "/home/lgl/virtualenvs/py3_django/lib/python3.6/site-packages/rest_framework/views.py", line 480, in dispatch
    response = handler(request, *args, **kwargs)
  File "/home/lgl/virtualenvs/py3_django/lib/python3.6/site-packages/rest_framework/generics.py", line 192, in post
    return self.create(request, *args, **kwargs)
  File "/home/lgl/virtualenvs/py3_django/lib/python3.6/site-packages/rest_framework/mixins.py", line 20, in create
    serializer.is_valid(raise_exception=True)
  File "/home/lgl/virtualenvs/py3_django/lib/python3.6/site-packages/rest_framework/serializers.py", line 236, in is_valid
    self._validated_data = self.run_validation(self.initial_data)
  File "/home/lgl/virtualenvs/py3_django/lib/python3.6/site-packages/rest_framework/serializers.py", line 434, in run_validation
    value = self.to_internal_value(data)
  File "/home/lgl/virtualenvs/py3_django/lib/python3.6/site-packages/rest_framework/serializers.py", line 482, in to_internal_value
    fields = self._writable_fields
  File "/home/lgl/virtualenvs/py3_django/lib/python3.6/site-packages/django/utils/functional.py", line 37, in __get__
    res = instance.__dict__[self.name] = self.func(instance)
  File "/home/lgl/virtualenvs/py3_django/lib/python3.6/site-packages/rest_framework/serializers.py", line 370, in _writable_fields
    field for field in self.fields.values() if not field.read_only
  File "/home/lgl/virtualenvs/py3_django/lib/python3.6/site-packages/rest_framework/serializers.py", line 363, in fields
    for key, value in self.get_fields().items():
  File "/home/lgl/virtualenvs/py3_django/lib/python3.6/site-packages/rest_framework/serializers.py", line 1045, in get_fields
    source, info, model, depth
  File "/home/lgl/virtualenvs/py3_django/lib/python3.6/site-packages/rest_framework/serializers.py", line 1190, in build_field
    return self.build_unknown_field(field_name, model_class)
  File "/home/lgl/virtualenvs/py3_django/lib/python3.6/site-packages/rest_framework/serializers.py", line 1302, in build_unknown_field
    (field_name, model_class.__name__)
django.core.exceptions.ImproperlyConfigured: Field name `usernames` is not valid for model `User`.
ERROR 2019-10-10 17:42:55,907 basehttp 124 "POST /users/ HTTP/1.1" 500 19324
INFO 2019-10-10 17:44:33,745 basehttp 124 "GET /mobiles/13578945612/count/ HTTP/1.1" 200 34
INFO 2019-10-10 17:44:33,750 basehttp 124 "GET /usernames/111111/count/ HTTP/1.1" 200 31
ERROR 2019-10-10 17:44:33,777 log 228 Internal Server Error: /users/
Traceback (most recent call last):
  File "/home/lgl/virtualenvs/py3_django/lib/python3.6/site-packages/django/core/handlers/exception.py", line 34, in inner
    response = get_response(request)
  File "/home/lgl/virtualenvs/py3_django/lib/python3.6/site-packages/django/core/handlers/base.py", line 126, in _get_response
    response = self.process_exception_by_middleware(e, request)
  File "/home/lgl/virtualenvs/py3_django/lib/python3.6/site-packages/django/core/handlers/base.py", line 124, in _get_response
    response = wrapped_callback(request, *callback_args, **callback_kwargs)
  File "/home/lgl/virtualenvs/py3_django/lib/python3.6/site-packages/django/views/decorators/csrf.py", line 54, in wrapped_view
    return view_func(*args, **kwargs)
  File "/home/lgl/virtualenvs/py3_django/lib/python3.6/site-packages/django/views/generic/base.py", line 68, in view
    return self.dispatch(request, *args, **kwargs)
  File "/home/lgl/virtualenvs/py3_django/lib/python3.6/site-packages/rest_framework/views.py", line 483, in dispatch
    response = self.handle_exception(exc)
  File "/home/lgl/virtualenvs/py3_django/lib/python3.6/site-packages/rest_framework/views.py", line 443, in handle_exception
    self.raise_uncaught_exception(exc)
  File "/home/lgl/virtualenvs/py3_django/lib/python3.6/site-packages/rest_framework/views.py", line 480, in dispatch
    response = handler(request, *args, **kwargs)
  File "/home/lgl/virtualenvs/py3_django/lib/python3.6/site-packages/rest_framework/generics.py", line 192, in post
    return self.create(request, *args, **kwargs)
  File "/home/lgl/virtualenvs/py3_django/lib/python3.6/site-packages/rest_framework/mixins.py", line 20, in create
    serializer.is_valid(raise_exception=True)
  File "/home/lgl/virtualenvs/py3_django/lib/python3.6/site-packages/rest_framework/serializers.py", line 236, in is_valid
    self._validated_data = self.run_validation(self.initial_data)
  File "/home/lgl/virtualenvs/py3_django/lib/python3.6/site-packages/rest_framework/serializers.py", line 434, in run_validation
    value = self.to_internal_value(data)
  File "/home/lgl/virtualenvs/py3_django/lib/python3.6/site-packages/rest_framework/serializers.py", line 482, in to_internal_value
    fields = self._writable_fields
  File "/home/lgl/virtualenvs/py3_django/lib/python3.6/site-packages/django/utils/functional.py", line 37, in __get__
    res = instance.__dict__[self.name] = self.func(instance)
  File "/home/lgl/virtualenvs/py3_django/lib/python3.6/site-packages/rest_framework/serializers.py", line 370, in _writable_fields
    field for field in self.fields.values() if not field.read_only
  File "/home/lgl/virtualenvs/py3_django/lib/python3.6/site-packages/rest_framework/serializers.py", line 363, in fields
    for key, value in self.get_fields().items():
  File "/home/lgl/virtualenvs/py3_django/lib/python3.6/site-packages/rest_framework/serializers.py", line 1045, in get_fields
    source, info, model, depth
  File "/home/lgl/virtualenvs/py3_django/lib/python3.6/site-packages/rest_framework/serializers.py", line 1190, in build_field
    return self.build_unknown_field(field_name, model_class)
  File "/home/lgl/virtualenvs/py3_django/lib/python3.6/site-packages/rest_framework/serializers.py", line 1302, in build_unknown_field
    (field_name, model_class.__name__)
django.core.exceptions.ImproperlyConfigured: Field name `usernames` is not valid for model `User`.
ERROR 2019-10-10 17:44:33,779 basehttp 124 "POST /users/ HTTP/1.1" 500 19324
INFO 2019-10-10 17:47:14,791 basehttp 124 "GET /usernames/111111/count/ HTTP/1.1" 200 31
INFO 2019-10-10 17:47:14,799 basehttp 124 "GET /mobiles/13578945612/count/ HTTP/1.1" 200 34
ERROR 2019-10-10 17:47:14,865 log 228 Internal Server Error: /users/
Traceback (most recent call last):
  File "/home/lgl/virtualenvs/py3_django/lib/python3.6/site-packages/django/core/handlers/exception.py", line 34, in inner
    response = get_response(request)
  File "/home/lgl/virtualenvs/py3_django/lib/python3.6/site-packages/django/core/handlers/base.py", line 126, in _get_response
    response = self.process_exception_by_middleware(e, request)
  File "/home/lgl/virtualenvs/py3_django/lib/python3.6/site-packages/django/core/handlers/base.py", line 124, in _get_response
    response = wrapped_callback(request, *callback_args, **callback_kwargs)
  File "/home/lgl/virtualenvs/py3_django/lib/python3.6/site-packages/django/views/decorators/csrf.py", line 54, in wrapped_view
    return view_func(*args, **kwargs)
  File "/home/lgl/virtualenvs/py3_django/lib/python3.6/site-packages/django/views/generic/base.py", line 68, in view
    return self.dispatch(request, *args, **kwargs)
  File "/home/lgl/virtualenvs/py3_django/lib/python3.6/site-packages/rest_framework/views.py", line 483, in dispatch
    response = self.handle_exception(exc)
  File "/home/lgl/virtualenvs/py3_django/lib/python3.6/site-packages/rest_framework/views.py", line 443, in handle_exception
    self.raise_uncaught_exception(exc)
  File "/home/lgl/virtualenvs/py3_django/lib/python3.6/site-packages/rest_framework/views.py", line 480, in dispatch
    response = handler(request, *args, **kwargs)
  File "/home/lgl/virtualenvs/py3_django/lib/python3.6/site-packages/rest_framework/generics.py", line 192, in post
    return self.create(request, *args, **kwargs)
  File "/home/lgl/virtualenvs/py3_django/lib/python3.6/site-packages/rest_framework/mixins.py", line 20, in create
    serializer.is_valid(raise_exception=True)
  File "/home/lgl/virtualenvs/py3_django/lib/python3.6/site-packages/rest_framework/serializers.py", line 236, in is_valid
    self._validated_data = self.run_validation(self.initial_data)
  File "/home/lgl/virtualenvs/py3_django/lib/python3.6/site-packages/rest_framework/serializers.py", line 434, in run_validation
    value = self.to_internal_value(data)
  File "/home/lgl/virtualenvs/py3_django/lib/python3.6/site-packages/rest_framework/serializers.py", line 482, in to_internal_value
    fields = self._writable_fields
  File "/home/lgl/virtualenvs/py3_django/lib/python3.6/site-packages/django/utils/functional.py", line 37, in __get__
    res = instance.__dict__[self.name] = self.func(instance)
  File "/home/lgl/virtualenvs/py3_django/lib/python3.6/site-packages/rest_framework/serializers.py", line 370, in _writable_fields
    field for field in self.fields.values() if not field.read_only
  File "/home/lgl/virtualenvs/py3_django/lib/python3.6/site-packages/rest_framework/serializers.py", line 363, in fields
    for key, value in self.get_fields().items():
  File "/home/lgl/virtualenvs/py3_django/lib/python3.6/site-packages/rest_framework/serializers.py", line 1045, in get_fields
    source, info, model, depth
  File "/home/lgl/virtualenvs/py3_django/lib/python3.6/site-packages/rest_framework/serializers.py", line 1190, in build_field
    return self.build_unknown_field(field_name, model_class)
  File "/home/lgl/virtualenvs/py3_django/lib/python3.6/site-packages/rest_framework/serializers.py", line 1302, in build_unknown_field
    (field_name, model_class.__name__)
django.core.exceptions.ImproperlyConfigured: Field name `usernames` is not valid for model `User`.
ERROR 2019-10-10 17:47:14,866 basehttp 124 "POST /users/ HTTP/1.1" 500 19324
INFO 2019-10-10 17:50:08,623 basehttp 124 "GET /image_codes/ac988cde-4416-4ff2-9c55-a2e9d1f90a5f/ HTTP/1.1" 200 3462
INFO 2019-10-10 17:50:15,202 basehttp 124 "GET /image_codes/60e5394a-856c-4998-8ece-469c33c8ebd7/ HTTP/1.1" 200 3378
INFO 2019-10-10 17:50:25,545 basehttp 124 "GET /usernames/11111/count/ HTTP/1.1" 200 30
INFO 2019-10-10 17:50:36,497 basehttp 124 "GET /mobiles/13578945612/count/ HTTP/1.1" 200 34
INFO 2019-10-10 17:50:40,066 basehttp 124 "GET /sms_codes/13578945612/?text=BNJG&image_code_id=60e5394a-856c-4998-8ece-469c33c8ebd7 HTTP/1.1" 200 16
INFO 2019-10-10 17:50:40,071 basehttp 124 "GET /mobiles/13578945612/count/ HTTP/1.1" 200 34
INFO 2019-10-10 17:50:57,503 basehttp 124 "GET /usernames/11111/count/ HTTP/1.1" 200 30
INFO 2019-10-10 17:50:57,511 basehttp 124 "GET /mobiles/13578945612/count/ HTTP/1.1" 200 34
ERROR 2019-10-10 17:50:57,547 log 228 Internal Server Error: /users/
Traceback (most recent call last):
  File "/home/lgl/virtualenvs/py3_django/lib/python3.6/site-packages/django/core/handlers/exception.py", line 34, in inner
    response = get_response(request)
  File "/home/lgl/virtualenvs/py3_django/lib/python3.6/site-packages/django/core/handlers/base.py", line 126, in _get_response
    response = self.process_exception_by_middleware(e, request)
  File "/home/lgl/virtualenvs/py3_django/lib/python3.6/site-packages/django/core/handlers/base.py", line 124, in _get_response
    response = wrapped_callback(request, *callback_args, **callback_kwargs)
  File "/home/lgl/virtualenvs/py3_django/lib/python3.6/site-packages/django/views/decorators/csrf.py", line 54, in wrapped_view
    return view_func(*args, **kwargs)
  File "/home/lgl/virtualenvs/py3_django/lib/python3.6/site-packages/django/views/generic/base.py", line 68, in view
    return self.dispatch(request, *args, **kwargs)
  File "/home/lgl/virtualenvs/py3_django/lib/python3.6/site-packages/rest_framework/views.py", line 483, in dispatch
    response = self.handle_exception(exc)
  File "/home/lgl/virtualenvs/py3_django/lib/python3.6/site-packages/rest_framework/views.py", line 443, in handle_exception
    self.raise_uncaught_exception(exc)
  File "/home/lgl/virtualenvs/py3_django/lib/python3.6/site-packages/rest_framework/views.py", line 480, in dispatch
    response = handler(request, *args, **kwargs)
  File "/home/lgl/virtualenvs/py3_django/lib/python3.6/site-packages/rest_framework/generics.py", line 192, in post
    return self.create(request, *args, **kwargs)
  File "/home/lgl/virtualenvs/py3_django/lib/python3.6/site-packages/rest_framework/mixins.py", line 20, in create
    serializer.is_valid(raise_exception=True)
  File "/home/lgl/virtualenvs/py3_django/lib/python3.6/site-packages/rest_framework/serializers.py", line 236, in is_valid
    self._validated_data = self.run_validation(self.initial_data)
  File "/home/lgl/virtualenvs/py3_django/lib/python3.6/site-packages/rest_framework/serializers.py", line 434, in run_validation
    value = self.to_internal_value(data)
  File "/home/lgl/virtualenvs/py3_django/lib/python3.6/site-packages/rest_framework/serializers.py", line 482, in to_internal_value
    fields = self._writable_fields
  File "/home/lgl/virtualenvs/py3_django/lib/python3.6/site-packages/django/utils/functional.py", line 37, in __get__
    res = instance.__dict__[self.name] = self.func(instance)
  File "/home/lgl/virtualenvs/py3_django/lib/python3.6/site-packages/rest_framework/serializers.py", line 370, in _writable_fields
    field for field in self.fields.values() if not field.read_only
  File "/home/lgl/virtualenvs/py3_django/lib/python3.6/site-packages/rest_framework/serializers.py", line 363, in fields
    for key, value in self.get_fields().items():
  File "/home/lgl/virtualenvs/py3_django/lib/python3.6/site-packages/rest_framework/serializers.py", line 1045, in get_fields
    source, info, model, depth
  File "/home/lgl/virtualenvs/py3_django/lib/python3.6/site-packages/rest_framework/serializers.py", line 1190, in build_field
    return self.build_unknown_field(field_name, model_class)
  File "/home/lgl/virtualenvs/py3_django/lib/python3.6/site-packages/rest_framework/serializers.py", line 1302, in build_unknown_field
    (field_name, model_class.__name__)
django.core.exceptions.ImproperlyConfigured: Field name `usernames` is not valid for model `User`.
ERROR 2019-10-10 17:50:57,548 basehttp 124 "POST /users/ HTTP/1.1" 500 19325
INFO 2019-10-10 17:52:11,084 basehttp 124 "GET /image_codes/a4bc6249-60d8-4411-85ab-045db9f317d8/ HTTP/1.1" 200 3392
INFO 2019-10-10 17:52:22,466 basehttp 124 "GET /image_codes/e51de127-f74e-4301-ab99-537270f0e32a/ HTTP/1.1" 200 3082
INFO 2019-10-10 17:54:56,569 basehttp 124 "GET /usernames/454555/count/ HTTP/1.1" 200 31
INFO 2019-10-10 17:55:12,831 basehttp 124 "GET /mobiles/13555555555/count/ HTTP/1.1" 200 34
INFO 2019-10-10 17:55:55,277 basehttp 124 "GET /image_codes/f0547f61-9c03-47e2-ac77-63944cb9fb96/ HTTP/1.1" 200 3440
INFO 2019-10-10 17:56:04,252 basehttp 124 "GET /usernames/222222/count/ HTTP/1.1" 200 31
INFO 2019-10-10 17:57:04,466 basehttp 124 "GET /mobiles/13411111111/count/ HTTP/1.1" 200 34
INFO 2019-10-10 17:57:09,597 basehttp 124 "GET /sms_codes/13411111111/?text=GKTZ&image_code_id=f0547f61-9c03-47e2-ac77-63944cb9fb96 HTTP/1.1" 200 16
INFO 2019-10-10 17:57:09,601 basehttp 124 "GET /mobiles/13411111111/count/ HTTP/1.1" 200 34
INFO 2019-10-10 17:57:26,036 basehttp 124 "GET /usernames/222222/count/ HTTP/1.1" 200 31
INFO 2019-10-10 17:57:26,040 basehttp 124 "GET /mobiles/13411111111/count/ HTTP/1.1" 200 34
ERROR 2019-10-10 17:57:26,094 log 228 Internal Server Error: /users/
Traceback (most recent call last):
  File "/home/lgl/virtualenvs/py3_django/lib/python3.6/site-packages/django/core/handlers/exception.py", line 34, in inner
    response = get_response(request)
  File "/home/lgl/virtualenvs/py3_django/lib/python3.6/site-packages/django/core/handlers/base.py", line 126, in _get_response
    response = self.process_exception_by_middleware(e, request)
  File "/home/lgl/virtualenvs/py3_django/lib/python3.6/site-packages/django/core/handlers/base.py", line 124, in _get_response
    response = wrapped_callback(request, *callback_args, **callback_kwargs)
  File "/home/lgl/virtualenvs/py3_django/lib/python3.6/site-packages/django/views/decorators/csrf.py", line 54, in wrapped_view
    return view_func(*args, **kwargs)
  File "/home/lgl/virtualenvs/py3_django/lib/python3.6/site-packages/django/views/generic/base.py", line 68, in view
    return self.dispatch(request, *args, **kwargs)
  File "/home/lgl/virtualenvs/py3_django/lib/python3.6/site-packages/rest_framework/views.py", line 483, in dispatch
    response = self.handle_exception(exc)
  File "/home/lgl/virtualenvs/py3_django/lib/python3.6/site-packages/rest_framework/views.py", line 443, in handle_exception
    self.raise_uncaught_exception(exc)
  File "/home/lgl/virtualenvs/py3_django/lib/python3.6/site-packages/rest_framework/views.py", line 480, in dispatch
    response = handler(request, *args, **kwargs)
  File "/home/lgl/virtualenvs/py3_django/lib/python3.6/site-packages/rest_framework/generics.py", line 192, in post
    return self.create(request, *args, **kwargs)
  File "/home/lgl/virtualenvs/py3_django/lib/python3.6/site-packages/rest_framework/mixins.py", line 20, in create
    serializer.is_valid(raise_exception=True)
  File "/home/lgl/virtualenvs/py3_django/lib/python3.6/site-packages/rest_framework/serializers.py", line 236, in is_valid
    self._validated_data = self.run_validation(self.initial_data)
  File "/home/lgl/virtualenvs/py3_django/lib/python3.6/site-packages/rest_framework/serializers.py", line 434, in run_validation
    value = self.to_internal_value(data)
  File "/home/lgl/virtualenvs/py3_django/lib/python3.6/site-packages/rest_framework/serializers.py", line 482, in to_internal_value
    fields = self._writable_fields
  File "/home/lgl/virtualenvs/py3_django/lib/python3.6/site-packages/django/utils/functional.py", line 37, in __get__
    res = instance.__dict__[self.name] = self.func(instance)
  File "/home/lgl/virtualenvs/py3_django/lib/python3.6/site-packages/rest_framework/serializers.py", line 370, in _writable_fields
    field for field in self.fields.values() if not field.read_only
  File "/home/lgl/virtualenvs/py3_django/lib/python3.6/site-packages/rest_framework/serializers.py", line 363, in fields
    for key, value in self.get_fields().items():
  File "/home/lgl/virtualenvs/py3_django/lib/python3.6/site-packages/rest_framework/serializers.py", line 1045, in get_fields
    source, info, model, depth
  File "/home/lgl/virtualenvs/py3_django/lib/python3.6/site-packages/rest_framework/serializers.py", line 1190, in build_field
    return self.build_unknown_field(field_name, model_class)
  File "/home/lgl/virtualenvs/py3_django/lib/python3.6/site-packages/rest_framework/serializers.py", line 1302, in build_unknown_field
    (field_name, model_class.__name__)
django.core.exceptions.ImproperlyConfigured: Field name `usernames` is not valid for model `User`.
ERROR 2019-10-10 17:57:26,096 basehttp 124 "POST /users/ HTTP/1.1" 500 19325
INFO 2019-10-10 17:58:13,845 basehttp 124 "GET /mobiles/13411111111/count/ HTTP/1.1" 200 34
INFO 2019-10-10 17:58:13,853 basehttp 124 "GET /usernames/222222/count/ HTTP/1.1" 200 31
INFO 2019-10-10 18:06:13,933 basehttp 124 "GET /image_codes/ca5f6471-933b-44b3-b785-9f7c5261104a/ HTTP/1.1" 200 3288
INFO 2019-10-10 18:06:16,802 basehttp 124 "GET /usernames/222222/count/ HTTP/1.1" 200 31
INFO 2019-10-10 18:06:33,176 basehttp 124 "GET /mobiles/13578945612/count/ HTTP/1.1" 200 34
INFO 2019-10-10 18:11:46,960 basehttp 124 "GET /mobiles/13578945612/count/ HTTP/1.1" 200 34
INFO 2019-10-10 18:12:00,580 basehttp 124 "GET /sms_codes/13578945612/?text=MSTW&image_code_id=ca5f6471-933b-44b3-b785-9f7c5261104a HTTP/1.1" 200 16
INFO 2019-10-10 18:12:00,582 basehttp 124 "GET /mobiles/13578945612/count/ HTTP/1.1" 200 34
INFO 2019-10-10 18:12:06,333 basehttp 124 "GET /usernames/222222/count/ HTTP/1.1" 200 31
INFO 2019-10-10 18:12:06,340 basehttp 124 "GET /mobiles/13578945612/count/ HTTP/1.1" 200 34
WARNING 2019-10-10 18:12:06,342 log 228 Bad Request: /users/
WARNING 2019-10-10 18:12:06,343 basehttp 124 "POST /users/ HTTP/1.1" 400 49
WARNING 2019-10-10 18:12:55,889 log 228 Bad Request: /users/
INFO 2019-10-10 18:12:55,889 basehttp 124 "GET /usernames/222222/count/ HTTP/1.1" 200 31
INFO 2019-10-10 18:12:55,890 basehttp 124 "GET /mobiles/13578945612/count/ HTTP/1.1" 200 34
WARNING 2019-10-10 18:12:55,892 basehttp 124 "POST /users/ HTTP/1.1" 400 49
WARNING 2019-10-10 18:12:57,968 log 228 Bad Request: /users/
INFO 2019-10-10 18:12:57,969 basehttp 124 "GET /usernames/222222/count/ HTTP/1.1" 200 31
INFO 2019-10-10 18:12:57,970 basehttp 124 "GET /mobiles/13578945612/count/ HTTP/1.1" 200 34
WARNING 2019-10-10 18:12:57,972 basehttp 124 "POST /users/ HTTP/1.1" 400 49
INFO 2019-10-10 18:12:58,215 basehttp 124 "GET /usernames/222222/count/ HTTP/1.1" 200 31
INFO 2019-10-10 18:12:58,219 basehttp 124 "GET /mobiles/13578945612/count/ HTTP/1.1" 200 34
WARNING 2019-10-10 18:12:58,224 log 228 Bad Request: /users/
WARNING 2019-10-10 18:12:58,225 basehttp 124 "POST /users/ HTTP/1.1" 400 49
INFO 2019-10-10 18:12:58,400 basehttp 124 "GET /usernames/222222/count/ HTTP/1.1" 200 31
WARNING 2019-10-10 18:12:58,416 log 228 Bad Request: /users/
INFO 2019-10-10 18:12:58,416 basehttp 124 "GET /mobiles/13578945612/count/ HTTP/1.1" 200 34
WARNING 2019-10-10 18:12:58,417 basehttp 124 "POST /users/ HTTP/1.1" 400 49
INFO 2019-10-10 18:12:58,671 basehttp 124 "GET /usernames/222222/count/ HTTP/1.1" 200 31
INFO 2019-10-10 18:12:58,679 basehttp 124 "GET /mobiles/13578945612/count/ HTTP/1.1" 200 34
WARNING 2019-10-10 18:12:58,683 log 228 Bad Request: /users/
WARNING 2019-10-10 18:12:58,685 basehttp 124 "POST /users/ HTTP/1.1" 400 49
INFO 2019-10-10 18:12:58,867 basehttp 124 "GET /mobiles/13578945612/count/ HTTP/1.1" 200 34
INFO 2019-10-10 18:12:58,869 basehttp 124 "GET /usernames/222222/count/ HTTP/1.1" 200 31
WARNING 2019-10-10 18:12:58,873 log 228 Bad Request: /users/
WARNING 2019-10-10 18:12:58,874 basehttp 124 "POST /users/ HTTP/1.1" 400 49
INFO 2019-10-10 18:12:59,048 basehttp 124 "GET /usernames/222222/count/ HTTP/1.1" 200 31
WARNING 2019-10-10 18:12:59,061 log 228 Bad Request: /users/
INFO 2019-10-10 18:12:59,062 basehttp 124 "GET /mobiles/13578945612/count/ HTTP/1.1" 200 34
WARNING 2019-10-10 18:12:59,066 basehttp 124 "POST /users/ HTTP/1.1" 400 49
WARNING 2019-10-10 18:13:01,162 log 228 Bad Request: /sms_codes/13578945612/
WARNING 2019-10-10 18:13:01,164 basehttp 124 "GET /sms_codes/13578945612/?text=MSTW&image_code_id=ca5f6471-933b-44b3-b785-9f7c5261104a HTTP/1.1" 400 49
INFO 2019-10-10 18:13:01,169 basehttp 124 "GET /mobiles/13578945612/count/ HTTP/1.1" 200 34
INFO 2019-10-10 18:13:15,029 basehttp 124 "GET /image_codes/e51d0dca-5a94-465b-883e-03395a5eef24/ HTTP/1.1" 200 3329
INFO 2019-10-10 18:13:25,310 basehttp 124 "GET /sms_codes/13578945612/?text=ZDKN&image_code_id=e51d0dca-5a94-465b-883e-03395a5eef24 HTTP/1.1" 200 16
INFO 2019-10-10 18:13:25,315 basehttp 124 "GET /mobiles/13578945612/count/ HTTP/1.1" 200 34
INFO 2019-10-10 18:13:40,312 basehttp 124 "GET /usernames/222222/count/ HTTP/1.1" 200 31
INFO 2019-10-10 18:13:40,318 basehttp 124 "GET /mobiles/13578945612/count/ HTTP/1.1" 200 34
WARNING 2019-10-10 18:13:40,319 log 228 Bad Request: /users/
WARNING 2019-10-10 18:13:40,321 basehttp 124 "POST /users/ HTTP/1.1" 400 49
INFO 2019-10-10 18:14:07,635 basehttp 124 "GET /usernames/2222222/count/ HTTP/1.1" 200 32
INFO 2019-10-10 18:14:07,722 basehttp 124 "GET /mobiles/13578945612/count/ HTTP/1.1" 200 34
INFO 2019-10-10 18:14:07,726 basehttp 124 "GET /usernames/2222222/count/ HTTP/1.1" 200 32
WARNING 2019-10-10 18:14:07,729 log 228 Bad Request: /users/
WARNING 2019-10-10 18:14:07,729 basehttp 124 "POST /users/ HTTP/1.1" 400 49
INFO 2019-10-10 18:14:14,101 basehttp 124 "GET /image_codes/59c2041a-4747-49f2-bfbf-aeadc975a639/ HTTP/1.1" 200 3014
INFO 2019-10-10 18:14:26,289 basehttp 124 "GET /sms_codes/13578945612/?text=SSVN&image_code_id=59c2041a-4747-49f2-bfbf-aeadc975a639 HTTP/1.1" 200 16
INFO 2019-10-10 18:14:26,293 basehttp 124 "GET /mobiles/13578945612/count/ HTTP/1.1" 200 34
INFO 2019-10-11 16:18:15,778 basehttp 124 "GET /image_codes/1d7a27af-30cb-4a61-b34b-cb84dc955462/ HTTP/1.1" 200 3224
INFO 2019-10-11 16:18:28,415 basehttp 124 "GET /usernames/jjjjjj/count/ HTTP/1.1" 200 31
INFO 2019-10-11 16:18:40,850 basehttp 124 "GET /mobiles/13578945612/count/ HTTP/1.1" 200 34
INFO 2019-10-11 16:19:02,897 basehttp 124 "GET /sms_codes/13578945612/?text=VJNR&image_code_id=1d7a27af-30cb-4a61-b34b-cb84dc955462 HTTP/1.1" 200 16
INFO 2019-10-11 16:19:02,903 basehttp 124 "GET /mobiles/13578945612/count/ HTTP/1.1" 200 34
INFO 2019-10-11 16:19:23,931 basehttp 124 "OPTIONS /users/ HTTP/1.1" 200 0
INFO 2019-10-11 16:19:23,939 basehttp 124 "GET /mobiles/13578945612/count/ HTTP/1.1" 200 34
INFO 2019-10-11 16:19:23,941 basehttp 124 "GET /usernames/jjjjjj/count/ HTTP/1.1" 200 31
WARNING 2019-10-11 16:19:23,959 log 228 Bad Request: /users/
WARNING 2019-10-11 16:19:23,960 basehttp 124 "POST /users/ HTTP/1.1" 400 49
INFO 2019-10-11 16:19:48,849 basehttp 124 "GET /image_codes/b650f415-0e1d-41d4-8002-f30e430d3fa7/ HTTP/1.1" 200 3632
INFO 2019-10-11 16:19:54,336 basehttp 124 "GET /usernames/aabbb/count/ HTTP/1.1" 200 30
INFO 2019-10-11 16:20:06,045 basehttp 124 "GET /mobiles/13411111111/count/ HTTP/1.1" 200 34
INFO 2019-10-11 16:20:10,731 basehttp 124 "GET /sms_codes/13411111111/?text=q5yz&image_code_id=b650f415-0e1d-41d4-8002-f30e430d3fa7 HTTP/1.1" 200 16
INFO 2019-10-11 16:20:10,736 basehttp 124 "GET /mobiles/13411111111/count/ HTTP/1.1" 200 34
WARNING 2019-10-11 16:21:41,959 log 228 Bad Request: /users/
INFO 2019-10-11 16:21:41,959 basehttp 124 "GET /mobiles/13411111111/count/ HTTP/1.1" 200 34
INFO 2019-10-11 16:21:41,960 basehttp 124 "GET /usernames/aabbb/count/ HTTP/1.1" 200 30
WARNING 2019-10-11 16:21:41,960 basehttp 124 "POST /users/ HTTP/1.1" 400 49
INFO 2019-10-11 16:23:16,627 basehttp 124 "GET /usernames/aabbb/count/ HTTP/1.1" 200 30
INFO 2019-10-11 16:23:16,629 basehttp 124 "GET /mobiles/13411111111/count/ HTTP/1.1" 200 34
WARNING 2019-10-11 16:23:16,632 log 228 Bad Request: /users/
WARNING 2019-10-11 16:23:16,632 basehttp 124 "POST /users/ HTTP/1.1" 400 49
INFO 2019-10-11 16:24:33,108 basehttp 124 "GET /image_codes/c779f730-ae94-44c1-99d6-cb38fb1fb13b/ HTTP/1.1" 200 3531
INFO 2019-10-11 16:24:36,355 basehttp 124 "GET /usernames/aabbb/count/ HTTP/1.1" 200 30
INFO 2019-10-11 16:24:49,037 basehttp 124 "GET /mobiles/13411111118/count/ HTTP/1.1" 200 34
INFO 2019-10-11 16:24:54,625 basehttp 124 "GET /sms_codes/13411111118/?text=egik&image_code_id=c779f730-ae94-44c1-99d6-cb38fb1fb13b HTTP/1.1" 200 16
INFO 2019-10-11 16:24:54,630 basehttp 124 "GET /mobiles/13411111118/count/ HTTP/1.1" 200 34
INFO 2019-10-11 16:25:14,477 basehttp 124 "GET /usernames/aabbb/count/ HTTP/1.1" 200 30
INFO 2019-10-11 16:25:14,480 basehttp 124 "GET /mobiles/13411111118/count/ HTTP/1.1" 200 34
ERROR 2019-10-11 16:25:15,172 log 228 Internal Server Error: /users/
Traceback (most recent call last):
  File "/home/lgl/virtualenvs/py3_django/lib/python3.6/site-packages/django/core/handlers/exception.py", line 34, in inner
    response = get_response(request)
  File "/home/lgl/virtualenvs/py3_django/lib/python3.6/site-packages/django/core/handlers/base.py", line 126, in _get_response
    response = self.process_exception_by_middleware(e, request)
  File "/home/lgl/virtualenvs/py3_django/lib/python3.6/site-packages/django/core/handlers/base.py", line 124, in _get_response
    response = wrapped_callback(request, *callback_args, **callback_kwargs)
  File "/home/lgl/virtualenvs/py3_django/lib/python3.6/site-packages/django/views/decorators/csrf.py", line 54, in wrapped_view
    return view_func(*args, **kwargs)
  File "/home/lgl/virtualenvs/py3_django/lib/python3.6/site-packages/django/views/generic/base.py", line 68, in view
    return self.dispatch(request, *args, **kwargs)
  File "/home/lgl/virtualenvs/py3_django/lib/python3.6/site-packages/rest_framework/views.py", line 483, in dispatch
    response = self.handle_exception(exc)
  File "/home/lgl/virtualenvs/py3_django/lib/python3.6/site-packages/rest_framework/views.py", line 443, in handle_exception
    self.raise_uncaught_exception(exc)
  File "/home/lgl/virtualenvs/py3_django/lib/python3.6/site-packages/rest_framework/views.py", line 480, in dispatch
    response = handler(request, *args, **kwargs)
  File "/home/lgl/virtualenvs/py3_django/lib/python3.6/site-packages/rest_framework/generics.py", line 192, in post
    return self.create(request, *args, **kwargs)
  File "/home/lgl/virtualenvs/py3_django/lib/python3.6/site-packages/rest_framework/mixins.py", line 20, in create
    serializer.is_valid(raise_exception=True)
  File "/home/lgl/virtualenvs/py3_django/lib/python3.6/site-packages/rest_framework/serializers.py", line 236, in is_valid
    self._validated_data = self.run_validation(self.initial_data)
  File "/home/lgl/virtualenvs/py3_django/lib/python3.6/site-packages/rest_framework/serializers.py", line 437, in run_validation
    value = self.validate(value)
  File "/home/lgl/workplace/django_project/meiduo_mall/meiduo_mall/apps/users/serializers.py", line 40, in validate
    print(data['sms_code'], real_sms_code.decode())
AttributeError: 'NoneType' object has no attribute 'decode'
ERROR 2019-10-11 16:25:15,173 basehttp 124 "POST /users/ HTTP/1.1" 500 19918
INFO 2019-10-11 16:25:55,852 basehttp 124 "GET /mobiles/13411111118/count/ HTTP/1.1" 200 34
WARNING 2019-10-11 16:25:55,857 log 228 Bad Request: /sms_codes/13411111118/
WARNING 2019-10-11 16:25:55,858 basehttp 124 "GET /sms_codes/13411111118/?text=egik&image_code_id=c779f730-ae94-44c1-99d6-cb38fb1fb13b HTTP/1.1" 400 49
INFO 2019-10-11 16:25:59,021 basehttp 124 "GET /image_codes/9ae70c55-013f-4bbb-b322-f9a7f2a426b4/ HTTP/1.1" 200 3279
INFO 2019-10-11 16:26:09,059 basehttp 124 "GET /sms_codes/13411111118/?text=vfet&image_code_id=9ae70c55-013f-4bbb-b322-f9a7f2a426b4 HTTP/1.1" 200 16
INFO 2019-10-11 16:26:09,064 basehttp 124 "GET /mobiles/13411111118/count/ HTTP/1.1" 200 34
INFO 2019-10-11 16:26:27,822 basehttp 124 "GET /usernames/aabbb/count/ HTTP/1.1" 200 30
INFO 2019-10-11 16:26:27,823 basehttp 124 "GET /mobiles/13411111118/count/ HTTP/1.1" 200 34
WARNING 2019-10-11 16:26:27,830 log 228 Bad Request: /users/
WARNING 2019-10-11 16:26:27,831 basehttp 124 "POST /users/ HTTP/1.1" 400 49
INFO 2019-10-11 16:27:49,079 basehttp 124 "GET /mobiles/13411111118/count/ HTTP/1.1" 200 34
WARNING 2019-10-11 16:27:49,083 log 228 Bad Request: /sms_codes/13411111118/
WARNING 2019-10-11 16:27:49,084 basehttp 124 "GET /sms_codes/13411111118/?text=vfet&image_code_id=9ae70c55-013f-4bbb-b322-f9a7f2a426b4 HTTP/1.1" 400 49
INFO 2019-10-11 16:27:50,263 basehttp 124 "GET /image_codes/86330b70-a89b-4bec-8515-39fb349f506f/ HTTP/1.1" 200 2692
INFO 2019-10-11 16:27:55,363 basehttp 124 "GET /sms_codes/13411111118/?text=ylkj&image_code_id=86330b70-a89b-4bec-8515-39fb349f506f HTTP/1.1" 200 16
INFO 2019-10-11 16:27:55,368 basehttp 124 "GET /mobiles/13411111118/count/ HTTP/1.1" 200 34
INFO 2019-10-11 16:28:46,918 basehttp 124 "GET /image_codes/e9872441-10b2-4c61-9520-e66d5d4a0309/ HTTP/1.1" 200 3325
INFO 2019-10-11 16:28:56,330 basehttp 124 "GET /sms_codes/13411111118/?text=zvde&image_code_id=e9872441-10b2-4c61-9520-e66d5d4a0309 HTTP/1.1" 200 16
INFO 2019-10-11 16:28:56,334 basehttp 124 "GET /mobiles/13411111118/count/ HTTP/1.1" 200 34
INFO 2019-10-11 16:30:12,134 basehttp 124 "GET /mobiles/13411111118/count/ HTTP/1.1" 200 34
WARNING 2019-10-11 16:30:12,137 log 228 Bad Request: /sms_codes/13411111118/
WARNING 2019-10-11 16:30:12,138 basehttp 124 "GET /sms_codes/13411111118/?text=zvde&image_code_id=e9872441-10b2-4c61-9520-e66d5d4a0309 HTTP/1.1" 400 49
INFO 2019-10-11 16:30:13,125 basehttp 124 "GET /image_codes/600a85aa-462d-4de1-a5dc-f85cacf1c8f9/ HTTP/1.1" 200 3056
INFO 2019-10-11 16:30:15,873 basehttp 124 "GET /image_codes/b230af39-fa6e-4281-a425-3983a6244399/ HTTP/1.1" 200 3281
WARNING 2019-10-11 16:30:22,492 log 228 Bad Request: /sms_codes/13411111118/
WARNING 2019-10-11 16:30:22,493 basehttp 124 "GET /sms_codes/13411111118/?text=6vac&image_code_id=b230af39-fa6e-4281-a425-3983a6244399 HTTP/1.1" 400 46
INFO 2019-10-11 16:30:22,495 basehttp 124 "GET /mobiles/13411111118/count/ HTTP/1.1" 200 34
INFO 2019-10-11 16:30:23,721 basehttp 124 "GET /image_codes/15636176-60e1-4ba3-9f8b-b5aec391be26/ HTTP/1.1" 200 3314
INFO 2019-10-11 16:30:29,540 basehttp 124 "GET /sms_codes/13411111118/?text=qjth&image_code_id=15636176-60e1-4ba3-9f8b-b5aec391be26 HTTP/1.1" 200 16
INFO 2019-10-11 16:30:29,542 basehttp 124 "GET /mobiles/13411111118/count/ HTTP/1.1" 200 34
INFO 2019-10-11 16:30:48,909 basehttp 124 "GET /usernames/aabbb/count/ HTTP/1.1" 200 30
INFO 2019-10-11 16:30:48,910 basehttp 124 "GET /mobiles/13411111118/count/ HTTP/1.1" 200 34
WARNING 2019-10-11 16:30:48,918 log 228 Bad Request: /users/
WARNING 2019-10-11 16:30:48,919 basehttp 124 "POST /users/ HTTP/1.1" 400 49
INFO 2019-10-11 16:31:36,391 basehttp 124 "GET /mobiles/13411111118/count/ HTTP/1.1" 200 34
WARNING 2019-10-11 16:31:36,395 log 228 Bad Request: /sms_codes/13411111118/
WARNING 2019-10-11 16:31:36,396 basehttp 124 "GET /sms_codes/13411111118/?text=qjth&image_code_id=15636176-60e1-4ba3-9f8b-b5aec391be26 HTTP/1.1" 400 49
INFO 2019-10-11 16:31:37,729 basehttp 124 "GET /image_codes/dc7b6a5c-0953-406a-9485-ebc1538623cf/ HTTP/1.1" 200 3253
INFO 2019-10-11 16:31:44,494 basehttp 124 "GET /sms_codes/13411111118/?text=mq3p&image_code_id=dc7b6a5c-0953-406a-9485-ebc1538623cf HTTP/1.1" 200 16
INFO 2019-10-11 16:31:44,498 basehttp 124 "GET /mobiles/13411111118/count/ HTTP/1.1" 200 34
WARNING 2019-10-11 16:31:57,232 log 228 Bad Request: /users/
INFO 2019-10-11 16:31:57,233 basehttp 124 "GET /mobiles/13411111118/count/ HTTP/1.1" 200 34
INFO 2019-10-11 16:31:57,237 basehttp 124 "GET /usernames/aabbb/count/ HTTP/1.1" 200 30
WARNING 2019-10-11 16:31:57,234 basehttp 124 "POST /users/ HTTP/1.1" 400 49
WARNING 2019-10-11 16:32:45,046 log 228 Bad Request: /sms_codes/13411111118/
WARNING 2019-10-11 16:32:45,047 basehttp 124 "GET /sms_codes/13411111118/?text=mq3p&image_code_id=dc7b6a5c-0953-406a-9485-ebc1538623cf HTTP/1.1" 400 49
INFO 2019-10-11 16:32:45,055 basehttp 124 "GET /mobiles/13411111118/count/ HTTP/1.1" 200 34
INFO 2019-10-11 16:32:50,433 basehttp 124 "GET /image_codes/9205d91b-d142-402c-8eab-1daf1a762bd8/ HTTP/1.1" 200 3077
INFO 2019-10-11 16:32:56,108 basehttp 124 "GET /sms_codes/13411111118/?text=wbxf&image_code_id=9205d91b-d142-402c-8eab-1daf1a762bd8 HTTP/1.1" 200 16
INFO 2019-10-11 16:32:56,114 basehttp 124 "GET /mobiles/13411111118/count/ HTTP/1.1" 200 34
INFO 2019-10-11 16:33:13,340 basehttp 124 "GET /usernames/aabbb/count/ HTTP/1.1" 200 30
INFO 2019-10-11 16:33:13,340 basehttp 124 "GET /mobiles/13411111118/count/ HTTP/1.1" 200 34
WARNING 2019-10-11 16:33:13,343 log 228 Bad Request: /users/
WARNING 2019-10-11 16:33:13,344 basehttp 124 "POST /users/ HTTP/1.1" 400 49
INFO 2019-10-11 16:33:42,185 basehttp 124 "GET /mobiles/13411111118/count/ HTTP/1.1" 200 34
INFO 2019-10-11 16:33:42,185 basehttp 124 "GET /usernames/aabbb/count/ HTTP/1.1" 200 30
WARNING 2019-10-11 16:33:42,190 log 228 Bad Request: /users/
WARNING 2019-10-11 16:33:42,190 basehttp 124 "POST /users/ HTTP/1.1" 400 49
WARNING 2019-10-11 16:35:41,310 log 228 Bad Request: /sms_codes/13411111118/
INFO 2019-10-11 16:35:41,311 basehttp 124 "GET /mobiles/13411111118/count/ HTTP/1.1" 200 34
WARNING 2019-10-11 16:35:41,311 basehttp 124 "GET /sms_codes/13411111118/?text=wbxf&image_code_id=9205d91b-d142-402c-8eab-1daf1a762bd8 HTTP/1.1" 400 49
INFO 2019-10-11 16:35:42,640 basehttp 124 "GET /image_codes/119497d0-148a-427c-9ce6-6b9cba956b72/ HTTP/1.1" 200 3303
INFO 2019-10-11 16:35:49,464 basehttp 124 "GET /sms_codes/13411111118/?text=kjup&image_code_id=119497d0-148a-427c-9ce6-6b9cba956b72 HTTP/1.1" 200 16
INFO 2019-10-11 16:35:49,468 basehttp 124 "GET /mobiles/13411111118/count/ HTTP/1.1" 200 34
INFO 2019-10-11 16:36:04,648 basehttp 124 "GET /mobiles/13411111118/count/ HTTP/1.1" 200 34
INFO 2019-10-11 16:36:04,651 basehttp 124 "GET /usernames/aabbb/count/ HTTP/1.1" 200 30
INFO 2019-10-11 16:36:04,884 basehttp 124 "POST /users/ HTTP/1.1" 201 222
INFO 2019-10-11 16:38:24,884 basehttp 124 "GET /image_codes/50561a3d-9b98-4b9b-a8c3-a32a265d60eb/ HTTP/1.1" 200 3022
INFO 2019-10-11 16:39:39,567 basehttp 124 "GET /image_codes/b867dc83-d819-4110-adf2-2f77597b9e5b/ HTTP/1.1" 200 3018
INFO 2019-10-11 16:39:46,079 basehttp 124 "GET /usernames/lgljy/count/ HTTP/1.1" 200 30
INFO 2019-10-11 16:40:00,271 basehttp 124 "GET /mobiles/13020785602/count/ HTTP/1.1" 200 34
INFO 2019-10-11 16:40:13,483 basehttp 124 "GET /sms_codes/13020785602/?text=FCOZ&image_code_id=b867dc83-d819-4110-adf2-2f77597b9e5b HTTP/1.1" 200 16
INFO 2019-10-11 16:40:13,488 basehttp 124 "GET /mobiles/13020785602/count/ HTTP/1.1" 200 34
INFO 2019-10-11 16:40:22,722 basehttp 124 "GET /mobiles/13020785602/count/ HTTP/1.1" 200 34
INFO 2019-10-11 16:40:22,723 basehttp 124 "GET /usernames/lgljy/count/ HTTP/1.1" 200 30
INFO 2019-10-11 16:40:22,951 basehttp 124 "POST /users/ HTTP/1.1" 201 222
INFO 2019-10-11 16:58:10,157 basehttp 124 "OPTIONS /authorizations/ HTTP/1.1" 200 0
INFO 2019-10-11 16:58:10,251 basehttp 124 "POST /authorizations/ HTTP/1.1" 200 204
INFO 2019-10-11 16:58:10,441 basehttp 124 "OPTIONS /cart/ HTTP/1.1" 200 0
WARNING 2019-10-11 16:58:10,532 log 228 Not Found: /cart/
WARNING 2019-10-11 16:58:10,533 basehttp 124 "GET /cart/ HTTP/1.1" 404 3039
WARNING 2019-10-11 16:58:17,684 log 228 Not Found: /cart/
WARNING 2019-10-11 16:58:17,686 basehttp 124 "GET /cart/ HTTP/1.1" 404 3039
WARNING 2019-10-11 16:58:29,166 log 228 Bad Request: /authorizations/
WARNING 2019-10-11 16:58:29,167 basehttp 124 "POST /authorizations/ HTTP/1.1" 400 67
WARNING 2019-10-11 16:58:39,412 log 228 Bad Request: /authorizations/
WARNING 2019-10-11 16:58:39,413 basehttp 124 "POST /authorizations/ HTTP/1.1" 400 67
WARNING 2019-10-11 16:58:40,770 log 228 Bad Request: /authorizations/
WARNING 2019-10-11 16:58:40,770 basehttp 124 "POST /authorizations/ HTTP/1.1" 400 67
INFO 2019-10-11 16:58:47,387 basehttp 124 "POST /authorizations/ HTTP/1.1" 200 204
WARNING 2019-10-11 16:58:47,567 log 228 Not Found: /cart/
WARNING 2019-10-11 16:58:47,567 basehttp 124 "GET /cart/ HTTP/1.1" 404 3039
WARNING 2019-10-11 16:58:54,742 log 228 Not Found: /cart/
WARNING 2019-10-11 16:58:54,743 basehttp 124 "GET /cart/ HTTP/1.1" 404 3039
WARNING 2019-10-11 17:24:42,842 log 228 Not Found: /cart/
WARNING 2019-10-11 17:24:42,843 basehttp 124 "GET /cart/ HTTP/1.1" 404 3039
WARNING 2019-10-11 17:25:03,647 log 228 Not Found: /cart/
WARNING 2019-10-11 17:25:03,648 basehttp 124 "GET /cart/ HTTP/1.1" 404 3039
WARNING 2019-10-11 17:25:04,164 log 228 Not Found: /cart/
WARNING 2019-10-11 17:25:04,165 basehttp 124 "GET /cart/ HTTP/1.1" 404 3039
INFO 2019-10-11 17:25:08,226 basehttp 124 "GET /image_codes/17a60efe-5f37-421d-a72f-86d55dd709d7/ HTTP/1.1" 200 3245
INFO 2019-10-12 14:45:44,461 basehttp 124 "OPTIONS /cart/ HTTP/1.1" 200 0
WARNING 2019-10-12 14:45:44,526 log 228 Not Found: /cart/
WARNING 2019-10-12 14:45:44,526 basehttp 124 "GET /cart/ HTTP/1.1" 404 3264
INFO 2019-10-12 14:46:28,910 basehttp 124 "GET /image_codes/c7e66adb-0993-41e2-a339-fafc196dbae0/ HTTP/1.1" 200 3242
INFO 2019-10-12 14:46:32,527 basehttp 124 "GET /image_codes/ec2c266c-3ef7-43a8-b22c-2ad918a050b4/ HTTP/1.1" 200 3471
INFO 2019-10-12 14:46:47,134 basehttp 124 "GET /image_codes/6dea6b90-5606-4899-979a-3cd4f50ad59b/ HTTP/1.1" 200 2910
INFO 2019-10-12 14:46:51,927 basehttp 124 "GET /image_codes/862b65db-9d12-4528-9e9a-8bd55039524a/ HTTP/1.1" 200 3160
WARNING 2019-10-12 14:47:04,729 log 228 Not Found: /accounts/lgljy/sms/token/
WARNING 2019-10-12 14:47:04,729 basehttp 124 "GET /accounts/lgljy/sms/token/?text=qrvw&image_code_id=862b65db-9d12-4528-9e9a-8bd55039524a HTTP/1.1" 404 3389
INFO 2019-10-12 14:47:30,740 basehttp 124 "GET /image_codes/828545e3-591f-4a7a-9047-c5142e8cc1c6/ HTTP/1.1" 200 3370
INFO 2019-10-12 14:47:39,013 basehttp 124 "GET /usernames/lgljy/count/ HTTP/1.1" 200 30
INFO 2019-10-12 14:48:04,512 basehttp 124 "GET /image_codes/9695adbb-7214-4168-ab4b-eb19bd2b7a52/ HTTP/1.1" 200 3478
WARNING 2019-10-12 14:48:16,695 log 228 Not Found: /accounts/lgljy/sms/token/
WARNING 2019-10-12 14:48:16,696 basehttp 124 "GET /accounts/lgljy/sms/token/?text=BJKL&image_code_id=9695adbb-7214-4168-ab4b-eb19bd2b7a52 HTTP/1.1" 404 3389
INFO 2019-10-12 14:53:52,516 basehttp 124 "GET /image_codes/0c1d3dbd-7f70-49ac-8bbf-909f5dc62218/ HTTP/1.1" 200 3028
WARNING 2019-10-12 14:54:09,880 log 228 Not Found: /accounts/lgljy/sms/token/
WARNING 2019-10-12 14:54:09,880 basehttp 124 "GET /accounts/lgljy/sms/token/?text=YYJP&image_code_id=0c1d3dbd-7f70-49ac-8bbf-909f5dc62218 HTTP/1.1" 404 3389
INFO 2019-10-12 14:59:57,131 basehttp 124 "GET /image_codes/1079725e-03bd-4058-9d26-5e66f4469d04/ HTTP/1.1" 200 3199
WARNING 2019-10-12 15:00:07,201 log 228 Not Found: /accounts/lgljy/sms/token/
WARNING 2019-10-12 15:00:07,202 basehttp 124 "GET /accounts/lgljy/sms/token/?text=GQSY&image_code_id=1079725e-03bd-4058-9d26-5e66f4469d04 HTTP/1.1" 404 3389
INFO 2019-10-12 15:01:21,386 basehttp 124 "GET /image_codes/d5d948eb-6128-4a12-9050-9184e5d65d8d/ HTTP/1.1" 200 3187
WARNING 2019-10-12 15:01:29,924 log 228 Not Found: /accounts/lgljy/sms/token/
WARNING 2019-10-12 15:01:29,925 basehttp 124 "GET /accounts/lgljy/sms/token/?text=S6BY&image_code_id=d5d948eb-6128-4a12-9050-9184e5d65d8d HTTP/1.1" 404 3389
INFO 2019-10-12 15:02:22,066 basehttp 124 "GET /image_codes/258d0f7f-52df-4057-9183-c1de964895cb/ HTTP/1.1" 200 3314
WARNING 2019-10-12 15:02:36,092 log 228 Not Found: /accounts/13020785602/sms/token/
WARNING 2019-10-12 15:02:36,092 basehttp 124 "GET /accounts/13020785602/sms/token/?text=BGYZ&image_code_id=258d0f7f-52df-4057-9183-c1de964895cb HTTP/1.1" 404 3407
WARNING 2019-10-17 15:58:25,251 log 228 Not Found: /
WARNING 2019-10-17 15:58:25,267 basehttp 124 "GET / HTTP/1.1" 404 3332
INFO 2019-10-17 15:58:30,718 basehttp 124 "GET /docs/ HTTP/1.1" 200 46056
INFO 2019-10-17 15:58:30,758 basehttp 124 "GET /static/rest_framework/docs/css/base.css HTTP/1.1" 200 5942
INFO 2019-10-17 15:58:30,763 basehttp 124 "GET /static/rest_framework/css/bootstrap.min.css HTTP/1.1" 200 24576
INFO 2019-10-17 15:58:30,764 basehttp 124 "GET /static/rest_framework/docs/css/jquery.json-view.min.css HTTP/1.1" 200 1307
INFO 2019-10-17 15:58:30,764 basehttp 124 "GET /static/rest_framework/css/bootstrap-theme.min.css HTTP/1.1" 200 8192
INFO 2019-10-17 15:58:30,764 basehttp 124 "GET /static/rest_framework/js/coreapi-0.1.1.js HTTP/1.1" 200 8192
INFO 2019-10-17 15:58:30,770 basehttp 124 "GET /static/rest_framework/css/font-awesome-4.0.3.css HTTP/1.1" 200 21658
INFO 2019-10-17 15:58:30,773 basehttp 124 "GET /static/rest_framework/docs/css/base.css HTTP/1.1" 200 5942
INFO 2019-10-17 15:58:30,775 basehttp 124 "GET /static/rest_framework/css/font-awesome-4.0.3.css HTTP/1.1" 200 21658
INFO 2019-10-17 15:58:30,814 basehttp 124 "GET /static/rest_framework/css/bootstrap.min.css HTTP/1.1" 200 121200
INFO 2019-10-17 15:58:30,814 basehttp 124 "GET /static/rest_framework/docs/js/api.js HTTP/1.1" 200 10539
INFO 2019-10-17 15:58:30,818 basehttp 124 "GET /static/rest_framework/docs/js/jquery.json-view.min.js HTTP/1.1" 200 2700
INFO 2019-10-17 15:58:30,818 basehttp 124 "GET /static/rest_framework/docs/css/jquery.json-view.min.css HTTP/1.1" 200 1307
INFO 2019-10-17 15:58:30,841 basehttp 124 "GET /docs/schema.js HTTP/1.1" 200 4040
INFO 2019-10-17 15:58:30,884 basehttp 124 "GET /static/rest_framework/css/bootstrap-theme.min.css HTTP/1.1" 200 124939
INFO 2019-10-17 15:58:30,884 basehttp 124 "GET /static/rest_framework/js/bootstrap.min.js HTTP/1.1" 200 37045
ERROR 2019-10-17 15:58:30,924 basehttp 124 "GET /static/rest_framework/css/bootstrap.min.css HTTP/1.1" 500 59
ERROR 2019-10-17 15:58:30,926 basehttp 124 "GET /static/rest_framework/css/font-awesome-4.0.3.css HTTP/1.1" 500 59
INFO 2019-10-17 15:58:30,927 basehttp 124 "GET /static/rest_framework/js/coreapi-0.1.1.js HTTP/1.1" 200 157600
INFO 2019-10-17 15:58:31,440 basehttp 124 "GET /static/rest_framework/fonts/fontawesome-webfont.woff?v=4.0.3 HTTP/1.1" 200 44432
INFO 2019-10-17 15:58:32,524 basehttp 124 "GET /static/rest_framework/docs/img/favicon.ico HTTP/1.1" 200 5430
WARNING 2019-10-17 16:00:14,705 log 228 Not Found: /
WARNING 2019-10-17 16:00:14,705 basehttp 124 "GET / HTTP/1.1" 404 3332
WARNING 2019-10-17 16:00:44,121 log 228 Not Found: /
WARNING 2019-10-17 16:00:44,121 basehttp 124 "GET / HTTP/1.1" 404 3332
INFO 2019-10-17 16:00:52,665 basehttp 124 "GET /docs/ HTTP/1.1" 200 46056
INFO 2019-10-17 16:00:52,683 basehttp 124 "GET /docs/schema.js HTTP/1.1" 200 4040
